[2024-05-16 02:21:56,555] {processor.py:153} INFO - Started process (PID=173) to work on /opt/airflow/dags/ETL_Games.py
[2024-05-16 02:21:56,556] {processor.py:641} INFO - Processing file /opt/airflow/dags/ETL_Games.py for tasks to queue
[2024-05-16 02:21:56,558] {logging_mixin.py:115} INFO - [2024-05-16 02:21:56,557] {dagbag.py:508} INFO - Filling up the DagBag from /opt/airflow/dags/ETL_Games.py
[2024-05-16 02:21:56,598] {logging_mixin.py:115} INFO - [2024-05-16 02:21:56,592] {dagbag.py:321} ERROR - Failed to import: /opt/airflow/dags/ETL_Games.py
Traceback (most recent call last):
  File "/home/airflow/.local/lib/python3.7/site-packages/airflow/models/dagbag.py", line 318, in parse
    loader.exec_module(new_module)
  File "<frozen importlib._bootstrap_external>", line 728, in exec_module
  File "<frozen importlib._bootstrap>", line 219, in _call_with_frames_removed
  File "/opt/airflow/dags/ETL_Games.py", line 6, in <module>
    from modulos.modulo1 import *
ModuleNotFoundError: No module named 'modulos'
[2024-05-16 02:21:56,600] {processor.py:653} WARNING - No viable dags retrieved from /opt/airflow/dags/ETL_Games.py
[2024-05-16 02:21:56,634] {processor.py:161} INFO - Processing /opt/airflow/dags/ETL_Games.py took 0.084 seconds
[2024-05-16 02:22:06,709] {processor.py:153} INFO - Started process (PID=178) to work on /opt/airflow/dags/ETL_Games.py
[2024-05-16 02:22:06,710] {processor.py:641} INFO - Processing file /opt/airflow/dags/ETL_Games.py for tasks to queue
[2024-05-16 02:22:06,711] {logging_mixin.py:115} INFO - [2024-05-16 02:22:06,711] {dagbag.py:508} INFO - Filling up the DagBag from /opt/airflow/dags/ETL_Games.py
[2024-05-16 02:22:06,730] {logging_mixin.py:115} INFO - [2024-05-16 02:22:06,726] {dagbag.py:321} ERROR - Failed to import: /opt/airflow/dags/ETL_Games.py
Traceback (most recent call last):
  File "/home/airflow/.local/lib/python3.7/site-packages/airflow/models/dagbag.py", line 318, in parse
    loader.exec_module(new_module)
  File "<frozen importlib._bootstrap_external>", line 728, in exec_module
  File "<frozen importlib._bootstrap>", line 219, in _call_with_frames_removed
  File "/opt/airflow/dags/ETL_Games.py", line 6, in <module>
    from modulos.modulo1 import *
ModuleNotFoundError: No module named 'modulos'
[2024-05-16 02:22:06,731] {processor.py:653} WARNING - No viable dags retrieved from /opt/airflow/dags/ETL_Games.py
[2024-05-16 02:22:06,763] {processor.py:161} INFO - Processing /opt/airflow/dags/ETL_Games.py took 0.059 seconds
[2024-05-16 02:22:16,823] {processor.py:153} INFO - Started process (PID=183) to work on /opt/airflow/dags/ETL_Games.py
[2024-05-16 02:22:16,823] {processor.py:641} INFO - Processing file /opt/airflow/dags/ETL_Games.py for tasks to queue
[2024-05-16 02:22:16,824] {logging_mixin.py:115} INFO - [2024-05-16 02:22:16,824] {dagbag.py:508} INFO - Filling up the DagBag from /opt/airflow/dags/ETL_Games.py
[2024-05-16 02:22:16,831] {logging_mixin.py:115} INFO - [2024-05-16 02:22:16,830] {dagbag.py:321} ERROR - Failed to import: /opt/airflow/dags/ETL_Games.py
Traceback (most recent call last):
  File "/home/airflow/.local/lib/python3.7/site-packages/airflow/models/dagbag.py", line 318, in parse
    loader.exec_module(new_module)
  File "<frozen importlib._bootstrap_external>", line 728, in exec_module
  File "<frozen importlib._bootstrap>", line 219, in _call_with_frames_removed
  File "/opt/airflow/dags/ETL_Games.py", line 6, in <module>
    from modulos.modulo1 import *
ModuleNotFoundError: No module named 'modulos'
[2024-05-16 02:22:16,832] {processor.py:653} WARNING - No viable dags retrieved from /opt/airflow/dags/ETL_Games.py
[2024-05-16 02:22:16,847] {processor.py:161} INFO - Processing /opt/airflow/dags/ETL_Games.py took 0.028 seconds
[2024-05-16 02:22:26,894] {processor.py:153} INFO - Started process (PID=188) to work on /opt/airflow/dags/ETL_Games.py
[2024-05-16 02:22:26,895] {processor.py:641} INFO - Processing file /opt/airflow/dags/ETL_Games.py for tasks to queue
[2024-05-16 02:22:26,895] {logging_mixin.py:115} INFO - [2024-05-16 02:22:26,895] {dagbag.py:508} INFO - Filling up the DagBag from /opt/airflow/dags/ETL_Games.py
[2024-05-16 02:22:26,905] {logging_mixin.py:115} INFO - [2024-05-16 02:22:26,903] {dagbag.py:321} ERROR - Failed to import: /opt/airflow/dags/ETL_Games.py
Traceback (most recent call last):
  File "/home/airflow/.local/lib/python3.7/site-packages/airflow/models/dagbag.py", line 318, in parse
    loader.exec_module(new_module)
  File "<frozen importlib._bootstrap_external>", line 728, in exec_module
  File "<frozen importlib._bootstrap>", line 219, in _call_with_frames_removed
  File "/opt/airflow/dags/ETL_Games.py", line 6, in <module>
    from modulos.modulo1 import *
ModuleNotFoundError: No module named 'modulos'
[2024-05-16 02:22:26,906] {processor.py:653} WARNING - No viable dags retrieved from /opt/airflow/dags/ETL_Games.py
[2024-05-16 02:22:26,923] {processor.py:161} INFO - Processing /opt/airflow/dags/ETL_Games.py took 0.032 seconds
[2024-05-16 02:22:36,972] {processor.py:153} INFO - Started process (PID=193) to work on /opt/airflow/dags/ETL_Games.py
[2024-05-16 02:22:36,973] {processor.py:641} INFO - Processing file /opt/airflow/dags/ETL_Games.py for tasks to queue
[2024-05-16 02:22:36,974] {logging_mixin.py:115} INFO - [2024-05-16 02:22:36,974] {dagbag.py:508} INFO - Filling up the DagBag from /opt/airflow/dags/ETL_Games.py
[2024-05-16 02:22:36,984] {logging_mixin.py:115} INFO - [2024-05-16 02:22:36,982] {dagbag.py:321} ERROR - Failed to import: /opt/airflow/dags/ETL_Games.py
Traceback (most recent call last):
  File "/home/airflow/.local/lib/python3.7/site-packages/airflow/models/dagbag.py", line 318, in parse
    loader.exec_module(new_module)
  File "<frozen importlib._bootstrap_external>", line 728, in exec_module
  File "<frozen importlib._bootstrap>", line 219, in _call_with_frames_removed
  File "/opt/airflow/dags/ETL_Games.py", line 6, in <module>
    from modulos.modulo1 import *
ModuleNotFoundError: No module named 'modulos'
[2024-05-16 02:22:36,985] {processor.py:653} WARNING - No viable dags retrieved from /opt/airflow/dags/ETL_Games.py
[2024-05-16 02:22:37,004] {processor.py:161} INFO - Processing /opt/airflow/dags/ETL_Games.py took 0.035 seconds
[2024-05-16 02:22:47,058] {processor.py:153} INFO - Started process (PID=198) to work on /opt/airflow/dags/ETL_Games.py
[2024-05-16 02:22:47,059] {processor.py:641} INFO - Processing file /opt/airflow/dags/ETL_Games.py for tasks to queue
[2024-05-16 02:22:47,059] {logging_mixin.py:115} INFO - [2024-05-16 02:22:47,059] {dagbag.py:508} INFO - Filling up the DagBag from /opt/airflow/dags/ETL_Games.py
[2024-05-16 02:22:47,068] {logging_mixin.py:115} INFO - [2024-05-16 02:22:47,066] {dagbag.py:321} ERROR - Failed to import: /opt/airflow/dags/ETL_Games.py
Traceback (most recent call last):
  File "/home/airflow/.local/lib/python3.7/site-packages/airflow/models/dagbag.py", line 318, in parse
    loader.exec_module(new_module)
  File "<frozen importlib._bootstrap_external>", line 728, in exec_module
  File "<frozen importlib._bootstrap>", line 219, in _call_with_frames_removed
  File "/opt/airflow/dags/ETL_Games.py", line 6, in <module>
    from modulos.modulo1 import *
ModuleNotFoundError: No module named 'modulos'
[2024-05-16 02:22:47,069] {processor.py:653} WARNING - No viable dags retrieved from /opt/airflow/dags/ETL_Games.py
[2024-05-16 02:22:47,083] {processor.py:161} INFO - Processing /opt/airflow/dags/ETL_Games.py took 0.027 seconds
[2024-05-16 02:22:57,122] {processor.py:153} INFO - Started process (PID=203) to work on /opt/airflow/dags/ETL_Games.py
[2024-05-16 02:22:57,124] {processor.py:641} INFO - Processing file /opt/airflow/dags/ETL_Games.py for tasks to queue
[2024-05-16 02:22:57,125] {logging_mixin.py:115} INFO - [2024-05-16 02:22:57,125] {dagbag.py:508} INFO - Filling up the DagBag from /opt/airflow/dags/ETL_Games.py
[2024-05-16 02:22:57,142] {logging_mixin.py:115} INFO - [2024-05-16 02:22:57,139] {dagbag.py:321} ERROR - Failed to import: /opt/airflow/dags/ETL_Games.py
Traceback (most recent call last):
  File "/home/airflow/.local/lib/python3.7/site-packages/airflow/models/dagbag.py", line 318, in parse
    loader.exec_module(new_module)
  File "<frozen importlib._bootstrap_external>", line 728, in exec_module
  File "<frozen importlib._bootstrap>", line 219, in _call_with_frames_removed
  File "/opt/airflow/dags/ETL_Games.py", line 6, in <module>
    from modulos.modulo1 import *
ModuleNotFoundError: No module named 'modulos'
[2024-05-16 02:22:57,144] {processor.py:653} WARNING - No viable dags retrieved from /opt/airflow/dags/ETL_Games.py
[2024-05-16 02:22:57,160] {processor.py:161} INFO - Processing /opt/airflow/dags/ETL_Games.py took 0.043 seconds
[2024-05-16 02:23:07,211] {processor.py:153} INFO - Started process (PID=208) to work on /opt/airflow/dags/ETL_Games.py
[2024-05-16 02:23:07,212] {processor.py:641} INFO - Processing file /opt/airflow/dags/ETL_Games.py for tasks to queue
[2024-05-16 02:23:07,213] {logging_mixin.py:115} INFO - [2024-05-16 02:23:07,213] {dagbag.py:508} INFO - Filling up the DagBag from /opt/airflow/dags/ETL_Games.py
[2024-05-16 02:23:07,224] {logging_mixin.py:115} INFO - [2024-05-16 02:23:07,221] {dagbag.py:321} ERROR - Failed to import: /opt/airflow/dags/ETL_Games.py
Traceback (most recent call last):
  File "/home/airflow/.local/lib/python3.7/site-packages/airflow/models/dagbag.py", line 318, in parse
    loader.exec_module(new_module)
  File "<frozen importlib._bootstrap_external>", line 728, in exec_module
  File "<frozen importlib._bootstrap>", line 219, in _call_with_frames_removed
  File "/opt/airflow/dags/ETL_Games.py", line 6, in <module>
    from modulos.modulo1 import *
ModuleNotFoundError: No module named 'modulos'
[2024-05-16 02:23:07,225] {processor.py:653} WARNING - No viable dags retrieved from /opt/airflow/dags/ETL_Games.py
[2024-05-16 02:23:07,247] {processor.py:161} INFO - Processing /opt/airflow/dags/ETL_Games.py took 0.039 seconds
[2024-05-16 02:23:17,304] {processor.py:153} INFO - Started process (PID=213) to work on /opt/airflow/dags/ETL_Games.py
[2024-05-16 02:23:17,305] {processor.py:641} INFO - Processing file /opt/airflow/dags/ETL_Games.py for tasks to queue
[2024-05-16 02:23:17,306] {logging_mixin.py:115} INFO - [2024-05-16 02:23:17,306] {dagbag.py:508} INFO - Filling up the DagBag from /opt/airflow/dags/ETL_Games.py
[2024-05-16 02:23:17,319] {logging_mixin.py:115} INFO - [2024-05-16 02:23:17,316] {dagbag.py:321} ERROR - Failed to import: /opt/airflow/dags/ETL_Games.py
Traceback (most recent call last):
  File "/home/airflow/.local/lib/python3.7/site-packages/airflow/models/dagbag.py", line 318, in parse
    loader.exec_module(new_module)
  File "<frozen importlib._bootstrap_external>", line 728, in exec_module
  File "<frozen importlib._bootstrap>", line 219, in _call_with_frames_removed
  File "/opt/airflow/dags/ETL_Games.py", line 6, in <module>
    from modulos.modulo1 import *
ModuleNotFoundError: No module named 'modulos'
[2024-05-16 02:23:17,320] {processor.py:653} WARNING - No viable dags retrieved from /opt/airflow/dags/ETL_Games.py
[2024-05-16 02:23:17,340] {processor.py:161} INFO - Processing /opt/airflow/dags/ETL_Games.py took 0.040 seconds
[2024-05-16 02:23:27,389] {processor.py:153} INFO - Started process (PID=218) to work on /opt/airflow/dags/ETL_Games.py
[2024-05-16 02:23:27,390] {processor.py:641} INFO - Processing file /opt/airflow/dags/ETL_Games.py for tasks to queue
[2024-05-16 02:23:27,391] {logging_mixin.py:115} INFO - [2024-05-16 02:23:27,391] {dagbag.py:508} INFO - Filling up the DagBag from /opt/airflow/dags/ETL_Games.py
[2024-05-16 02:23:27,405] {logging_mixin.py:115} INFO - [2024-05-16 02:23:27,402] {dagbag.py:321} ERROR - Failed to import: /opt/airflow/dags/ETL_Games.py
Traceback (most recent call last):
  File "/home/airflow/.local/lib/python3.7/site-packages/airflow/models/dagbag.py", line 318, in parse
    loader.exec_module(new_module)
  File "<frozen importlib._bootstrap_external>", line 728, in exec_module
  File "<frozen importlib._bootstrap>", line 219, in _call_with_frames_removed
  File "/opt/airflow/dags/ETL_Games.py", line 6, in <module>
    from modulos.modulo1 import *
ModuleNotFoundError: No module named 'modulos'
[2024-05-16 02:23:27,406] {processor.py:653} WARNING - No viable dags retrieved from /opt/airflow/dags/ETL_Games.py
[2024-05-16 02:23:27,426] {processor.py:161} INFO - Processing /opt/airflow/dags/ETL_Games.py took 0.039 seconds
[2024-05-16 02:23:37,478] {processor.py:153} INFO - Started process (PID=223) to work on /opt/airflow/dags/ETL_Games.py
[2024-05-16 02:23:37,479] {processor.py:641} INFO - Processing file /opt/airflow/dags/ETL_Games.py for tasks to queue
[2024-05-16 02:23:37,479] {logging_mixin.py:115} INFO - [2024-05-16 02:23:37,479] {dagbag.py:508} INFO - Filling up the DagBag from /opt/airflow/dags/ETL_Games.py
[2024-05-16 02:23:37,492] {logging_mixin.py:115} INFO - [2024-05-16 02:23:37,489] {dagbag.py:321} ERROR - Failed to import: /opt/airflow/dags/ETL_Games.py
Traceback (most recent call last):
  File "/home/airflow/.local/lib/python3.7/site-packages/airflow/models/dagbag.py", line 318, in parse
    loader.exec_module(new_module)
  File "<frozen importlib._bootstrap_external>", line 728, in exec_module
  File "<frozen importlib._bootstrap>", line 219, in _call_with_frames_removed
  File "/opt/airflow/dags/ETL_Games.py", line 6, in <module>
    from modulos.modulo1 import *
ModuleNotFoundError: No module named 'modulos'
[2024-05-16 02:23:37,492] {processor.py:653} WARNING - No viable dags retrieved from /opt/airflow/dags/ETL_Games.py
[2024-05-16 02:23:37,512] {processor.py:161} INFO - Processing /opt/airflow/dags/ETL_Games.py took 0.037 seconds
[2024-05-16 02:23:47,563] {processor.py:153} INFO - Started process (PID=228) to work on /opt/airflow/dags/ETL_Games.py
[2024-05-16 02:23:47,564] {processor.py:641} INFO - Processing file /opt/airflow/dags/ETL_Games.py for tasks to queue
[2024-05-16 02:23:47,565] {logging_mixin.py:115} INFO - [2024-05-16 02:23:47,565] {dagbag.py:508} INFO - Filling up the DagBag from /opt/airflow/dags/ETL_Games.py
[2024-05-16 02:23:47,574] {logging_mixin.py:115} INFO - [2024-05-16 02:23:47,571] {dagbag.py:321} ERROR - Failed to import: /opt/airflow/dags/ETL_Games.py
Traceback (most recent call last):
  File "/home/airflow/.local/lib/python3.7/site-packages/airflow/models/dagbag.py", line 318, in parse
    loader.exec_module(new_module)
  File "<frozen importlib._bootstrap_external>", line 728, in exec_module
  File "<frozen importlib._bootstrap>", line 219, in _call_with_frames_removed
  File "/opt/airflow/dags/ETL_Games.py", line 6, in <module>
    from modulos.modulo1 import *
ModuleNotFoundError: No module named 'modulos'
[2024-05-16 02:23:47,574] {processor.py:653} WARNING - No viable dags retrieved from /opt/airflow/dags/ETL_Games.py
[2024-05-16 02:23:47,588] {processor.py:161} INFO - Processing /opt/airflow/dags/ETL_Games.py took 0.027 seconds
[2024-05-16 02:23:57,636] {processor.py:153} INFO - Started process (PID=233) to work on /opt/airflow/dags/ETL_Games.py
[2024-05-16 02:23:57,636] {processor.py:641} INFO - Processing file /opt/airflow/dags/ETL_Games.py for tasks to queue
[2024-05-16 02:23:57,637] {logging_mixin.py:115} INFO - [2024-05-16 02:23:57,637] {dagbag.py:508} INFO - Filling up the DagBag from /opt/airflow/dags/ETL_Games.py
[2024-05-16 02:23:57,648] {logging_mixin.py:115} INFO - [2024-05-16 02:23:57,645] {dagbag.py:321} ERROR - Failed to import: /opt/airflow/dags/ETL_Games.py
Traceback (most recent call last):
  File "/home/airflow/.local/lib/python3.7/site-packages/airflow/models/dagbag.py", line 318, in parse
    loader.exec_module(new_module)
  File "<frozen importlib._bootstrap_external>", line 728, in exec_module
  File "<frozen importlib._bootstrap>", line 219, in _call_with_frames_removed
  File "/opt/airflow/dags/ETL_Games.py", line 6, in <module>
    from modulos.modulo1 import *
ModuleNotFoundError: No module named 'modulos'
[2024-05-16 02:23:57,649] {processor.py:653} WARNING - No viable dags retrieved from /opt/airflow/dags/ETL_Games.py
[2024-05-16 02:23:57,672] {processor.py:161} INFO - Processing /opt/airflow/dags/ETL_Games.py took 0.039 seconds
[2024-05-16 02:24:07,731] {processor.py:153} INFO - Started process (PID=238) to work on /opt/airflow/dags/ETL_Games.py
[2024-05-16 02:24:07,731] {processor.py:641} INFO - Processing file /opt/airflow/dags/ETL_Games.py for tasks to queue
[2024-05-16 02:24:07,732] {logging_mixin.py:115} INFO - [2024-05-16 02:24:07,732] {dagbag.py:508} INFO - Filling up the DagBag from /opt/airflow/dags/ETL_Games.py
[2024-05-16 02:24:07,750] {logging_mixin.py:115} INFO - [2024-05-16 02:24:07,745] {dagbag.py:321} ERROR - Failed to import: /opt/airflow/dags/ETL_Games.py
Traceback (most recent call last):
  File "/home/airflow/.local/lib/python3.7/site-packages/airflow/models/dagbag.py", line 318, in parse
    loader.exec_module(new_module)
  File "<frozen importlib._bootstrap_external>", line 728, in exec_module
  File "<frozen importlib._bootstrap>", line 219, in _call_with_frames_removed
  File "/opt/airflow/dags/ETL_Games.py", line 6, in <module>
    from modulos.modulo1 import *
ModuleNotFoundError: No module named 'modulos'
[2024-05-16 02:24:07,751] {processor.py:653} WARNING - No viable dags retrieved from /opt/airflow/dags/ETL_Games.py
[2024-05-16 02:24:07,770] {processor.py:161} INFO - Processing /opt/airflow/dags/ETL_Games.py took 0.043 seconds
[2024-05-16 02:24:17,833] {processor.py:153} INFO - Started process (PID=243) to work on /opt/airflow/dags/ETL_Games.py
[2024-05-16 02:24:17,834] {processor.py:641} INFO - Processing file /opt/airflow/dags/ETL_Games.py for tasks to queue
[2024-05-16 02:24:17,835] {logging_mixin.py:115} INFO - [2024-05-16 02:24:17,835] {dagbag.py:508} INFO - Filling up the DagBag from /opt/airflow/dags/ETL_Games.py
[2024-05-16 02:24:17,854] {logging_mixin.py:115} INFO - [2024-05-16 02:24:17,850] {dagbag.py:321} ERROR - Failed to import: /opt/airflow/dags/ETL_Games.py
Traceback (most recent call last):
  File "/home/airflow/.local/lib/python3.7/site-packages/airflow/models/dagbag.py", line 318, in parse
    loader.exec_module(new_module)
  File "<frozen importlib._bootstrap_external>", line 728, in exec_module
  File "<frozen importlib._bootstrap>", line 219, in _call_with_frames_removed
  File "/opt/airflow/dags/ETL_Games.py", line 6, in <module>
    from modulos.modulo1 import *
ModuleNotFoundError: No module named 'modulos'
[2024-05-16 02:24:17,855] {processor.py:653} WARNING - No viable dags retrieved from /opt/airflow/dags/ETL_Games.py
[2024-05-16 02:24:17,880] {processor.py:161} INFO - Processing /opt/airflow/dags/ETL_Games.py took 0.051 seconds
[2024-05-16 02:24:27,944] {processor.py:153} INFO - Started process (PID=248) to work on /opt/airflow/dags/ETL_Games.py
[2024-05-16 02:24:27,945] {processor.py:641} INFO - Processing file /opt/airflow/dags/ETL_Games.py for tasks to queue
[2024-05-16 02:24:27,946] {logging_mixin.py:115} INFO - [2024-05-16 02:24:27,946] {dagbag.py:508} INFO - Filling up the DagBag from /opt/airflow/dags/ETL_Games.py
[2024-05-16 02:24:27,967] {logging_mixin.py:115} INFO - [2024-05-16 02:24:27,961] {dagbag.py:321} ERROR - Failed to import: /opt/airflow/dags/ETL_Games.py
Traceback (most recent call last):
  File "/home/airflow/.local/lib/python3.7/site-packages/airflow/models/dagbag.py", line 318, in parse
    loader.exec_module(new_module)
  File "<frozen importlib._bootstrap_external>", line 728, in exec_module
  File "<frozen importlib._bootstrap>", line 219, in _call_with_frames_removed
  File "/opt/airflow/dags/ETL_Games.py", line 6, in <module>
    from modulos.modulo1 import *
ModuleNotFoundError: No module named 'modulos'
[2024-05-16 02:24:27,968] {processor.py:653} WARNING - No viable dags retrieved from /opt/airflow/dags/ETL_Games.py
[2024-05-16 02:24:27,994] {processor.py:161} INFO - Processing /opt/airflow/dags/ETL_Games.py took 0.053 seconds
[2024-05-16 02:24:38,046] {processor.py:153} INFO - Started process (PID=253) to work on /opt/airflow/dags/ETL_Games.py
[2024-05-16 02:24:38,047] {processor.py:641} INFO - Processing file /opt/airflow/dags/ETL_Games.py for tasks to queue
[2024-05-16 02:24:38,048] {logging_mixin.py:115} INFO - [2024-05-16 02:24:38,048] {dagbag.py:508} INFO - Filling up the DagBag from /opt/airflow/dags/ETL_Games.py
[2024-05-16 02:24:38,062] {logging_mixin.py:115} INFO - [2024-05-16 02:24:38,059] {dagbag.py:321} ERROR - Failed to import: /opt/airflow/dags/ETL_Games.py
Traceback (most recent call last):
  File "/home/airflow/.local/lib/python3.7/site-packages/airflow/models/dagbag.py", line 318, in parse
    loader.exec_module(new_module)
  File "<frozen importlib._bootstrap_external>", line 728, in exec_module
  File "<frozen importlib._bootstrap>", line 219, in _call_with_frames_removed
  File "/opt/airflow/dags/ETL_Games.py", line 6, in <module>
    from modulos.modulo1 import *
ModuleNotFoundError: No module named 'modulos'
[2024-05-16 02:24:38,063] {processor.py:653} WARNING - No viable dags retrieved from /opt/airflow/dags/ETL_Games.py
[2024-05-16 02:24:38,083] {processor.py:161} INFO - Processing /opt/airflow/dags/ETL_Games.py took 0.040 seconds
[2024-05-16 02:24:48,141] {processor.py:153} INFO - Started process (PID=258) to work on /opt/airflow/dags/ETL_Games.py
[2024-05-16 02:24:48,142] {processor.py:641} INFO - Processing file /opt/airflow/dags/ETL_Games.py for tasks to queue
[2024-05-16 02:24:48,143] {logging_mixin.py:115} INFO - [2024-05-16 02:24:48,143] {dagbag.py:508} INFO - Filling up the DagBag from /opt/airflow/dags/ETL_Games.py
[2024-05-16 02:24:48,154] {logging_mixin.py:115} INFO - [2024-05-16 02:24:48,151] {dagbag.py:321} ERROR - Failed to import: /opt/airflow/dags/ETL_Games.py
Traceback (most recent call last):
  File "/home/airflow/.local/lib/python3.7/site-packages/airflow/models/dagbag.py", line 318, in parse
    loader.exec_module(new_module)
  File "<frozen importlib._bootstrap_external>", line 728, in exec_module
  File "<frozen importlib._bootstrap>", line 219, in _call_with_frames_removed
  File "/opt/airflow/dags/ETL_Games.py", line 6, in <module>
    from modulos.modulo1 import *
ModuleNotFoundError: No module named 'modulos'
[2024-05-16 02:24:48,155] {processor.py:653} WARNING - No viable dags retrieved from /opt/airflow/dags/ETL_Games.py
[2024-05-16 02:24:48,174] {processor.py:161} INFO - Processing /opt/airflow/dags/ETL_Games.py took 0.035 seconds
[2024-05-16 02:24:58,225] {processor.py:153} INFO - Started process (PID=263) to work on /opt/airflow/dags/ETL_Games.py
[2024-05-16 02:24:58,225] {processor.py:641} INFO - Processing file /opt/airflow/dags/ETL_Games.py for tasks to queue
[2024-05-16 02:24:58,226] {logging_mixin.py:115} INFO - [2024-05-16 02:24:58,226] {dagbag.py:508} INFO - Filling up the DagBag from /opt/airflow/dags/ETL_Games.py
[2024-05-16 02:24:58,236] {logging_mixin.py:115} INFO - [2024-05-16 02:24:58,234] {dagbag.py:321} ERROR - Failed to import: /opt/airflow/dags/ETL_Games.py
Traceback (most recent call last):
  File "/home/airflow/.local/lib/python3.7/site-packages/airflow/models/dagbag.py", line 318, in parse
    loader.exec_module(new_module)
  File "<frozen importlib._bootstrap_external>", line 728, in exec_module
  File "<frozen importlib._bootstrap>", line 219, in _call_with_frames_removed
  File "/opt/airflow/dags/ETL_Games.py", line 6, in <module>
    from modulos.modulo1 import *
ModuleNotFoundError: No module named 'modulos'
[2024-05-16 02:24:58,236] {processor.py:653} WARNING - No viable dags retrieved from /opt/airflow/dags/ETL_Games.py
[2024-05-16 02:24:58,254] {processor.py:161} INFO - Processing /opt/airflow/dags/ETL_Games.py took 0.032 seconds
[2024-05-16 02:25:08,301] {processor.py:153} INFO - Started process (PID=268) to work on /opt/airflow/dags/ETL_Games.py
[2024-05-16 02:25:08,302] {processor.py:641} INFO - Processing file /opt/airflow/dags/ETL_Games.py for tasks to queue
[2024-05-16 02:25:08,302] {logging_mixin.py:115} INFO - [2024-05-16 02:25:08,302] {dagbag.py:508} INFO - Filling up the DagBag from /opt/airflow/dags/ETL_Games.py
[2024-05-16 02:25:08,311] {logging_mixin.py:115} INFO - [2024-05-16 02:25:08,309] {dagbag.py:321} ERROR - Failed to import: /opt/airflow/dags/ETL_Games.py
Traceback (most recent call last):
  File "/home/airflow/.local/lib/python3.7/site-packages/airflow/models/dagbag.py", line 318, in parse
    loader.exec_module(new_module)
  File "<frozen importlib._bootstrap_external>", line 728, in exec_module
  File "<frozen importlib._bootstrap>", line 219, in _call_with_frames_removed
  File "/opt/airflow/dags/ETL_Games.py", line 6, in <module>
    from modulos.modulo1 import *
ModuleNotFoundError: No module named 'modulos'
[2024-05-16 02:25:08,312] {processor.py:653} WARNING - No viable dags retrieved from /opt/airflow/dags/ETL_Games.py
[2024-05-16 02:25:08,326] {processor.py:161} INFO - Processing /opt/airflow/dags/ETL_Games.py took 0.027 seconds
[2024-05-16 02:25:18,385] {processor.py:153} INFO - Started process (PID=273) to work on /opt/airflow/dags/ETL_Games.py
[2024-05-16 02:25:18,386] {processor.py:641} INFO - Processing file /opt/airflow/dags/ETL_Games.py for tasks to queue
[2024-05-16 02:25:18,387] {logging_mixin.py:115} INFO - [2024-05-16 02:25:18,386] {dagbag.py:508} INFO - Filling up the DagBag from /opt/airflow/dags/ETL_Games.py
[2024-05-16 02:25:18,395] {logging_mixin.py:115} INFO - [2024-05-16 02:25:18,393] {dagbag.py:321} ERROR - Failed to import: /opt/airflow/dags/ETL_Games.py
Traceback (most recent call last):
  File "/home/airflow/.local/lib/python3.7/site-packages/airflow/models/dagbag.py", line 318, in parse
    loader.exec_module(new_module)
  File "<frozen importlib._bootstrap_external>", line 728, in exec_module
  File "<frozen importlib._bootstrap>", line 219, in _call_with_frames_removed
  File "/opt/airflow/dags/ETL_Games.py", line 6, in <module>
    from modulos.modulo1 import *
ModuleNotFoundError: No module named 'modulos'
[2024-05-16 02:25:18,396] {processor.py:653} WARNING - No viable dags retrieved from /opt/airflow/dags/ETL_Games.py
[2024-05-16 02:25:18,411] {processor.py:161} INFO - Processing /opt/airflow/dags/ETL_Games.py took 0.028 seconds
[2024-05-16 02:25:28,456] {processor.py:153} INFO - Started process (PID=278) to work on /opt/airflow/dags/ETL_Games.py
[2024-05-16 02:25:28,457] {processor.py:641} INFO - Processing file /opt/airflow/dags/ETL_Games.py for tasks to queue
[2024-05-16 02:25:28,458] {logging_mixin.py:115} INFO - [2024-05-16 02:25:28,457] {dagbag.py:508} INFO - Filling up the DagBag from /opt/airflow/dags/ETL_Games.py
[2024-05-16 02:25:28,468] {logging_mixin.py:115} INFO - [2024-05-16 02:25:28,466] {dagbag.py:321} ERROR - Failed to import: /opt/airflow/dags/ETL_Games.py
Traceback (most recent call last):
  File "/home/airflow/.local/lib/python3.7/site-packages/airflow/models/dagbag.py", line 318, in parse
    loader.exec_module(new_module)
  File "<frozen importlib._bootstrap_external>", line 728, in exec_module
  File "<frozen importlib._bootstrap>", line 219, in _call_with_frames_removed
  File "/opt/airflow/dags/ETL_Games.py", line 6, in <module>
    from modulos.modulo1 import *
ModuleNotFoundError: No module named 'modulos'
[2024-05-16 02:25:28,469] {processor.py:653} WARNING - No viable dags retrieved from /opt/airflow/dags/ETL_Games.py
[2024-05-16 02:25:28,486] {processor.py:161} INFO - Processing /opt/airflow/dags/ETL_Games.py took 0.033 seconds
[2024-05-16 02:25:38,542] {processor.py:153} INFO - Started process (PID=283) to work on /opt/airflow/dags/ETL_Games.py
[2024-05-16 02:25:38,543] {processor.py:641} INFO - Processing file /opt/airflow/dags/ETL_Games.py for tasks to queue
[2024-05-16 02:25:38,544] {logging_mixin.py:115} INFO - [2024-05-16 02:25:38,544] {dagbag.py:508} INFO - Filling up the DagBag from /opt/airflow/dags/ETL_Games.py
[2024-05-16 02:25:38,597] {logging_mixin.py:115} INFO - [2024-05-16 02:25:38,589] {dagbag.py:321} ERROR - Failed to import: /opt/airflow/dags/ETL_Games.py
Traceback (most recent call last):
  File "/home/airflow/.local/lib/python3.7/site-packages/airflow/models/dagbag.py", line 318, in parse
    loader.exec_module(new_module)
  File "<frozen importlib._bootstrap_external>", line 728, in exec_module
  File "<frozen importlib._bootstrap>", line 219, in _call_with_frames_removed
  File "/opt/airflow/dags/ETL_Games.py", line 6, in <module>
    from modulos.modulo1 import *
  File "/opt/airflow/dags/modulos/modulo1.py", line 6, in <module>
    from dotenv import load_dotenv
ModuleNotFoundError: No module named 'dotenv'
[2024-05-16 02:25:38,600] {processor.py:653} WARNING - No viable dags retrieved from /opt/airflow/dags/ETL_Games.py
[2024-05-16 02:25:38,629] {processor.py:161} INFO - Processing /opt/airflow/dags/ETL_Games.py took 0.092 seconds
[2024-05-16 02:25:48,687] {processor.py:153} INFO - Started process (PID=288) to work on /opt/airflow/dags/ETL_Games.py
[2024-05-16 02:25:48,687] {processor.py:641} INFO - Processing file /opt/airflow/dags/ETL_Games.py for tasks to queue
[2024-05-16 02:25:48,688] {logging_mixin.py:115} INFO - [2024-05-16 02:25:48,688] {dagbag.py:508} INFO - Filling up the DagBag from /opt/airflow/dags/ETL_Games.py
[2024-05-16 02:25:48,728] {logging_mixin.py:115} INFO - [2024-05-16 02:25:48,721] {dagbag.py:321} ERROR - Failed to import: /opt/airflow/dags/ETL_Games.py
Traceback (most recent call last):
  File "/home/airflow/.local/lib/python3.7/site-packages/airflow/models/dagbag.py", line 318, in parse
    loader.exec_module(new_module)
  File "<frozen importlib._bootstrap_external>", line 728, in exec_module
  File "<frozen importlib._bootstrap>", line 219, in _call_with_frames_removed
  File "/opt/airflow/dags/ETL_Games.py", line 6, in <module>
    from modulos.modulo1 import *
  File "/opt/airflow/dags/modulos/modulo1.py", line 6, in <module>
    from dotenv import load_dotenv
ModuleNotFoundError: No module named 'dotenv'
[2024-05-16 02:25:48,730] {processor.py:653} WARNING - No viable dags retrieved from /opt/airflow/dags/ETL_Games.py
[2024-05-16 02:25:48,758] {processor.py:161} INFO - Processing /opt/airflow/dags/ETL_Games.py took 0.074 seconds
[2024-05-16 02:25:53,709] {processor.py:153} INFO - Started process (PID=293) to work on /opt/airflow/dags/ETL_Games.py
[2024-05-16 02:25:53,709] {processor.py:641} INFO - Processing file /opt/airflow/dags/ETL_Games.py for tasks to queue
[2024-05-16 02:25:53,710] {logging_mixin.py:115} INFO - [2024-05-16 02:25:53,710] {dagbag.py:508} INFO - Filling up the DagBag from /opt/airflow/dags/ETL_Games.py
[2024-05-16 02:25:53,749] {logging_mixin.py:115} INFO - [2024-05-16 02:25:53,744] {dagbag.py:321} ERROR - Failed to import: /opt/airflow/dags/ETL_Games.py
Traceback (most recent call last):
  File "/home/airflow/.local/lib/python3.7/site-packages/airflow/models/dagbag.py", line 318, in parse
    loader.exec_module(new_module)
  File "<frozen importlib._bootstrap_external>", line 728, in exec_module
  File "<frozen importlib._bootstrap>", line 219, in _call_with_frames_removed
  File "/opt/airflow/dags/ETL_Games.py", line 6, in <module>
    from modulos.modulo1 import *
  File "/opt/airflow/dags/modulos/modulo1.py", line 6, in <module>
    from dotenv import load_dotenv
ModuleNotFoundError: No module named 'dotenv'
[2024-05-16 02:25:53,750] {processor.py:653} WARNING - No viable dags retrieved from /opt/airflow/dags/ETL_Games.py
[2024-05-16 02:25:53,775] {processor.py:161} INFO - Processing /opt/airflow/dags/ETL_Games.py took 0.070 seconds
[2024-05-16 02:26:03,841] {processor.py:153} INFO - Started process (PID=298) to work on /opt/airflow/dags/ETL_Games.py
[2024-05-16 02:26:03,842] {processor.py:641} INFO - Processing file /opt/airflow/dags/ETL_Games.py for tasks to queue
[2024-05-16 02:26:03,843] {logging_mixin.py:115} INFO - [2024-05-16 02:26:03,843] {dagbag.py:508} INFO - Filling up the DagBag from /opt/airflow/dags/ETL_Games.py
[2024-05-16 02:26:03,874] {logging_mixin.py:115} INFO - [2024-05-16 02:26:03,868] {dagbag.py:321} ERROR - Failed to import: /opt/airflow/dags/ETL_Games.py
Traceback (most recent call last):
  File "/home/airflow/.local/lib/python3.7/site-packages/airflow/models/dagbag.py", line 318, in parse
    loader.exec_module(new_module)
  File "<frozen importlib._bootstrap_external>", line 728, in exec_module
  File "<frozen importlib._bootstrap>", line 219, in _call_with_frames_removed
  File "/opt/airflow/dags/ETL_Games.py", line 6, in <module>
    from modulos.modulo1 import *
  File "/opt/airflow/dags/modulos/modulo1.py", line 6, in <module>
    from dotenv import load_dotenv
ModuleNotFoundError: No module named 'dotenv'
[2024-05-16 02:26:03,877] {processor.py:653} WARNING - No viable dags retrieved from /opt/airflow/dags/ETL_Games.py
[2024-05-16 02:26:03,901] {processor.py:161} INFO - Processing /opt/airflow/dags/ETL_Games.py took 0.062 seconds
[2024-05-16 02:26:13,956] {processor.py:153} INFO - Started process (PID=303) to work on /opt/airflow/dags/ETL_Games.py
[2024-05-16 02:26:13,956] {processor.py:641} INFO - Processing file /opt/airflow/dags/ETL_Games.py for tasks to queue
[2024-05-16 02:26:13,957] {logging_mixin.py:115} INFO - [2024-05-16 02:26:13,957] {dagbag.py:508} INFO - Filling up the DagBag from /opt/airflow/dags/ETL_Games.py
[2024-05-16 02:26:13,979] {logging_mixin.py:115} INFO - [2024-05-16 02:26:13,975] {dagbag.py:321} ERROR - Failed to import: /opt/airflow/dags/ETL_Games.py
Traceback (most recent call last):
  File "/home/airflow/.local/lib/python3.7/site-packages/airflow/models/dagbag.py", line 318, in parse
    loader.exec_module(new_module)
  File "<frozen importlib._bootstrap_external>", line 728, in exec_module
  File "<frozen importlib._bootstrap>", line 219, in _call_with_frames_removed
  File "/opt/airflow/dags/ETL_Games.py", line 6, in <module>
    from modulos.modulo1 import *
  File "/opt/airflow/dags/modulos/modulo1.py", line 6, in <module>
    from dotenv import load_dotenv
ModuleNotFoundError: No module named 'dotenv'
[2024-05-16 02:26:13,980] {processor.py:653} WARNING - No viable dags retrieved from /opt/airflow/dags/ETL_Games.py
[2024-05-16 02:26:14,000] {processor.py:161} INFO - Processing /opt/airflow/dags/ETL_Games.py took 0.047 seconds
[2024-05-16 02:26:24,057] {processor.py:153} INFO - Started process (PID=308) to work on /opt/airflow/dags/ETL_Games.py
[2024-05-16 02:26:24,058] {processor.py:641} INFO - Processing file /opt/airflow/dags/ETL_Games.py for tasks to queue
[2024-05-16 02:26:24,059] {logging_mixin.py:115} INFO - [2024-05-16 02:26:24,058] {dagbag.py:508} INFO - Filling up the DagBag from /opt/airflow/dags/ETL_Games.py
[2024-05-16 02:26:24,100] {logging_mixin.py:115} INFO - [2024-05-16 02:26:24,091] {dagbag.py:321} ERROR - Failed to import: /opt/airflow/dags/ETL_Games.py
Traceback (most recent call last):
  File "/home/airflow/.local/lib/python3.7/site-packages/airflow/models/dagbag.py", line 318, in parse
    loader.exec_module(new_module)
  File "<frozen importlib._bootstrap_external>", line 728, in exec_module
  File "<frozen importlib._bootstrap>", line 219, in _call_with_frames_removed
  File "/opt/airflow/dags/ETL_Games.py", line 6, in <module>
    from modulos.modulo1 import *
  File "/opt/airflow/dags/modulos/modulo1.py", line 6, in <module>
    from dotenv import load_dotenv
ModuleNotFoundError: No module named 'dotenv'
[2024-05-16 02:26:24,103] {processor.py:653} WARNING - No viable dags retrieved from /opt/airflow/dags/ETL_Games.py
[2024-05-16 02:26:24,132] {processor.py:161} INFO - Processing /opt/airflow/dags/ETL_Games.py took 0.079 seconds
[2024-05-16 02:26:34,199] {processor.py:153} INFO - Started process (PID=313) to work on /opt/airflow/dags/ETL_Games.py
[2024-05-16 02:26:34,201] {processor.py:641} INFO - Processing file /opt/airflow/dags/ETL_Games.py for tasks to queue
[2024-05-16 02:26:34,202] {logging_mixin.py:115} INFO - [2024-05-16 02:26:34,202] {dagbag.py:508} INFO - Filling up the DagBag from /opt/airflow/dags/ETL_Games.py
[2024-05-16 02:26:34,248] {logging_mixin.py:115} INFO - [2024-05-16 02:26:34,239] {dagbag.py:321} ERROR - Failed to import: /opt/airflow/dags/ETL_Games.py
Traceback (most recent call last):
  File "/home/airflow/.local/lib/python3.7/site-packages/airflow/models/dagbag.py", line 318, in parse
    loader.exec_module(new_module)
  File "<frozen importlib._bootstrap_external>", line 728, in exec_module
  File "<frozen importlib._bootstrap>", line 219, in _call_with_frames_removed
  File "/opt/airflow/dags/ETL_Games.py", line 6, in <module>
    from modulos.modulo1 import *
  File "/opt/airflow/dags/modulos/modulo1.py", line 6, in <module>
    from dotenv import load_dotenv
ModuleNotFoundError: No module named 'dotenv'
[2024-05-16 02:26:34,251] {processor.py:653} WARNING - No viable dags retrieved from /opt/airflow/dags/ETL_Games.py
[2024-05-16 02:26:34,284] {processor.py:161} INFO - Processing /opt/airflow/dags/ETL_Games.py took 0.089 seconds
[2024-05-16 02:26:44,343] {processor.py:153} INFO - Started process (PID=318) to work on /opt/airflow/dags/ETL_Games.py
[2024-05-16 02:26:44,343] {processor.py:641} INFO - Processing file /opt/airflow/dags/ETL_Games.py for tasks to queue
[2024-05-16 02:26:44,344] {logging_mixin.py:115} INFO - [2024-05-16 02:26:44,344] {dagbag.py:508} INFO - Filling up the DagBag from /opt/airflow/dags/ETL_Games.py
[2024-05-16 02:26:44,363] {logging_mixin.py:115} INFO - [2024-05-16 02:26:44,359] {dagbag.py:321} ERROR - Failed to import: /opt/airflow/dags/ETL_Games.py
Traceback (most recent call last):
  File "/home/airflow/.local/lib/python3.7/site-packages/airflow/models/dagbag.py", line 318, in parse
    loader.exec_module(new_module)
  File "<frozen importlib._bootstrap_external>", line 728, in exec_module
  File "<frozen importlib._bootstrap>", line 219, in _call_with_frames_removed
  File "/opt/airflow/dags/ETL_Games.py", line 6, in <module>
    from modulos.modulo1 import *
  File "/opt/airflow/dags/modulos/modulo1.py", line 6, in <module>
    from dotenv import load_dotenv
ModuleNotFoundError: No module named 'dotenv'
[2024-05-16 02:26:44,364] {processor.py:653} WARNING - No viable dags retrieved from /opt/airflow/dags/ETL_Games.py
[2024-05-16 02:26:44,379] {processor.py:161} INFO - Processing /opt/airflow/dags/ETL_Games.py took 0.039 seconds
[2024-05-16 02:26:54,432] {processor.py:153} INFO - Started process (PID=323) to work on /opt/airflow/dags/ETL_Games.py
[2024-05-16 02:26:54,432] {processor.py:641} INFO - Processing file /opt/airflow/dags/ETL_Games.py for tasks to queue
[2024-05-16 02:26:54,433] {logging_mixin.py:115} INFO - [2024-05-16 02:26:54,433] {dagbag.py:508} INFO - Filling up the DagBag from /opt/airflow/dags/ETL_Games.py
[2024-05-16 02:26:54,462] {logging_mixin.py:115} INFO - [2024-05-16 02:26:54,455] {dagbag.py:321} ERROR - Failed to import: /opt/airflow/dags/ETL_Games.py
Traceback (most recent call last):
  File "/home/airflow/.local/lib/python3.7/site-packages/airflow/models/dagbag.py", line 318, in parse
    loader.exec_module(new_module)
  File "<frozen importlib._bootstrap_external>", line 728, in exec_module
  File "<frozen importlib._bootstrap>", line 219, in _call_with_frames_removed
  File "/opt/airflow/dags/ETL_Games.py", line 6, in <module>
    from modulos.modulo1 import *
  File "/opt/airflow/dags/modulos/modulo1.py", line 6, in <module>
    from dotenv import load_dotenv
ModuleNotFoundError: No module named 'dotenv'
[2024-05-16 02:26:54,464] {processor.py:653} WARNING - No viable dags retrieved from /opt/airflow/dags/ETL_Games.py
[2024-05-16 02:26:54,487] {processor.py:161} INFO - Processing /opt/airflow/dags/ETL_Games.py took 0.059 seconds
[2024-05-16 02:27:04,518] {processor.py:153} INFO - Started process (PID=328) to work on /opt/airflow/dags/ETL_Games.py
[2024-05-16 02:27:04,519] {processor.py:641} INFO - Processing file /opt/airflow/dags/ETL_Games.py for tasks to queue
[2024-05-16 02:27:04,519] {logging_mixin.py:115} INFO - [2024-05-16 02:27:04,519] {dagbag.py:508} INFO - Filling up the DagBag from /opt/airflow/dags/ETL_Games.py
[2024-05-16 02:27:04,548] {logging_mixin.py:115} INFO - [2024-05-16 02:27:04,541] {dagbag.py:321} ERROR - Failed to import: /opt/airflow/dags/ETL_Games.py
Traceback (most recent call last):
  File "/home/airflow/.local/lib/python3.7/site-packages/airflow/models/dagbag.py", line 318, in parse
    loader.exec_module(new_module)
  File "<frozen importlib._bootstrap_external>", line 728, in exec_module
  File "<frozen importlib._bootstrap>", line 219, in _call_with_frames_removed
  File "/opt/airflow/dags/ETL_Games.py", line 6, in <module>
    from modulos.modulo1 import *
  File "/opt/airflow/dags/modulos/modulo1.py", line 6, in <module>
    from dotenv import load_dotenv
ModuleNotFoundError: No module named 'dotenv'
[2024-05-16 02:27:04,550] {processor.py:653} WARNING - No viable dags retrieved from /opt/airflow/dags/ETL_Games.py
[2024-05-16 02:27:04,571] {processor.py:161} INFO - Processing /opt/airflow/dags/ETL_Games.py took 0.057 seconds
[2024-05-16 02:27:14,627] {processor.py:153} INFO - Started process (PID=333) to work on /opt/airflow/dags/ETL_Games.py
[2024-05-16 02:27:14,628] {processor.py:641} INFO - Processing file /opt/airflow/dags/ETL_Games.py for tasks to queue
[2024-05-16 02:27:14,629] {logging_mixin.py:115} INFO - [2024-05-16 02:27:14,629] {dagbag.py:508} INFO - Filling up the DagBag from /opt/airflow/dags/ETL_Games.py
[2024-05-16 02:27:14,656] {logging_mixin.py:115} INFO - [2024-05-16 02:27:14,651] {dagbag.py:321} ERROR - Failed to import: /opt/airflow/dags/ETL_Games.py
Traceback (most recent call last):
  File "/home/airflow/.local/lib/python3.7/site-packages/airflow/models/dagbag.py", line 318, in parse
    loader.exec_module(new_module)
  File "<frozen importlib._bootstrap_external>", line 728, in exec_module
  File "<frozen importlib._bootstrap>", line 219, in _call_with_frames_removed
  File "/opt/airflow/dags/ETL_Games.py", line 6, in <module>
    from modulos.modulo1 import *
  File "/opt/airflow/dags/modulos/modulo1.py", line 6, in <module>
    from dotenv import load_dotenv
ModuleNotFoundError: No module named 'dotenv'
[2024-05-16 02:27:14,658] {processor.py:653} WARNING - No viable dags retrieved from /opt/airflow/dags/ETL_Games.py
[2024-05-16 02:27:14,673] {processor.py:161} INFO - Processing /opt/airflow/dags/ETL_Games.py took 0.049 seconds
[2024-05-16 02:27:24,727] {processor.py:153} INFO - Started process (PID=338) to work on /opt/airflow/dags/ETL_Games.py
[2024-05-16 02:27:24,728] {processor.py:641} INFO - Processing file /opt/airflow/dags/ETL_Games.py for tasks to queue
[2024-05-16 02:27:24,728] {logging_mixin.py:115} INFO - [2024-05-16 02:27:24,728] {dagbag.py:508} INFO - Filling up the DagBag from /opt/airflow/dags/ETL_Games.py
[2024-05-16 02:27:24,749] {logging_mixin.py:115} INFO - [2024-05-16 02:27:24,745] {dagbag.py:321} ERROR - Failed to import: /opt/airflow/dags/ETL_Games.py
Traceback (most recent call last):
  File "/home/airflow/.local/lib/python3.7/site-packages/airflow/models/dagbag.py", line 318, in parse
    loader.exec_module(new_module)
  File "<frozen importlib._bootstrap_external>", line 728, in exec_module
  File "<frozen importlib._bootstrap>", line 219, in _call_with_frames_removed
  File "/opt/airflow/dags/ETL_Games.py", line 6, in <module>
    from modulos.modulo1 import *
  File "/opt/airflow/dags/modulos/modulo1.py", line 6, in <module>
    from dotenv import load_dotenv
ModuleNotFoundError: No module named 'dotenv'
[2024-05-16 02:27:24,750] {processor.py:653} WARNING - No viable dags retrieved from /opt/airflow/dags/ETL_Games.py
[2024-05-16 02:27:24,766] {processor.py:161} INFO - Processing /opt/airflow/dags/ETL_Games.py took 0.042 seconds
[2024-05-16 02:27:34,821] {processor.py:153} INFO - Started process (PID=343) to work on /opt/airflow/dags/ETL_Games.py
[2024-05-16 02:27:34,821] {processor.py:641} INFO - Processing file /opt/airflow/dags/ETL_Games.py for tasks to queue
[2024-05-16 02:27:34,822] {logging_mixin.py:115} INFO - [2024-05-16 02:27:34,822] {dagbag.py:508} INFO - Filling up the DagBag from /opt/airflow/dags/ETL_Games.py
[2024-05-16 02:27:34,843] {logging_mixin.py:115} INFO - [2024-05-16 02:27:34,839] {dagbag.py:321} ERROR - Failed to import: /opt/airflow/dags/ETL_Games.py
Traceback (most recent call last):
  File "/home/airflow/.local/lib/python3.7/site-packages/airflow/models/dagbag.py", line 318, in parse
    loader.exec_module(new_module)
  File "<frozen importlib._bootstrap_external>", line 728, in exec_module
  File "<frozen importlib._bootstrap>", line 219, in _call_with_frames_removed
  File "/opt/airflow/dags/ETL_Games.py", line 6, in <module>
    from modulos.modulo1 import *
  File "/opt/airflow/dags/modulos/modulo1.py", line 6, in <module>
    from dotenv import load_dotenv
ModuleNotFoundError: No module named 'dotenv'
[2024-05-16 02:27:34,844] {processor.py:653} WARNING - No viable dags retrieved from /opt/airflow/dags/ETL_Games.py
[2024-05-16 02:27:34,857] {processor.py:161} INFO - Processing /opt/airflow/dags/ETL_Games.py took 0.039 seconds
[2024-05-16 02:27:44,912] {processor.py:153} INFO - Started process (PID=348) to work on /opt/airflow/dags/ETL_Games.py
[2024-05-16 02:27:44,913] {processor.py:641} INFO - Processing file /opt/airflow/dags/ETL_Games.py for tasks to queue
[2024-05-16 02:27:44,913] {logging_mixin.py:115} INFO - [2024-05-16 02:27:44,913] {dagbag.py:508} INFO - Filling up the DagBag from /opt/airflow/dags/ETL_Games.py
[2024-05-16 02:27:44,945] {logging_mixin.py:115} INFO - [2024-05-16 02:27:44,939] {dagbag.py:321} ERROR - Failed to import: /opt/airflow/dags/ETL_Games.py
Traceback (most recent call last):
  File "/home/airflow/.local/lib/python3.7/site-packages/airflow/models/dagbag.py", line 318, in parse
    loader.exec_module(new_module)
  File "<frozen importlib._bootstrap_external>", line 728, in exec_module
  File "<frozen importlib._bootstrap>", line 219, in _call_with_frames_removed
  File "/opt/airflow/dags/ETL_Games.py", line 6, in <module>
    from modulos.modulo1 import *
  File "/opt/airflow/dags/modulos/modulo1.py", line 6, in <module>
    from dotenv import load_dotenv
ModuleNotFoundError: No module named 'dotenv'
[2024-05-16 02:27:44,947] {processor.py:653} WARNING - No viable dags retrieved from /opt/airflow/dags/ETL_Games.py
[2024-05-16 02:27:44,967] {processor.py:161} INFO - Processing /opt/airflow/dags/ETL_Games.py took 0.058 seconds
[2024-05-16 02:27:55,021] {processor.py:153} INFO - Started process (PID=353) to work on /opt/airflow/dags/ETL_Games.py
[2024-05-16 02:27:55,021] {processor.py:641} INFO - Processing file /opt/airflow/dags/ETL_Games.py for tasks to queue
[2024-05-16 02:27:55,022] {logging_mixin.py:115} INFO - [2024-05-16 02:27:55,022] {dagbag.py:508} INFO - Filling up the DagBag from /opt/airflow/dags/ETL_Games.py
[2024-05-16 02:27:55,048] {logging_mixin.py:115} INFO - [2024-05-16 02:27:55,042] {dagbag.py:321} ERROR - Failed to import: /opt/airflow/dags/ETL_Games.py
Traceback (most recent call last):
  File "/home/airflow/.local/lib/python3.7/site-packages/airflow/models/dagbag.py", line 318, in parse
    loader.exec_module(new_module)
  File "<frozen importlib._bootstrap_external>", line 728, in exec_module
  File "<frozen importlib._bootstrap>", line 219, in _call_with_frames_removed
  File "/opt/airflow/dags/ETL_Games.py", line 6, in <module>
    from modulos.modulo1 import *
  File "/opt/airflow/dags/modulos/modulo1.py", line 6, in <module>
    from dotenv import load_dotenv
ModuleNotFoundError: No module named 'dotenv'
[2024-05-16 02:27:55,050] {processor.py:653} WARNING - No viable dags retrieved from /opt/airflow/dags/ETL_Games.py
[2024-05-16 02:27:55,068] {processor.py:161} INFO - Processing /opt/airflow/dags/ETL_Games.py took 0.051 seconds
[2024-05-16 02:28:05,136] {processor.py:153} INFO - Started process (PID=358) to work on /opt/airflow/dags/ETL_Games.py
[2024-05-16 02:28:05,137] {processor.py:641} INFO - Processing file /opt/airflow/dags/ETL_Games.py for tasks to queue
[2024-05-16 02:28:05,138] {logging_mixin.py:115} INFO - [2024-05-16 02:28:05,138] {dagbag.py:508} INFO - Filling up the DagBag from /opt/airflow/dags/ETL_Games.py
[2024-05-16 02:28:05,171] {logging_mixin.py:115} INFO - [2024-05-16 02:28:05,165] {dagbag.py:321} ERROR - Failed to import: /opt/airflow/dags/ETL_Games.py
Traceback (most recent call last):
  File "/home/airflow/.local/lib/python3.7/site-packages/airflow/models/dagbag.py", line 318, in parse
    loader.exec_module(new_module)
  File "<frozen importlib._bootstrap_external>", line 728, in exec_module
  File "<frozen importlib._bootstrap>", line 219, in _call_with_frames_removed
  File "/opt/airflow/dags/ETL_Games.py", line 6, in <module>
    from modulos.modulo1 import *
  File "/opt/airflow/dags/modulos/modulo1.py", line 6, in <module>
    from dotenv import load_dotenv
ModuleNotFoundError: No module named 'dotenv'
[2024-05-16 02:28:05,174] {processor.py:653} WARNING - No viable dags retrieved from /opt/airflow/dags/ETL_Games.py
[2024-05-16 02:28:05,196] {processor.py:161} INFO - Processing /opt/airflow/dags/ETL_Games.py took 0.064 seconds
[2024-05-16 02:28:15,249] {processor.py:153} INFO - Started process (PID=363) to work on /opt/airflow/dags/ETL_Games.py
[2024-05-16 02:28:15,250] {processor.py:641} INFO - Processing file /opt/airflow/dags/ETL_Games.py for tasks to queue
[2024-05-16 02:28:15,251] {logging_mixin.py:115} INFO - [2024-05-16 02:28:15,250] {dagbag.py:508} INFO - Filling up the DagBag from /opt/airflow/dags/ETL_Games.py
[2024-05-16 02:28:15,280] {logging_mixin.py:115} INFO - [2024-05-16 02:28:15,272] {dagbag.py:321} ERROR - Failed to import: /opt/airflow/dags/ETL_Games.py
Traceback (most recent call last):
  File "/home/airflow/.local/lib/python3.7/site-packages/airflow/models/dagbag.py", line 318, in parse
    loader.exec_module(new_module)
  File "<frozen importlib._bootstrap_external>", line 728, in exec_module
  File "<frozen importlib._bootstrap>", line 219, in _call_with_frames_removed
  File "/opt/airflow/dags/ETL_Games.py", line 6, in <module>
    from modulos.modulo1 import *
  File "/opt/airflow/dags/modulos/modulo1.py", line 6, in <module>
    from dotenv import load_dotenv
ModuleNotFoundError: No module named 'dotenv'
[2024-05-16 02:28:15,282] {processor.py:653} WARNING - No viable dags retrieved from /opt/airflow/dags/ETL_Games.py
[2024-05-16 02:28:15,330] {processor.py:161} INFO - Processing /opt/airflow/dags/ETL_Games.py took 0.084 seconds
[2024-05-16 02:28:25,427] {processor.py:153} INFO - Started process (PID=368) to work on /opt/airflow/dags/ETL_Games.py
[2024-05-16 02:28:25,428] {processor.py:641} INFO - Processing file /opt/airflow/dags/ETL_Games.py for tasks to queue
[2024-05-16 02:28:25,429] {logging_mixin.py:115} INFO - [2024-05-16 02:28:25,428] {dagbag.py:508} INFO - Filling up the DagBag from /opt/airflow/dags/ETL_Games.py
[2024-05-16 02:28:25,455] {logging_mixin.py:115} INFO - [2024-05-16 02:28:25,449] {dagbag.py:321} ERROR - Failed to import: /opt/airflow/dags/ETL_Games.py
Traceback (most recent call last):
  File "/home/airflow/.local/lib/python3.7/site-packages/airflow/models/dagbag.py", line 318, in parse
    loader.exec_module(new_module)
  File "<frozen importlib._bootstrap_external>", line 728, in exec_module
  File "<frozen importlib._bootstrap>", line 219, in _call_with_frames_removed
  File "/opt/airflow/dags/ETL_Games.py", line 6, in <module>
    from modulos.modulo1 import *
  File "/opt/airflow/dags/modulos/modulo1.py", line 6, in <module>
    from dotenv import load_dotenv
ModuleNotFoundError: No module named 'dotenv'
[2024-05-16 02:28:25,458] {processor.py:653} WARNING - No viable dags retrieved from /opt/airflow/dags/ETL_Games.py
[2024-05-16 02:28:25,476] {processor.py:161} INFO - Processing /opt/airflow/dags/ETL_Games.py took 0.052 seconds
[2024-05-16 02:28:35,527] {processor.py:153} INFO - Started process (PID=373) to work on /opt/airflow/dags/ETL_Games.py
[2024-05-16 02:28:35,528] {processor.py:641} INFO - Processing file /opt/airflow/dags/ETL_Games.py for tasks to queue
[2024-05-16 02:28:35,528] {logging_mixin.py:115} INFO - [2024-05-16 02:28:35,528] {dagbag.py:508} INFO - Filling up the DagBag from /opt/airflow/dags/ETL_Games.py
[2024-05-16 02:28:35,552] {logging_mixin.py:115} INFO - [2024-05-16 02:28:35,547] {dagbag.py:321} ERROR - Failed to import: /opt/airflow/dags/ETL_Games.py
Traceback (most recent call last):
  File "/home/airflow/.local/lib/python3.7/site-packages/airflow/models/dagbag.py", line 318, in parse
    loader.exec_module(new_module)
  File "<frozen importlib._bootstrap_external>", line 728, in exec_module
  File "<frozen importlib._bootstrap>", line 219, in _call_with_frames_removed
  File "/opt/airflow/dags/ETL_Games.py", line 6, in <module>
    from modulos.modulo1 import *
  File "/opt/airflow/dags/modulos/modulo1.py", line 6, in <module>
    from dotenv import load_dotenv
ModuleNotFoundError: No module named 'dotenv'
[2024-05-16 02:28:35,555] {processor.py:653} WARNING - No viable dags retrieved from /opt/airflow/dags/ETL_Games.py
[2024-05-16 02:28:35,574] {processor.py:161} INFO - Processing /opt/airflow/dags/ETL_Games.py took 0.049 seconds
[2024-05-16 02:28:45,733] {processor.py:153} INFO - Started process (PID=378) to work on /opt/airflow/dags/ETL_Games.py
[2024-05-16 02:28:45,746] {processor.py:641} INFO - Processing file /opt/airflow/dags/ETL_Games.py for tasks to queue
[2024-05-16 02:28:45,749] {logging_mixin.py:115} INFO - [2024-05-16 02:28:45,748] {dagbag.py:508} INFO - Filling up the DagBag from /opt/airflow/dags/ETL_Games.py
[2024-05-16 02:28:47,227] {logging_mixin.py:115} INFO - No es posible conectar a Redshift
[2024-05-16 02:28:47,227] {logging_mixin.py:115} INFO - connection to server on socket "/var/run/postgresql/.s.PGSQL.5432" failed: No such file or directory
	Is the server running locally and accepting connections on that socket?
[2024-05-16 02:28:47,237] {logging_mixin.py:115} INFO - [2024-05-16 02:28:47,228] {dagbag.py:321} ERROR - Failed to import: /opt/airflow/dags/ETL_Games.py
Traceback (most recent call last):
  File "/home/airflow/.local/lib/python3.7/site-packages/airflow/models/dagbag.py", line 318, in parse
    loader.exec_module(new_module)
  File "<frozen importlib._bootstrap_external>", line 728, in exec_module
  File "<frozen importlib._bootstrap>", line 219, in _call_with_frames_removed
  File "/opt/airflow/dags/ETL_Games.py", line 13, in <module>
    conn = redshift_conn()
  File "/opt/airflow/dags/modulos/modulo1.py", line 81, in redshift_conn
    return conn
UnboundLocalError: local variable 'conn' referenced before assignment
[2024-05-16 02:28:47,240] {processor.py:653} WARNING - No viable dags retrieved from /opt/airflow/dags/ETL_Games.py
[2024-05-16 02:28:47,256] {processor.py:161} INFO - Processing /opt/airflow/dags/ETL_Games.py took 1.532 seconds
[2024-05-16 02:28:57,326] {processor.py:153} INFO - Started process (PID=384) to work on /opt/airflow/dags/ETL_Games.py
[2024-05-16 02:28:57,327] {processor.py:641} INFO - Processing file /opt/airflow/dags/ETL_Games.py for tasks to queue
[2024-05-16 02:28:57,327] {logging_mixin.py:115} INFO - [2024-05-16 02:28:57,327] {dagbag.py:508} INFO - Filling up the DagBag from /opt/airflow/dags/ETL_Games.py
[2024-05-16 02:28:57,788] {logging_mixin.py:115} INFO - No es posible conectar a Redshift
[2024-05-16 02:28:57,788] {logging_mixin.py:115} INFO - connection to server on socket "/var/run/postgresql/.s.PGSQL.5432" failed: No such file or directory
	Is the server running locally and accepting connections on that socket?
[2024-05-16 02:28:57,796] {logging_mixin.py:115} INFO - [2024-05-16 02:28:57,789] {dagbag.py:321} ERROR - Failed to import: /opt/airflow/dags/ETL_Games.py
Traceback (most recent call last):
  File "/home/airflow/.local/lib/python3.7/site-packages/airflow/models/dagbag.py", line 318, in parse
    loader.exec_module(new_module)
  File "<frozen importlib._bootstrap_external>", line 728, in exec_module
  File "<frozen importlib._bootstrap>", line 219, in _call_with_frames_removed
  File "/opt/airflow/dags/ETL_Games.py", line 13, in <module>
    conn = redshift_conn()
  File "/opt/airflow/dags/modulos/modulo1.py", line 81, in redshift_conn
    return conn
UnboundLocalError: local variable 'conn' referenced before assignment
[2024-05-16 02:28:57,798] {processor.py:653} WARNING - No viable dags retrieved from /opt/airflow/dags/ETL_Games.py
[2024-05-16 02:28:57,817] {processor.py:161} INFO - Processing /opt/airflow/dags/ETL_Games.py took 0.496 seconds
[2024-05-16 02:29:07,881] {processor.py:153} INFO - Started process (PID=390) to work on /opt/airflow/dags/ETL_Games.py
[2024-05-16 02:29:07,882] {processor.py:641} INFO - Processing file /opt/airflow/dags/ETL_Games.py for tasks to queue
[2024-05-16 02:29:07,882] {logging_mixin.py:115} INFO - [2024-05-16 02:29:07,882] {dagbag.py:508} INFO - Filling up the DagBag from /opt/airflow/dags/ETL_Games.py
[2024-05-16 02:29:08,164] {logging_mixin.py:115} INFO - No es posible conectar a Redshift
[2024-05-16 02:29:08,165] {logging_mixin.py:115} INFO - connection to server on socket "/var/run/postgresql/.s.PGSQL.5432" failed: No such file or directory
	Is the server running locally and accepting connections on that socket?
[2024-05-16 02:29:08,169] {logging_mixin.py:115} INFO - [2024-05-16 02:29:08,165] {dagbag.py:321} ERROR - Failed to import: /opt/airflow/dags/ETL_Games.py
Traceback (most recent call last):
  File "/home/airflow/.local/lib/python3.7/site-packages/airflow/models/dagbag.py", line 318, in parse
    loader.exec_module(new_module)
  File "<frozen importlib._bootstrap_external>", line 728, in exec_module
  File "<frozen importlib._bootstrap>", line 219, in _call_with_frames_removed
  File "/opt/airflow/dags/ETL_Games.py", line 13, in <module>
    conn = redshift_conn()
  File "/opt/airflow/dags/modulos/modulo1.py", line 81, in redshift_conn
    return conn
UnboundLocalError: local variable 'conn' referenced before assignment
[2024-05-16 02:29:08,172] {processor.py:653} WARNING - No viable dags retrieved from /opt/airflow/dags/ETL_Games.py
[2024-05-16 02:29:08,186] {processor.py:161} INFO - Processing /opt/airflow/dags/ETL_Games.py took 0.307 seconds
[2024-05-16 02:29:18,238] {processor.py:153} INFO - Started process (PID=396) to work on /opt/airflow/dags/ETL_Games.py
[2024-05-16 02:29:18,238] {processor.py:641} INFO - Processing file /opt/airflow/dags/ETL_Games.py for tasks to queue
[2024-05-16 02:29:18,239] {logging_mixin.py:115} INFO - [2024-05-16 02:29:18,239] {dagbag.py:508} INFO - Filling up the DagBag from /opt/airflow/dags/ETL_Games.py
[2024-05-16 02:29:18,514] {logging_mixin.py:115} INFO - No es posible conectar a Redshift
[2024-05-16 02:29:18,514] {logging_mixin.py:115} INFO - connection to server on socket "/var/run/postgresql/.s.PGSQL.5432" failed: No such file or directory
	Is the server running locally and accepting connections on that socket?
[2024-05-16 02:29:18,521] {logging_mixin.py:115} INFO - [2024-05-16 02:29:18,515] {dagbag.py:321} ERROR - Failed to import: /opt/airflow/dags/ETL_Games.py
Traceback (most recent call last):
  File "/home/airflow/.local/lib/python3.7/site-packages/airflow/models/dagbag.py", line 318, in parse
    loader.exec_module(new_module)
  File "<frozen importlib._bootstrap_external>", line 728, in exec_module
  File "<frozen importlib._bootstrap>", line 219, in _call_with_frames_removed
  File "/opt/airflow/dags/ETL_Games.py", line 13, in <module>
    conn = redshift_conn()
  File "/opt/airflow/dags/modulos/modulo1.py", line 81, in redshift_conn
    return conn
UnboundLocalError: local variable 'conn' referenced before assignment
[2024-05-16 02:29:18,522] {processor.py:653} WARNING - No viable dags retrieved from /opt/airflow/dags/ETL_Games.py
[2024-05-16 02:29:18,535] {processor.py:161} INFO - Processing /opt/airflow/dags/ETL_Games.py took 0.300 seconds
[2024-05-16 02:29:28,630] {processor.py:153} INFO - Started process (PID=402) to work on /opt/airflow/dags/ETL_Games.py
[2024-05-16 02:29:28,631] {processor.py:641} INFO - Processing file /opt/airflow/dags/ETL_Games.py for tasks to queue
[2024-05-16 02:29:28,631] {logging_mixin.py:115} INFO - [2024-05-16 02:29:28,631] {dagbag.py:508} INFO - Filling up the DagBag from /opt/airflow/dags/ETL_Games.py
[2024-05-16 02:29:29,024] {logging_mixin.py:115} INFO - No es posible conectar a Redshift
[2024-05-16 02:29:29,024] {logging_mixin.py:115} INFO - connection to server on socket "/var/run/postgresql/.s.PGSQL.5432" failed: No such file or directory
	Is the server running locally and accepting connections on that socket?
[2024-05-16 02:29:29,030] {logging_mixin.py:115} INFO - [2024-05-16 02:29:29,024] {dagbag.py:321} ERROR - Failed to import: /opt/airflow/dags/ETL_Games.py
Traceback (most recent call last):
  File "/home/airflow/.local/lib/python3.7/site-packages/airflow/models/dagbag.py", line 318, in parse
    loader.exec_module(new_module)
  File "<frozen importlib._bootstrap_external>", line 728, in exec_module
  File "<frozen importlib._bootstrap>", line 219, in _call_with_frames_removed
  File "/opt/airflow/dags/ETL_Games.py", line 13, in <module>
    conn = redshift_conn()
  File "/opt/airflow/dags/modulos/modulo1.py", line 81, in redshift_conn
    return conn
UnboundLocalError: local variable 'conn' referenced before assignment
[2024-05-16 02:29:29,032] {processor.py:653} WARNING - No viable dags retrieved from /opt/airflow/dags/ETL_Games.py
[2024-05-16 02:29:29,050] {processor.py:161} INFO - Processing /opt/airflow/dags/ETL_Games.py took 0.423 seconds
[2024-05-16 02:29:39,151] {processor.py:153} INFO - Started process (PID=408) to work on /opt/airflow/dags/ETL_Games.py
[2024-05-16 02:29:39,152] {processor.py:641} INFO - Processing file /opt/airflow/dags/ETL_Games.py for tasks to queue
[2024-05-16 02:29:39,152] {logging_mixin.py:115} INFO - [2024-05-16 02:29:39,152] {dagbag.py:508} INFO - Filling up the DagBag from /opt/airflow/dags/ETL_Games.py
[2024-05-16 02:29:39,601] {logging_mixin.py:115} INFO - No es posible conectar a Redshift
[2024-05-16 02:29:39,601] {logging_mixin.py:115} INFO - connection to server on socket "/var/run/postgresql/.s.PGSQL.5432" failed: No such file or directory
	Is the server running locally and accepting connections on that socket?
[2024-05-16 02:29:39,607] {logging_mixin.py:115} INFO - [2024-05-16 02:29:39,601] {dagbag.py:321} ERROR - Failed to import: /opt/airflow/dags/ETL_Games.py
Traceback (most recent call last):
  File "/home/airflow/.local/lib/python3.7/site-packages/airflow/models/dagbag.py", line 318, in parse
    loader.exec_module(new_module)
  File "<frozen importlib._bootstrap_external>", line 728, in exec_module
  File "<frozen importlib._bootstrap>", line 219, in _call_with_frames_removed
  File "/opt/airflow/dags/ETL_Games.py", line 13, in <module>
    conn = redshift_conn()
  File "/opt/airflow/dags/modulos/modulo1.py", line 81, in redshift_conn
    return conn
UnboundLocalError: local variable 'conn' referenced before assignment
[2024-05-16 02:29:39,608] {processor.py:653} WARNING - No viable dags retrieved from /opt/airflow/dags/ETL_Games.py
[2024-05-16 02:29:39,624] {processor.py:161} INFO - Processing /opt/airflow/dags/ETL_Games.py took 0.477 seconds
[2024-05-16 02:29:49,686] {processor.py:153} INFO - Started process (PID=414) to work on /opt/airflow/dags/ETL_Games.py
[2024-05-16 02:29:49,687] {processor.py:641} INFO - Processing file /opt/airflow/dags/ETL_Games.py for tasks to queue
[2024-05-16 02:29:49,687] {logging_mixin.py:115} INFO - [2024-05-16 02:29:49,687] {dagbag.py:508} INFO - Filling up the DagBag from /opt/airflow/dags/ETL_Games.py
[2024-05-16 02:29:50,053] {logging_mixin.py:115} INFO - No es posible conectar a Redshift
[2024-05-16 02:29:50,054] {logging_mixin.py:115} INFO - connection to server on socket "/var/run/postgresql/.s.PGSQL.5432" failed: No such file or directory
	Is the server running locally and accepting connections on that socket?
[2024-05-16 02:29:50,061] {logging_mixin.py:115} INFO - [2024-05-16 02:29:50,054] {dagbag.py:321} ERROR - Failed to import: /opt/airflow/dags/ETL_Games.py
Traceback (most recent call last):
  File "/home/airflow/.local/lib/python3.7/site-packages/airflow/models/dagbag.py", line 318, in parse
    loader.exec_module(new_module)
  File "<frozen importlib._bootstrap_external>", line 728, in exec_module
  File "<frozen importlib._bootstrap>", line 219, in _call_with_frames_removed
  File "/opt/airflow/dags/ETL_Games.py", line 13, in <module>
    conn = redshift_conn()
  File "/opt/airflow/dags/modulos/modulo1.py", line 80, in redshift_conn
    return conn
UnboundLocalError: local variable 'conn' referenced before assignment
[2024-05-16 02:29:50,064] {processor.py:653} WARNING - No viable dags retrieved from /opt/airflow/dags/ETL_Games.py
[2024-05-16 02:29:50,082] {processor.py:161} INFO - Processing /opt/airflow/dags/ETL_Games.py took 0.399 seconds
[2024-05-16 02:30:00,141] {processor.py:153} INFO - Started process (PID=420) to work on /opt/airflow/dags/ETL_Games.py
[2024-05-16 02:30:00,141] {processor.py:641} INFO - Processing file /opt/airflow/dags/ETL_Games.py for tasks to queue
[2024-05-16 02:30:00,142] {logging_mixin.py:115} INFO - [2024-05-16 02:30:00,142] {dagbag.py:508} INFO - Filling up the DagBag from /opt/airflow/dags/ETL_Games.py
[2024-05-16 02:30:00,428] {logging_mixin.py:115} INFO - No es posible conectar a Redshift
[2024-05-16 02:30:00,428] {logging_mixin.py:115} INFO - connection to server on socket "/var/run/postgresql/.s.PGSQL.5432" failed: No such file or directory
	Is the server running locally and accepting connections on that socket?
[2024-05-16 02:30:00,436] {logging_mixin.py:115} INFO - [2024-05-16 02:30:00,428] {dagbag.py:321} ERROR - Failed to import: /opt/airflow/dags/ETL_Games.py
Traceback (most recent call last):
  File "/home/airflow/.local/lib/python3.7/site-packages/airflow/models/dagbag.py", line 318, in parse
    loader.exec_module(new_module)
  File "<frozen importlib._bootstrap_external>", line 728, in exec_module
  File "<frozen importlib._bootstrap>", line 219, in _call_with_frames_removed
  File "/opt/airflow/dags/ETL_Games.py", line 13, in <module>
    conn = redshift_conn()
  File "/opt/airflow/dags/modulos/modulo1.py", line 80, in redshift_conn
    return conn
UnboundLocalError: local variable 'conn' referenced before assignment
[2024-05-16 02:30:00,437] {processor.py:653} WARNING - No viable dags retrieved from /opt/airflow/dags/ETL_Games.py
[2024-05-16 02:30:00,450] {processor.py:161} INFO - Processing /opt/airflow/dags/ETL_Games.py took 0.312 seconds
[2024-05-16 02:30:10,512] {processor.py:153} INFO - Started process (PID=426) to work on /opt/airflow/dags/ETL_Games.py
[2024-05-16 02:30:10,513] {processor.py:641} INFO - Processing file /opt/airflow/dags/ETL_Games.py for tasks to queue
[2024-05-16 02:30:10,514] {logging_mixin.py:115} INFO - [2024-05-16 02:30:10,514] {dagbag.py:508} INFO - Filling up the DagBag from /opt/airflow/dags/ETL_Games.py
[2024-05-16 02:30:10,815] {logging_mixin.py:115} INFO - No es posible conectar a Redshift
[2024-05-16 02:30:10,815] {logging_mixin.py:115} INFO - connection to server on socket "/var/run/postgresql/.s.PGSQL.5432" failed: No such file or directory
	Is the server running locally and accepting connections on that socket?
[2024-05-16 02:30:10,826] {logging_mixin.py:115} INFO - [2024-05-16 02:30:10,816] {dagbag.py:321} ERROR - Failed to import: /opt/airflow/dags/ETL_Games.py
Traceback (most recent call last):
  File "/home/airflow/.local/lib/python3.7/site-packages/airflow/models/dagbag.py", line 318, in parse
    loader.exec_module(new_module)
  File "<frozen importlib._bootstrap_external>", line 728, in exec_module
  File "<frozen importlib._bootstrap>", line 219, in _call_with_frames_removed
  File "/opt/airflow/dags/ETL_Games.py", line 13, in <module>
    conn = redshift_conn()
  File "/opt/airflow/dags/modulos/modulo1.py", line 80, in redshift_conn
    return conn
UnboundLocalError: local variable 'conn' referenced before assignment
[2024-05-16 02:30:10,828] {processor.py:653} WARNING - No viable dags retrieved from /opt/airflow/dags/ETL_Games.py
[2024-05-16 02:30:10,841] {processor.py:161} INFO - Processing /opt/airflow/dags/ETL_Games.py took 0.332 seconds
[2024-05-16 02:30:20,909] {processor.py:153} INFO - Started process (PID=432) to work on /opt/airflow/dags/ETL_Games.py
[2024-05-16 02:30:20,909] {processor.py:641} INFO - Processing file /opt/airflow/dags/ETL_Games.py for tasks to queue
[2024-05-16 02:30:20,910] {logging_mixin.py:115} INFO - [2024-05-16 02:30:20,910] {dagbag.py:508} INFO - Filling up the DagBag from /opt/airflow/dags/ETL_Games.py
[2024-05-16 02:30:21,251] {logging_mixin.py:115} INFO - No es posible conectar a Redshift
[2024-05-16 02:30:21,251] {logging_mixin.py:115} INFO - connection to server on socket "/var/run/postgresql/.s.PGSQL.5432" failed: No such file or directory
	Is the server running locally and accepting connections on that socket?
[2024-05-16 02:30:21,259] {logging_mixin.py:115} INFO - [2024-05-16 02:30:21,252] {dagbag.py:321} ERROR - Failed to import: /opt/airflow/dags/ETL_Games.py
Traceback (most recent call last):
  File "/home/airflow/.local/lib/python3.7/site-packages/airflow/models/dagbag.py", line 318, in parse
    loader.exec_module(new_module)
  File "<frozen importlib._bootstrap_external>", line 728, in exec_module
  File "<frozen importlib._bootstrap>", line 219, in _call_with_frames_removed
  File "/opt/airflow/dags/ETL_Games.py", line 13, in <module>
    conn = redshift_conn()
  File "/opt/airflow/dags/modulos/modulo1.py", line 80, in redshift_conn
    return conn
UnboundLocalError: local variable 'conn' referenced before assignment
[2024-05-16 02:30:21,262] {processor.py:653} WARNING - No viable dags retrieved from /opt/airflow/dags/ETL_Games.py
[2024-05-16 02:30:21,280] {processor.py:161} INFO - Processing /opt/airflow/dags/ETL_Games.py took 0.375 seconds
[2024-05-16 02:30:31,343] {processor.py:153} INFO - Started process (PID=438) to work on /opt/airflow/dags/ETL_Games.py
[2024-05-16 02:30:31,344] {processor.py:641} INFO - Processing file /opt/airflow/dags/ETL_Games.py for tasks to queue
[2024-05-16 02:30:31,345] {logging_mixin.py:115} INFO - [2024-05-16 02:30:31,345] {dagbag.py:508} INFO - Filling up the DagBag from /opt/airflow/dags/ETL_Games.py
[2024-05-16 02:30:31,647] {logging_mixin.py:115} INFO - No es posible conectar a Redshift
[2024-05-16 02:30:31,648] {logging_mixin.py:115} INFO - connection to server on socket "/var/run/postgresql/.s.PGSQL.5432" failed: No such file or directory
	Is the server running locally and accepting connections on that socket?
[2024-05-16 02:30:31,655] {logging_mixin.py:115} INFO - [2024-05-16 02:30:31,648] {dagbag.py:321} ERROR - Failed to import: /opt/airflow/dags/ETL_Games.py
Traceback (most recent call last):
  File "/home/airflow/.local/lib/python3.7/site-packages/airflow/models/dagbag.py", line 318, in parse
    loader.exec_module(new_module)
  File "<frozen importlib._bootstrap_external>", line 728, in exec_module
  File "<frozen importlib._bootstrap>", line 219, in _call_with_frames_removed
  File "/opt/airflow/dags/ETL_Games.py", line 13, in <module>
    conn = redshift_conn()
  File "/opt/airflow/dags/modulos/modulo1.py", line 80, in redshift_conn
    return conn
UnboundLocalError: local variable 'conn' referenced before assignment
[2024-05-16 02:30:31,657] {processor.py:653} WARNING - No viable dags retrieved from /opt/airflow/dags/ETL_Games.py
[2024-05-16 02:30:31,673] {processor.py:161} INFO - Processing /opt/airflow/dags/ETL_Games.py took 0.332 seconds
[2024-05-16 02:30:41,748] {processor.py:153} INFO - Started process (PID=444) to work on /opt/airflow/dags/ETL_Games.py
[2024-05-16 02:30:41,748] {processor.py:641} INFO - Processing file /opt/airflow/dags/ETL_Games.py for tasks to queue
[2024-05-16 02:30:41,749] {logging_mixin.py:115} INFO - [2024-05-16 02:30:41,749] {dagbag.py:508} INFO - Filling up the DagBag from /opt/airflow/dags/ETL_Games.py
[2024-05-16 02:30:42,036] {logging_mixin.py:115} INFO - No es posible conectar a Redshift
[2024-05-16 02:30:42,036] {logging_mixin.py:115} INFO - connection to server on socket "/var/run/postgresql/.s.PGSQL.5432" failed: No such file or directory
	Is the server running locally and accepting connections on that socket?
[2024-05-16 02:30:42,041] {logging_mixin.py:115} INFO - [2024-05-16 02:30:42,037] {dagbag.py:321} ERROR - Failed to import: /opt/airflow/dags/ETL_Games.py
Traceback (most recent call last):
  File "/home/airflow/.local/lib/python3.7/site-packages/airflow/models/dagbag.py", line 318, in parse
    loader.exec_module(new_module)
  File "<frozen importlib._bootstrap_external>", line 728, in exec_module
  File "<frozen importlib._bootstrap>", line 219, in _call_with_frames_removed
  File "/opt/airflow/dags/ETL_Games.py", line 13, in <module>
    conn = redshift_conn()
  File "/opt/airflow/dags/modulos/modulo1.py", line 80, in redshift_conn
    return conn
UnboundLocalError: local variable 'conn' referenced before assignment
[2024-05-16 02:30:42,044] {processor.py:653} WARNING - No viable dags retrieved from /opt/airflow/dags/ETL_Games.py
[2024-05-16 02:30:42,063] {processor.py:161} INFO - Processing /opt/airflow/dags/ETL_Games.py took 0.319 seconds
[2024-05-16 02:30:52,127] {processor.py:153} INFO - Started process (PID=450) to work on /opt/airflow/dags/ETL_Games.py
[2024-05-16 02:30:52,128] {processor.py:641} INFO - Processing file /opt/airflow/dags/ETL_Games.py for tasks to queue
[2024-05-16 02:30:52,128] {logging_mixin.py:115} INFO - [2024-05-16 02:30:52,128] {dagbag.py:508} INFO - Filling up the DagBag from /opt/airflow/dags/ETL_Games.py
[2024-05-16 02:30:52,401] {logging_mixin.py:115} INFO - No es posible conectar a Redshift
[2024-05-16 02:30:52,401] {logging_mixin.py:115} INFO - connection to server on socket "/var/run/postgresql/.s.PGSQL.5432" failed: No such file or directory
	Is the server running locally and accepting connections on that socket?
[2024-05-16 02:30:52,407] {logging_mixin.py:115} INFO - [2024-05-16 02:30:52,402] {dagbag.py:321} ERROR - Failed to import: /opt/airflow/dags/ETL_Games.py
Traceback (most recent call last):
  File "/home/airflow/.local/lib/python3.7/site-packages/airflow/models/dagbag.py", line 318, in parse
    loader.exec_module(new_module)
  File "<frozen importlib._bootstrap_external>", line 728, in exec_module
  File "<frozen importlib._bootstrap>", line 219, in _call_with_frames_removed
  File "/opt/airflow/dags/ETL_Games.py", line 13, in <module>
    conn = redshift_conn()
  File "/opt/airflow/dags/modulos/modulo1.py", line 80, in redshift_conn
    return conn
UnboundLocalError: local variable 'conn' referenced before assignment
[2024-05-16 02:30:52,408] {processor.py:653} WARNING - No viable dags retrieved from /opt/airflow/dags/ETL_Games.py
[2024-05-16 02:30:52,422] {processor.py:161} INFO - Processing /opt/airflow/dags/ETL_Games.py took 0.298 seconds
[2024-05-16 02:31:02,583] {processor.py:153} INFO - Started process (PID=456) to work on /opt/airflow/dags/ETL_Games.py
[2024-05-16 02:31:02,584] {processor.py:641} INFO - Processing file /opt/airflow/dags/ETL_Games.py for tasks to queue
[2024-05-16 02:31:02,585] {logging_mixin.py:115} INFO - [2024-05-16 02:31:02,585] {dagbag.py:508} INFO - Filling up the DagBag from /opt/airflow/dags/ETL_Games.py
[2024-05-16 02:31:03,217] {logging_mixin.py:115} INFO - No es posible conectar a Redshift
[2024-05-16 02:31:03,218] {logging_mixin.py:115} INFO - connection to server on socket "/var/run/postgresql/.s.PGSQL.5432" failed: No such file or directory
	Is the server running locally and accepting connections on that socket?
[2024-05-16 02:31:03,231] {logging_mixin.py:115} INFO - [2024-05-16 02:31:03,218] {dagbag.py:321} ERROR - Failed to import: /opt/airflow/dags/ETL_Games.py
Traceback (most recent call last):
  File "/home/airflow/.local/lib/python3.7/site-packages/airflow/models/dagbag.py", line 318, in parse
    loader.exec_module(new_module)
  File "<frozen importlib._bootstrap_external>", line 728, in exec_module
  File "<frozen importlib._bootstrap>", line 219, in _call_with_frames_removed
  File "/opt/airflow/dags/ETL_Games.py", line 13, in <module>
    conn = redshift_conn()
  File "/opt/airflow/dags/modulos/modulo1.py", line 80, in redshift_conn
    return conn
UnboundLocalError: local variable 'conn' referenced before assignment
[2024-05-16 02:31:03,234] {processor.py:653} WARNING - No viable dags retrieved from /opt/airflow/dags/ETL_Games.py
[2024-05-16 02:31:03,262] {processor.py:161} INFO - Processing /opt/airflow/dags/ETL_Games.py took 0.685 seconds
[2024-05-16 02:31:13,327] {processor.py:153} INFO - Started process (PID=462) to work on /opt/airflow/dags/ETL_Games.py
[2024-05-16 02:31:13,328] {processor.py:641} INFO - Processing file /opt/airflow/dags/ETL_Games.py for tasks to queue
[2024-05-16 02:31:13,328] {logging_mixin.py:115} INFO - [2024-05-16 02:31:13,328] {dagbag.py:508} INFO - Filling up the DagBag from /opt/airflow/dags/ETL_Games.py
[2024-05-16 02:31:13,674] {logging_mixin.py:115} INFO - No es posible conectar a Redshift
[2024-05-16 02:31:13,675] {logging_mixin.py:115} INFO - connection to server on socket "/var/run/postgresql/.s.PGSQL.5432" failed: No such file or directory
	Is the server running locally and accepting connections on that socket?
[2024-05-16 02:31:13,683] {logging_mixin.py:115} INFO - [2024-05-16 02:31:13,675] {dagbag.py:321} ERROR - Failed to import: /opt/airflow/dags/ETL_Games.py
Traceback (most recent call last):
  File "/home/airflow/.local/lib/python3.7/site-packages/airflow/models/dagbag.py", line 318, in parse
    loader.exec_module(new_module)
  File "<frozen importlib._bootstrap_external>", line 728, in exec_module
  File "<frozen importlib._bootstrap>", line 219, in _call_with_frames_removed
  File "/opt/airflow/dags/ETL_Games.py", line 13, in <module>
    conn = redshift_conn()
  File "/opt/airflow/dags/modulos/modulo1.py", line 80, in redshift_conn
    return conn
UnboundLocalError: local variable 'conn' referenced before assignment
[2024-05-16 02:31:13,685] {processor.py:653} WARNING - No viable dags retrieved from /opt/airflow/dags/ETL_Games.py
[2024-05-16 02:31:13,702] {processor.py:161} INFO - Processing /opt/airflow/dags/ETL_Games.py took 0.379 seconds
[2024-05-16 02:31:23,765] {processor.py:153} INFO - Started process (PID=468) to work on /opt/airflow/dags/ETL_Games.py
[2024-05-16 02:31:23,766] {processor.py:641} INFO - Processing file /opt/airflow/dags/ETL_Games.py for tasks to queue
[2024-05-16 02:31:23,766] {logging_mixin.py:115} INFO - [2024-05-16 02:31:23,766] {dagbag.py:508} INFO - Filling up the DagBag from /opt/airflow/dags/ETL_Games.py
[2024-05-16 02:31:24,236] {logging_mixin.py:115} INFO - No es posible conectar a Redshift
[2024-05-16 02:31:24,237] {logging_mixin.py:115} INFO - connection to server on socket "/var/run/postgresql/.s.PGSQL.5432" failed: No such file or directory
	Is the server running locally and accepting connections on that socket?
[2024-05-16 02:31:24,253] {logging_mixin.py:115} INFO - [2024-05-16 02:31:24,238] {dagbag.py:321} ERROR - Failed to import: /opt/airflow/dags/ETL_Games.py
Traceback (most recent call last):
  File "/home/airflow/.local/lib/python3.7/site-packages/airflow/models/dagbag.py", line 318, in parse
    loader.exec_module(new_module)
  File "<frozen importlib._bootstrap_external>", line 728, in exec_module
  File "<frozen importlib._bootstrap>", line 219, in _call_with_frames_removed
  File "/opt/airflow/dags/ETL_Games.py", line 13, in <module>
    conn = redshift_conn()
  File "/opt/airflow/dags/modulos/modulo1.py", line 80, in redshift_conn
    return conn
UnboundLocalError: local variable 'conn' referenced before assignment
[2024-05-16 02:31:24,255] {processor.py:653} WARNING - No viable dags retrieved from /opt/airflow/dags/ETL_Games.py
[2024-05-16 02:31:24,284] {processor.py:161} INFO - Processing /opt/airflow/dags/ETL_Games.py took 0.523 seconds
[2024-05-16 02:31:34,355] {processor.py:153} INFO - Started process (PID=474) to work on /opt/airflow/dags/ETL_Games.py
[2024-05-16 02:31:34,356] {processor.py:641} INFO - Processing file /opt/airflow/dags/ETL_Games.py for tasks to queue
[2024-05-16 02:31:34,356] {logging_mixin.py:115} INFO - [2024-05-16 02:31:34,356] {dagbag.py:508} INFO - Filling up the DagBag from /opt/airflow/dags/ETL_Games.py
[2024-05-16 02:31:34,819] {logging_mixin.py:115} INFO - No es posible conectar a Redshift
[2024-05-16 02:31:34,820] {logging_mixin.py:115} INFO - connection to server on socket "/var/run/postgresql/.s.PGSQL.5432" failed: No such file or directory
	Is the server running locally and accepting connections on that socket?
[2024-05-16 02:31:34,827] {logging_mixin.py:115} INFO - [2024-05-16 02:31:34,820] {dagbag.py:321} ERROR - Failed to import: /opt/airflow/dags/ETL_Games.py
Traceback (most recent call last):
  File "/home/airflow/.local/lib/python3.7/site-packages/airflow/models/dagbag.py", line 318, in parse
    loader.exec_module(new_module)
  File "<frozen importlib._bootstrap_external>", line 728, in exec_module
  File "<frozen importlib._bootstrap>", line 219, in _call_with_frames_removed
  File "/opt/airflow/dags/ETL_Games.py", line 13, in <module>
    conn = redshift_conn()
  File "/opt/airflow/dags/modulos/modulo1.py", line 80, in redshift_conn
    return conn
UnboundLocalError: local variable 'conn' referenced before assignment
[2024-05-16 02:31:34,829] {processor.py:653} WARNING - No viable dags retrieved from /opt/airflow/dags/ETL_Games.py
[2024-05-16 02:31:34,849] {processor.py:161} INFO - Processing /opt/airflow/dags/ETL_Games.py took 0.499 seconds
[2024-05-16 02:31:44,908] {processor.py:153} INFO - Started process (PID=480) to work on /opt/airflow/dags/ETL_Games.py
[2024-05-16 02:31:44,908] {processor.py:641} INFO - Processing file /opt/airflow/dags/ETL_Games.py for tasks to queue
[2024-05-16 02:31:44,909] {logging_mixin.py:115} INFO - [2024-05-16 02:31:44,909] {dagbag.py:508} INFO - Filling up the DagBag from /opt/airflow/dags/ETL_Games.py
[2024-05-16 02:31:45,256] {logging_mixin.py:115} INFO - No es posible conectar a Redshift
[2024-05-16 02:31:45,256] {logging_mixin.py:115} INFO - connection to server on socket "/var/run/postgresql/.s.PGSQL.5432" failed: No such file or directory
	Is the server running locally and accepting connections on that socket?
[2024-05-16 02:31:45,265] {logging_mixin.py:115} INFO - [2024-05-16 02:31:45,257] {dagbag.py:321} ERROR - Failed to import: /opt/airflow/dags/ETL_Games.py
Traceback (most recent call last):
  File "/home/airflow/.local/lib/python3.7/site-packages/airflow/models/dagbag.py", line 318, in parse
    loader.exec_module(new_module)
  File "<frozen importlib._bootstrap_external>", line 728, in exec_module
  File "<frozen importlib._bootstrap>", line 219, in _call_with_frames_removed
  File "/opt/airflow/dags/ETL_Games.py", line 13, in <module>
    conn = redshift_conn()
  File "/opt/airflow/dags/modulos/modulo1.py", line 80, in redshift_conn
    return conn
UnboundLocalError: local variable 'conn' referenced before assignment
[2024-05-16 02:31:45,267] {processor.py:653} WARNING - No viable dags retrieved from /opt/airflow/dags/ETL_Games.py
[2024-05-16 02:31:45,284] {processor.py:161} INFO - Processing /opt/airflow/dags/ETL_Games.py took 0.380 seconds
[2024-05-16 02:31:52,338] {processor.py:153} INFO - Started process (PID=486) to work on /opt/airflow/dags/ETL_Games.py
[2024-05-16 02:31:52,339] {processor.py:641} INFO - Processing file /opt/airflow/dags/ETL_Games.py for tasks to queue
[2024-05-16 02:31:52,340] {logging_mixin.py:115} INFO - [2024-05-16 02:31:52,340] {dagbag.py:508} INFO - Filling up the DagBag from /opt/airflow/dags/ETL_Games.py
[2024-05-16 02:31:52,755] {logging_mixin.py:115} INFO - [2024-05-16 02:31:52,751] {dagbag.py:321} ERROR - Failed to import: /opt/airflow/dags/ETL_Games.py
Traceback (most recent call last):
  File "/home/airflow/.local/lib/python3.7/site-packages/airflow/models/dagbag.py", line 318, in parse
    loader.exec_module(new_module)
  File "<frozen importlib._bootstrap_external>", line 728, in exec_module
  File "<frozen importlib._bootstrap>", line 219, in _call_with_frames_removed
  File "/opt/airflow/dags/ETL_Games.py", line 15, in <module>
    load_dotenv()
NameError: name 'load_dotenv' is not defined
[2024-05-16 02:31:52,757] {processor.py:653} WARNING - No viable dags retrieved from /opt/airflow/dags/ETL_Games.py
[2024-05-16 02:31:52,781] {processor.py:161} INFO - Processing /opt/airflow/dags/ETL_Games.py took 0.447 seconds
[2024-05-16 02:31:55,827] {processor.py:153} INFO - Started process (PID=492) to work on /opt/airflow/dags/ETL_Games.py
[2024-05-16 02:31:55,828] {processor.py:641} INFO - Processing file /opt/airflow/dags/ETL_Games.py for tasks to queue
[2024-05-16 02:31:55,829] {logging_mixin.py:115} INFO - [2024-05-16 02:31:55,829] {dagbag.py:508} INFO - Filling up the DagBag from /opt/airflow/dags/ETL_Games.py
[2024-05-16 02:31:56,224] {logging_mixin.py:115} INFO - [2024-05-16 02:31:56,221] {dagbag.py:321} ERROR - Failed to import: /opt/airflow/dags/ETL_Games.py
Traceback (most recent call last):
  File "/home/airflow/.local/lib/python3.7/site-packages/airflow/models/dagbag.py", line 318, in parse
    loader.exec_module(new_module)
  File "<frozen importlib._bootstrap_external>", line 728, in exec_module
  File "<frozen importlib._bootstrap>", line 219, in _call_with_frames_removed
  File "/opt/airflow/dags/ETL_Games.py", line 15, in <module>
    load_dotenv()
NameError: name 'load_dotenv' is not defined
[2024-05-16 02:31:56,225] {processor.py:653} WARNING - No viable dags retrieved from /opt/airflow/dags/ETL_Games.py
[2024-05-16 02:31:56,242] {processor.py:161} INFO - Processing /opt/airflow/dags/ETL_Games.py took 0.419 seconds
[2024-05-16 02:32:06,307] {processor.py:153} INFO - Started process (PID=498) to work on /opt/airflow/dags/ETL_Games.py
[2024-05-16 02:32:06,308] {processor.py:641} INFO - Processing file /opt/airflow/dags/ETL_Games.py for tasks to queue
[2024-05-16 02:32:06,309] {logging_mixin.py:115} INFO - [2024-05-16 02:32:06,309] {dagbag.py:508} INFO - Filling up the DagBag from /opt/airflow/dags/ETL_Games.py
[2024-05-16 02:32:06,664] {logging_mixin.py:115} INFO - [2024-05-16 02:32:06,660] {dagbag.py:321} ERROR - Failed to import: /opt/airflow/dags/ETL_Games.py
Traceback (most recent call last):
  File "/home/airflow/.local/lib/python3.7/site-packages/airflow/models/dagbag.py", line 318, in parse
    loader.exec_module(new_module)
  File "<frozen importlib._bootstrap_external>", line 728, in exec_module
  File "<frozen importlib._bootstrap>", line 219, in _call_with_frames_removed
  File "/opt/airflow/dags/ETL_Games.py", line 15, in <module>
    load_dotenv()
NameError: name 'load_dotenv' is not defined
[2024-05-16 02:32:06,666] {processor.py:653} WARNING - No viable dags retrieved from /opt/airflow/dags/ETL_Games.py
[2024-05-16 02:32:06,682] {processor.py:161} INFO - Processing /opt/airflow/dags/ETL_Games.py took 0.378 seconds
[2024-05-16 02:32:16,748] {processor.py:153} INFO - Started process (PID=504) to work on /opt/airflow/dags/ETL_Games.py
[2024-05-16 02:32:16,749] {processor.py:641} INFO - Processing file /opt/airflow/dags/ETL_Games.py for tasks to queue
[2024-05-16 02:32:16,750] {logging_mixin.py:115} INFO - [2024-05-16 02:32:16,750] {dagbag.py:508} INFO - Filling up the DagBag from /opt/airflow/dags/ETL_Games.py
[2024-05-16 02:32:17,194] {logging_mixin.py:115} INFO - [2024-05-16 02:32:17,187] {dagbag.py:321} ERROR - Failed to import: /opt/airflow/dags/ETL_Games.py
Traceback (most recent call last):
  File "/home/airflow/.local/lib/python3.7/site-packages/airflow/models/dagbag.py", line 318, in parse
    loader.exec_module(new_module)
  File "<frozen importlib._bootstrap_external>", line 728, in exec_module
  File "<frozen importlib._bootstrap>", line 219, in _call_with_frames_removed
  File "/opt/airflow/dags/ETL_Games.py", line 15, in <module>
    load_dotenv()
NameError: name 'load_dotenv' is not defined
[2024-05-16 02:32:17,197] {processor.py:653} WARNING - No viable dags retrieved from /opt/airflow/dags/ETL_Games.py
[2024-05-16 02:32:17,229] {processor.py:161} INFO - Processing /opt/airflow/dags/ETL_Games.py took 0.485 seconds
[2024-05-16 02:32:27,308] {processor.py:153} INFO - Started process (PID=510) to work on /opt/airflow/dags/ETL_Games.py
[2024-05-16 02:32:27,309] {processor.py:641} INFO - Processing file /opt/airflow/dags/ETL_Games.py for tasks to queue
[2024-05-16 02:32:27,311] {logging_mixin.py:115} INFO - [2024-05-16 02:32:27,310] {dagbag.py:508} INFO - Filling up the DagBag from /opt/airflow/dags/ETL_Games.py
[2024-05-16 02:32:27,672] {logging_mixin.py:115} INFO - [2024-05-16 02:32:27,669] {dagbag.py:321} ERROR - Failed to import: /opt/airflow/dags/ETL_Games.py
Traceback (most recent call last):
  File "/home/airflow/.local/lib/python3.7/site-packages/airflow/models/dagbag.py", line 318, in parse
    loader.exec_module(new_module)
  File "<frozen importlib._bootstrap_external>", line 728, in exec_module
  File "<frozen importlib._bootstrap>", line 219, in _call_with_frames_removed
  File "/opt/airflow/dags/ETL_Games.py", line 15, in <module>
    load_dotenv()
NameError: name 'load_dotenv' is not defined
[2024-05-16 02:32:27,673] {processor.py:653} WARNING - No viable dags retrieved from /opt/airflow/dags/ETL_Games.py
[2024-05-16 02:32:27,688] {processor.py:161} INFO - Processing /opt/airflow/dags/ETL_Games.py took 0.384 seconds
[2024-05-16 02:32:29,311] {processor.py:153} INFO - Started process (PID=516) to work on /opt/airflow/dags/ETL_Games.py
[2024-05-16 02:32:29,312] {processor.py:641} INFO - Processing file /opt/airflow/dags/ETL_Games.py for tasks to queue
[2024-05-16 02:32:29,313] {logging_mixin.py:115} INFO - [2024-05-16 02:32:29,312] {dagbag.py:508} INFO - Filling up the DagBag from /opt/airflow/dags/ETL_Games.py
[2024-05-16 02:32:29,808] {logging_mixin.py:115} INFO - [2024-05-16 02:32:29,804] {dagbag.py:321} ERROR - Failed to import: /opt/airflow/dags/ETL_Games.py
Traceback (most recent call last):
  File "/home/airflow/.local/lib/python3.7/site-packages/airflow/models/dagbag.py", line 318, in parse
    loader.exec_module(new_module)
  File "<frozen importlib._bootstrap_external>", line 728, in exec_module
  File "<frozen importlib._bootstrap>", line 219, in _call_with_frames_removed
  File "/opt/airflow/dags/ETL_Games.py", line 16, in <module>
    load_dotenv()
NameError: name 'load_dotenv' is not defined
[2024-05-16 02:32:29,809] {processor.py:653} WARNING - No viable dags retrieved from /opt/airflow/dags/ETL_Games.py
[2024-05-16 02:32:29,830] {processor.py:161} INFO - Processing /opt/airflow/dags/ETL_Games.py took 0.522 seconds
[2024-05-16 02:32:30,731] {processor.py:153} INFO - Started process (PID=522) to work on /opt/airflow/dags/ETL_Games.py
[2024-05-16 02:32:30,732] {processor.py:641} INFO - Processing file /opt/airflow/dags/ETL_Games.py for tasks to queue
[2024-05-16 02:32:30,733] {logging_mixin.py:115} INFO - [2024-05-16 02:32:30,733] {dagbag.py:508} INFO - Filling up the DagBag from /opt/airflow/dags/ETL_Games.py
[2024-05-16 02:32:31,232] {logging_mixin.py:115} INFO - [2024-05-16 02:32:31,228] {dagbag.py:321} ERROR - Failed to import: /opt/airflow/dags/ETL_Games.py
Traceback (most recent call last):
  File "/home/airflow/.local/lib/python3.7/site-packages/airflow/models/dagbag.py", line 318, in parse
    loader.exec_module(new_module)
  File "<frozen importlib._bootstrap_external>", line 728, in exec_module
  File "<frozen importlib._bootstrap>", line 219, in _call_with_frames_removed
  File "/opt/airflow/dags/ETL_Games.py", line 7, in <module>
    from dotenv import load_dotenv
ModuleNotFoundError: No module named 'dotenv'
[2024-05-16 02:32:31,234] {processor.py:653} WARNING - No viable dags retrieved from /opt/airflow/dags/ETL_Games.py
[2024-05-16 02:32:31,256] {processor.py:161} INFO - Processing /opt/airflow/dags/ETL_Games.py took 0.528 seconds
[2024-05-16 02:32:36,889] {processor.py:153} INFO - Started process (PID=528) to work on /opt/airflow/dags/ETL_Games.py
[2024-05-16 02:32:36,890] {processor.py:641} INFO - Processing file /opt/airflow/dags/ETL_Games.py for tasks to queue
[2024-05-16 02:32:36,890] {logging_mixin.py:115} INFO - [2024-05-16 02:32:36,890] {dagbag.py:508} INFO - Filling up the DagBag from /opt/airflow/dags/ETL_Games.py
[2024-05-16 02:32:37,252] {logging_mixin.py:115} INFO - [2024-05-16 02:32:37,247] {dagbag.py:321} ERROR - Failed to import: /opt/airflow/dags/ETL_Games.py
Traceback (most recent call last):
  File "/home/airflow/.local/lib/python3.7/site-packages/airflow/models/dagbag.py", line 318, in parse
    loader.exec_module(new_module)
  File "<frozen importlib._bootstrap_external>", line 728, in exec_module
  File "<frozen importlib._bootstrap>", line 219, in _call_with_frames_removed
  File "/opt/airflow/dags/ETL_Games.py", line 7, in <module>
    from dotenv import load_dotenv
ModuleNotFoundError: No module named 'dotenv'
[2024-05-16 02:32:37,253] {processor.py:653} WARNING - No viable dags retrieved from /opt/airflow/dags/ETL_Games.py
[2024-05-16 02:32:37,288] {processor.py:161} INFO - Processing /opt/airflow/dags/ETL_Games.py took 0.402 seconds
[2024-05-16 02:32:47,345] {processor.py:153} INFO - Started process (PID=534) to work on /opt/airflow/dags/ETL_Games.py
[2024-05-16 02:32:47,345] {processor.py:641} INFO - Processing file /opt/airflow/dags/ETL_Games.py for tasks to queue
[2024-05-16 02:32:47,346] {logging_mixin.py:115} INFO - [2024-05-16 02:32:47,346] {dagbag.py:508} INFO - Filling up the DagBag from /opt/airflow/dags/ETL_Games.py
[2024-05-16 02:32:47,712] {logging_mixin.py:115} INFO - [2024-05-16 02:32:47,708] {dagbag.py:321} ERROR - Failed to import: /opt/airflow/dags/ETL_Games.py
Traceback (most recent call last):
  File "/home/airflow/.local/lib/python3.7/site-packages/airflow/models/dagbag.py", line 318, in parse
    loader.exec_module(new_module)
  File "<frozen importlib._bootstrap_external>", line 728, in exec_module
  File "<frozen importlib._bootstrap>", line 219, in _call_with_frames_removed
  File "/opt/airflow/dags/ETL_Games.py", line 7, in <module>
    from dotenv import load_dotenv
ModuleNotFoundError: No module named 'dotenv'
[2024-05-16 02:32:47,713] {processor.py:653} WARNING - No viable dags retrieved from /opt/airflow/dags/ETL_Games.py
[2024-05-16 02:32:47,731] {processor.py:161} INFO - Processing /opt/airflow/dags/ETL_Games.py took 0.390 seconds
[2024-05-16 02:32:57,796] {processor.py:153} INFO - Started process (PID=540) to work on /opt/airflow/dags/ETL_Games.py
[2024-05-16 02:32:57,797] {processor.py:641} INFO - Processing file /opt/airflow/dags/ETL_Games.py for tasks to queue
[2024-05-16 02:32:57,798] {logging_mixin.py:115} INFO - [2024-05-16 02:32:57,798] {dagbag.py:508} INFO - Filling up the DagBag from /opt/airflow/dags/ETL_Games.py
[2024-05-16 02:32:58,286] {logging_mixin.py:115} INFO - [2024-05-16 02:32:58,282] {dagbag.py:321} ERROR - Failed to import: /opt/airflow/dags/ETL_Games.py
Traceback (most recent call last):
  File "/home/airflow/.local/lib/python3.7/site-packages/airflow/models/dagbag.py", line 318, in parse
    loader.exec_module(new_module)
  File "<frozen importlib._bootstrap_external>", line 728, in exec_module
  File "<frozen importlib._bootstrap>", line 219, in _call_with_frames_removed
  File "/opt/airflow/dags/ETL_Games.py", line 7, in <module>
    from dotenv import load_dotenv
ModuleNotFoundError: No module named 'dotenv'
[2024-05-16 02:32:58,287] {processor.py:653} WARNING - No viable dags retrieved from /opt/airflow/dags/ETL_Games.py
[2024-05-16 02:32:58,307] {processor.py:161} INFO - Processing /opt/airflow/dags/ETL_Games.py took 0.515 seconds
[2024-05-16 02:33:08,375] {processor.py:153} INFO - Started process (PID=546) to work on /opt/airflow/dags/ETL_Games.py
[2024-05-16 02:33:08,376] {processor.py:641} INFO - Processing file /opt/airflow/dags/ETL_Games.py for tasks to queue
[2024-05-16 02:33:08,376] {logging_mixin.py:115} INFO - [2024-05-16 02:33:08,376] {dagbag.py:508} INFO - Filling up the DagBag from /opt/airflow/dags/ETL_Games.py
[2024-05-16 02:33:08,688] {logging_mixin.py:115} INFO - [2024-05-16 02:33:08,684] {dagbag.py:321} ERROR - Failed to import: /opt/airflow/dags/ETL_Games.py
Traceback (most recent call last):
  File "/home/airflow/.local/lib/python3.7/site-packages/airflow/models/dagbag.py", line 318, in parse
    loader.exec_module(new_module)
  File "<frozen importlib._bootstrap_external>", line 728, in exec_module
  File "<frozen importlib._bootstrap>", line 219, in _call_with_frames_removed
  File "/opt/airflow/dags/ETL_Games.py", line 7, in <module>
    from dotenv import load_dotenv
ModuleNotFoundError: No module named 'dotenv'
[2024-05-16 02:33:08,688] {processor.py:653} WARNING - No viable dags retrieved from /opt/airflow/dags/ETL_Games.py
[2024-05-16 02:33:08,705] {processor.py:161} INFO - Processing /opt/airflow/dags/ETL_Games.py took 0.334 seconds
[2024-05-16 02:35:15,439] {processor.py:153} INFO - Started process (PID=172) to work on /opt/airflow/dags/ETL_Games.py
[2024-05-16 02:35:15,439] {processor.py:641} INFO - Processing file /opt/airflow/dags/ETL_Games.py for tasks to queue
[2024-05-16 02:35:15,440] {logging_mixin.py:115} INFO - [2024-05-16 02:35:15,440] {dagbag.py:508} INFO - Filling up the DagBag from /opt/airflow/dags/ETL_Games.py
[2024-05-16 02:35:15,997] {logging_mixin.py:115} INFO - [2024-05-16 02:35:15,991] {dagbag.py:321} ERROR - Failed to import: /opt/airflow/dags/ETL_Games.py
Traceback (most recent call last):
  File "/home/airflow/.local/lib/python3.7/site-packages/airflow/models/dagbag.py", line 318, in parse
    loader.exec_module(new_module)
  File "<frozen importlib._bootstrap_external>", line 728, in exec_module
  File "<frozen importlib._bootstrap>", line 219, in _call_with_frames_removed
  File "/opt/airflow/dags/ETL_Games.py", line 7, in <module>
    from dotenv import load_dotenv
ModuleNotFoundError: No module named 'dotenv'
[2024-05-16 02:35:15,998] {processor.py:653} WARNING - No viable dags retrieved from /opt/airflow/dags/ETL_Games.py
[2024-05-16 02:35:16,020] {processor.py:161} INFO - Processing /opt/airflow/dags/ETL_Games.py took 0.585 seconds
[2024-05-16 02:35:26,159] {processor.py:153} INFO - Started process (PID=179) to work on /opt/airflow/dags/ETL_Games.py
[2024-05-16 02:35:26,161] {processor.py:641} INFO - Processing file /opt/airflow/dags/ETL_Games.py for tasks to queue
[2024-05-16 02:35:26,162] {logging_mixin.py:115} INFO - [2024-05-16 02:35:26,162] {dagbag.py:508} INFO - Filling up the DagBag from /opt/airflow/dags/ETL_Games.py
[2024-05-16 02:35:26,805] {logging_mixin.py:115} INFO - [2024-05-16 02:35:26,800] {dagbag.py:321} ERROR - Failed to import: /opt/airflow/dags/ETL_Games.py
Traceback (most recent call last):
  File "/home/airflow/.local/lib/python3.7/site-packages/airflow/models/dagbag.py", line 318, in parse
    loader.exec_module(new_module)
  File "<frozen importlib._bootstrap_external>", line 728, in exec_module
  File "<frozen importlib._bootstrap>", line 219, in _call_with_frames_removed
  File "/opt/airflow/dags/ETL_Games.py", line 7, in <module>
    from dotenv import load_dotenv
ModuleNotFoundError: No module named 'dotenv'
[2024-05-16 02:35:26,807] {processor.py:653} WARNING - No viable dags retrieved from /opt/airflow/dags/ETL_Games.py
[2024-05-16 02:35:26,834] {processor.py:161} INFO - Processing /opt/airflow/dags/ETL_Games.py took 0.682 seconds
[2024-05-16 02:35:36,915] {processor.py:153} INFO - Started process (PID=185) to work on /opt/airflow/dags/ETL_Games.py
[2024-05-16 02:35:36,916] {processor.py:641} INFO - Processing file /opt/airflow/dags/ETL_Games.py for tasks to queue
[2024-05-16 02:35:36,918] {logging_mixin.py:115} INFO - [2024-05-16 02:35:36,917] {dagbag.py:508} INFO - Filling up the DagBag from /opt/airflow/dags/ETL_Games.py
[2024-05-16 02:35:37,864] {logging_mixin.py:115} INFO - [2024-05-16 02:35:37,860] {dagbag.py:321} ERROR - Failed to import: /opt/airflow/dags/ETL_Games.py
Traceback (most recent call last):
  File "/home/airflow/.local/lib/python3.7/site-packages/airflow/models/dagbag.py", line 318, in parse
    loader.exec_module(new_module)
  File "<frozen importlib._bootstrap_external>", line 728, in exec_module
  File "<frozen importlib._bootstrap>", line 219, in _call_with_frames_removed
  File "/opt/airflow/dags/ETL_Games.py", line 7, in <module>
    from dotenv import load_dotenv
ModuleNotFoundError: No module named 'dotenv'
[2024-05-16 02:35:37,866] {processor.py:653} WARNING - No viable dags retrieved from /opt/airflow/dags/ETL_Games.py
[2024-05-16 02:35:37,887] {processor.py:161} INFO - Processing /opt/airflow/dags/ETL_Games.py took 0.979 seconds
[2024-05-16 02:35:47,937] {processor.py:153} INFO - Started process (PID=191) to work on /opt/airflow/dags/ETL_Games.py
[2024-05-16 02:35:47,937] {processor.py:641} INFO - Processing file /opt/airflow/dags/ETL_Games.py for tasks to queue
[2024-05-16 02:35:47,938] {logging_mixin.py:115} INFO - [2024-05-16 02:35:47,938] {dagbag.py:508} INFO - Filling up the DagBag from /opt/airflow/dags/ETL_Games.py
[2024-05-16 02:35:48,207] {logging_mixin.py:115} INFO - [2024-05-16 02:35:48,203] {dagbag.py:321} ERROR - Failed to import: /opt/airflow/dags/ETL_Games.py
Traceback (most recent call last):
  File "/home/airflow/.local/lib/python3.7/site-packages/airflow/models/dagbag.py", line 318, in parse
    loader.exec_module(new_module)
  File "<frozen importlib._bootstrap_external>", line 728, in exec_module
  File "<frozen importlib._bootstrap>", line 219, in _call_with_frames_removed
  File "/opt/airflow/dags/ETL_Games.py", line 7, in <module>
    from dotenv import load_dotenv
ModuleNotFoundError: No module named 'dotenv'
[2024-05-16 02:35:48,208] {processor.py:653} WARNING - No viable dags retrieved from /opt/airflow/dags/ETL_Games.py
[2024-05-16 02:35:48,220] {processor.py:161} INFO - Processing /opt/airflow/dags/ETL_Games.py took 0.285 seconds
[2024-05-16 02:35:58,281] {processor.py:153} INFO - Started process (PID=197) to work on /opt/airflow/dags/ETL_Games.py
[2024-05-16 02:35:58,281] {processor.py:641} INFO - Processing file /opt/airflow/dags/ETL_Games.py for tasks to queue
[2024-05-16 02:35:58,282] {logging_mixin.py:115} INFO - [2024-05-16 02:35:58,282] {dagbag.py:508} INFO - Filling up the DagBag from /opt/airflow/dags/ETL_Games.py
[2024-05-16 02:35:58,615] {logging_mixin.py:115} INFO - [2024-05-16 02:35:58,612] {dagbag.py:321} ERROR - Failed to import: /opt/airflow/dags/ETL_Games.py
Traceback (most recent call last):
  File "/home/airflow/.local/lib/python3.7/site-packages/airflow/models/dagbag.py", line 318, in parse
    loader.exec_module(new_module)
  File "<frozen importlib._bootstrap_external>", line 728, in exec_module
  File "<frozen importlib._bootstrap>", line 219, in _call_with_frames_removed
  File "/opt/airflow/dags/ETL_Games.py", line 7, in <module>
    from dotenv import load_dotenv
ModuleNotFoundError: No module named 'dotenv'
[2024-05-16 02:35:58,616] {processor.py:653} WARNING - No viable dags retrieved from /opt/airflow/dags/ETL_Games.py
[2024-05-16 02:35:58,632] {processor.py:161} INFO - Processing /opt/airflow/dags/ETL_Games.py took 0.354 seconds
[2024-05-16 02:36:08,888] {processor.py:153} INFO - Started process (PID=203) to work on /opt/airflow/dags/ETL_Games.py
[2024-05-16 02:36:08,891] {processor.py:641} INFO - Processing file /opt/airflow/dags/ETL_Games.py for tasks to queue
[2024-05-16 02:36:08,900] {logging_mixin.py:115} INFO - [2024-05-16 02:36:08,893] {dagbag.py:508} INFO - Filling up the DagBag from /opt/airflow/dags/ETL_Games.py
[2024-05-16 02:36:09,304] {logging_mixin.py:115} INFO - [2024-05-16 02:36:09,299] {dagbag.py:321} ERROR - Failed to import: /opt/airflow/dags/ETL_Games.py
Traceback (most recent call last):
  File "/home/airflow/.local/lib/python3.7/site-packages/airflow/models/dagbag.py", line 318, in parse
    loader.exec_module(new_module)
  File "<frozen importlib._bootstrap_external>", line 728, in exec_module
  File "<frozen importlib._bootstrap>", line 219, in _call_with_frames_removed
  File "/opt/airflow/dags/ETL_Games.py", line 7, in <module>
    from dotenv import load_dotenv
ModuleNotFoundError: No module named 'dotenv'
[2024-05-16 02:36:09,305] {processor.py:653} WARNING - No viable dags retrieved from /opt/airflow/dags/ETL_Games.py
[2024-05-16 02:36:09,320] {processor.py:161} INFO - Processing /opt/airflow/dags/ETL_Games.py took 0.439 seconds
[2024-05-16 02:36:19,363] {processor.py:153} INFO - Started process (PID=209) to work on /opt/airflow/dags/ETL_Games.py
[2024-05-16 02:36:19,364] {processor.py:641} INFO - Processing file /opt/airflow/dags/ETL_Games.py for tasks to queue
[2024-05-16 02:36:19,364] {logging_mixin.py:115} INFO - [2024-05-16 02:36:19,364] {dagbag.py:508} INFO - Filling up the DagBag from /opt/airflow/dags/ETL_Games.py
[2024-05-16 02:36:19,692] {logging_mixin.py:115} INFO - [2024-05-16 02:36:19,688] {dagbag.py:321} ERROR - Failed to import: /opt/airflow/dags/ETL_Games.py
Traceback (most recent call last):
  File "/home/airflow/.local/lib/python3.7/site-packages/airflow/models/dagbag.py", line 318, in parse
    loader.exec_module(new_module)
  File "<frozen importlib._bootstrap_external>", line 728, in exec_module
  File "<frozen importlib._bootstrap>", line 219, in _call_with_frames_removed
  File "/opt/airflow/dags/ETL_Games.py", line 7, in <module>
    from dotenv import load_dotenv
ModuleNotFoundError: No module named 'dotenv'
[2024-05-16 02:36:19,693] {processor.py:653} WARNING - No viable dags retrieved from /opt/airflow/dags/ETL_Games.py
[2024-05-16 02:36:19,706] {processor.py:161} INFO - Processing /opt/airflow/dags/ETL_Games.py took 0.345 seconds
[2024-05-16 02:36:29,771] {processor.py:153} INFO - Started process (PID=215) to work on /opt/airflow/dags/ETL_Games.py
[2024-05-16 02:36:29,772] {processor.py:641} INFO - Processing file /opt/airflow/dags/ETL_Games.py for tasks to queue
[2024-05-16 02:36:29,772] {logging_mixin.py:115} INFO - [2024-05-16 02:36:29,772] {dagbag.py:508} INFO - Filling up the DagBag from /opt/airflow/dags/ETL_Games.py
[2024-05-16 02:36:30,082] {logging_mixin.py:115} INFO - [2024-05-16 02:36:30,077] {dagbag.py:321} ERROR - Failed to import: /opt/airflow/dags/ETL_Games.py
Traceback (most recent call last):
  File "/home/airflow/.local/lib/python3.7/site-packages/airflow/models/dagbag.py", line 318, in parse
    loader.exec_module(new_module)
  File "<frozen importlib._bootstrap_external>", line 728, in exec_module
  File "<frozen importlib._bootstrap>", line 219, in _call_with_frames_removed
  File "/opt/airflow/dags/ETL_Games.py", line 7, in <module>
    from dotenv import load_dotenv
ModuleNotFoundError: No module named 'dotenv'
[2024-05-16 02:36:30,083] {processor.py:653} WARNING - No viable dags retrieved from /opt/airflow/dags/ETL_Games.py
[2024-05-16 02:36:30,099] {processor.py:161} INFO - Processing /opt/airflow/dags/ETL_Games.py took 0.332 seconds
[2024-05-16 02:36:40,154] {processor.py:153} INFO - Started process (PID=221) to work on /opt/airflow/dags/ETL_Games.py
[2024-05-16 02:36:40,154] {processor.py:641} INFO - Processing file /opt/airflow/dags/ETL_Games.py for tasks to queue
[2024-05-16 02:36:40,155] {logging_mixin.py:115} INFO - [2024-05-16 02:36:40,155] {dagbag.py:508} INFO - Filling up the DagBag from /opt/airflow/dags/ETL_Games.py
[2024-05-16 02:36:40,400] {logging_mixin.py:115} INFO - [2024-05-16 02:36:40,396] {dagbag.py:321} ERROR - Failed to import: /opt/airflow/dags/ETL_Games.py
Traceback (most recent call last):
  File "/home/airflow/.local/lib/python3.7/site-packages/airflow/models/dagbag.py", line 318, in parse
    loader.exec_module(new_module)
  File "<frozen importlib._bootstrap_external>", line 728, in exec_module
  File "<frozen importlib._bootstrap>", line 219, in _call_with_frames_removed
  File "/opt/airflow/dags/ETL_Games.py", line 7, in <module>
    from dotenv import load_dotenv
ModuleNotFoundError: No module named 'dotenv'
[2024-05-16 02:36:40,402] {processor.py:653} WARNING - No viable dags retrieved from /opt/airflow/dags/ETL_Games.py
[2024-05-16 02:36:40,415] {processor.py:161} INFO - Processing /opt/airflow/dags/ETL_Games.py took 0.263 seconds
[2024-05-16 02:36:50,488] {processor.py:153} INFO - Started process (PID=227) to work on /opt/airflow/dags/ETL_Games.py
[2024-05-16 02:36:50,489] {processor.py:641} INFO - Processing file /opt/airflow/dags/ETL_Games.py for tasks to queue
[2024-05-16 02:36:50,489] {logging_mixin.py:115} INFO - [2024-05-16 02:36:50,489] {dagbag.py:508} INFO - Filling up the DagBag from /opt/airflow/dags/ETL_Games.py
[2024-05-16 02:36:50,764] {logging_mixin.py:115} INFO - [2024-05-16 02:36:50,761] {dagbag.py:321} ERROR - Failed to import: /opt/airflow/dags/ETL_Games.py
Traceback (most recent call last):
  File "/home/airflow/.local/lib/python3.7/site-packages/airflow/models/dagbag.py", line 318, in parse
    loader.exec_module(new_module)
  File "<frozen importlib._bootstrap_external>", line 728, in exec_module
  File "<frozen importlib._bootstrap>", line 219, in _call_with_frames_removed
  File "/opt/airflow/dags/ETL_Games.py", line 7, in <module>
    from dotenv import load_dotenv
ModuleNotFoundError: No module named 'dotenv'
[2024-05-16 02:36:50,765] {processor.py:653} WARNING - No viable dags retrieved from /opt/airflow/dags/ETL_Games.py
[2024-05-16 02:36:50,779] {processor.py:161} INFO - Processing /opt/airflow/dags/ETL_Games.py took 0.293 seconds
[2024-05-16 02:37:00,827] {processor.py:153} INFO - Started process (PID=233) to work on /opt/airflow/dags/ETL_Games.py
[2024-05-16 02:37:00,827] {processor.py:641} INFO - Processing file /opt/airflow/dags/ETL_Games.py for tasks to queue
[2024-05-16 02:37:00,828] {logging_mixin.py:115} INFO - [2024-05-16 02:37:00,828] {dagbag.py:508} INFO - Filling up the DagBag from /opt/airflow/dags/ETL_Games.py
[2024-05-16 02:37:01,143] {logging_mixin.py:115} INFO - [2024-05-16 02:37:01,141] {dagbag.py:321} ERROR - Failed to import: /opt/airflow/dags/ETL_Games.py
Traceback (most recent call last):
  File "/home/airflow/.local/lib/python3.7/site-packages/airflow/models/dagbag.py", line 318, in parse
    loader.exec_module(new_module)
  File "<frozen importlib._bootstrap_external>", line 728, in exec_module
  File "<frozen importlib._bootstrap>", line 219, in _call_with_frames_removed
  File "/opt/airflow/dags/ETL_Games.py", line 7, in <module>
    from dotenv import load_dotenv
ModuleNotFoundError: No module named 'dotenv'
[2024-05-16 02:37:01,144] {processor.py:653} WARNING - No viable dags retrieved from /opt/airflow/dags/ETL_Games.py
[2024-05-16 02:37:01,161] {processor.py:161} INFO - Processing /opt/airflow/dags/ETL_Games.py took 0.338 seconds
[2024-05-16 02:37:11,217] {processor.py:153} INFO - Started process (PID=239) to work on /opt/airflow/dags/ETL_Games.py
[2024-05-16 02:37:11,218] {processor.py:641} INFO - Processing file /opt/airflow/dags/ETL_Games.py for tasks to queue
[2024-05-16 02:37:11,218] {logging_mixin.py:115} INFO - [2024-05-16 02:37:11,218] {dagbag.py:508} INFO - Filling up the DagBag from /opt/airflow/dags/ETL_Games.py
[2024-05-16 02:37:11,517] {logging_mixin.py:115} INFO - [2024-05-16 02:37:11,513] {dagbag.py:321} ERROR - Failed to import: /opt/airflow/dags/ETL_Games.py
Traceback (most recent call last):
  File "/home/airflow/.local/lib/python3.7/site-packages/airflow/models/dagbag.py", line 318, in parse
    loader.exec_module(new_module)
  File "<frozen importlib._bootstrap_external>", line 728, in exec_module
  File "<frozen importlib._bootstrap>", line 219, in _call_with_frames_removed
  File "/opt/airflow/dags/ETL_Games.py", line 7, in <module>
    from dotenv import load_dotenv
ModuleNotFoundError: No module named 'dotenv'
[2024-05-16 02:37:11,518] {processor.py:653} WARNING - No viable dags retrieved from /opt/airflow/dags/ETL_Games.py
[2024-05-16 02:37:11,532] {processor.py:161} INFO - Processing /opt/airflow/dags/ETL_Games.py took 0.317 seconds
[2024-05-16 02:37:21,622] {processor.py:153} INFO - Started process (PID=245) to work on /opt/airflow/dags/ETL_Games.py
[2024-05-16 02:37:21,623] {processor.py:641} INFO - Processing file /opt/airflow/dags/ETL_Games.py for tasks to queue
[2024-05-16 02:37:21,624] {logging_mixin.py:115} INFO - [2024-05-16 02:37:21,624] {dagbag.py:508} INFO - Filling up the DagBag from /opt/airflow/dags/ETL_Games.py
[2024-05-16 02:37:21,910] {logging_mixin.py:115} INFO - [2024-05-16 02:37:21,905] {dagbag.py:321} ERROR - Failed to import: /opt/airflow/dags/ETL_Games.py
Traceback (most recent call last):
  File "/home/airflow/.local/lib/python3.7/site-packages/airflow/models/dagbag.py", line 318, in parse
    loader.exec_module(new_module)
  File "<frozen importlib._bootstrap_external>", line 728, in exec_module
  File "<frozen importlib._bootstrap>", line 219, in _call_with_frames_removed
  File "/opt/airflow/dags/ETL_Games.py", line 7, in <module>
    from dotenv import load_dotenv
ModuleNotFoundError: No module named 'dotenv'
[2024-05-16 02:37:21,910] {processor.py:653} WARNING - No viable dags retrieved from /opt/airflow/dags/ETL_Games.py
[2024-05-16 02:37:21,925] {processor.py:161} INFO - Processing /opt/airflow/dags/ETL_Games.py took 0.306 seconds
[2024-05-16 02:42:40,611] {processor.py:153} INFO - Started process (PID=172) to work on /opt/airflow/dags/ETL_Games.py
[2024-05-16 02:42:40,612] {processor.py:641} INFO - Processing file /opt/airflow/dags/ETL_Games.py for tasks to queue
[2024-05-16 02:42:40,613] {logging_mixin.py:115} INFO - [2024-05-16 02:42:40,613] {dagbag.py:508} INFO - Filling up the DagBag from /opt/airflow/dags/ETL_Games.py
[2024-05-16 02:42:41,166] {logging_mixin.py:115} INFO - [2024-05-16 02:42:41,162] {dagbag.py:321} ERROR - Failed to import: /opt/airflow/dags/ETL_Games.py
Traceback (most recent call last):
  File "/home/airflow/.local/lib/python3.7/site-packages/airflow/models/dagbag.py", line 318, in parse
    loader.exec_module(new_module)
  File "<frozen importlib._bootstrap_external>", line 728, in exec_module
  File "<frozen importlib._bootstrap>", line 219, in _call_with_frames_removed
  File "/opt/airflow/dags/ETL_Games.py", line 7, in <module>
    from dotenv import load_dotenv
ModuleNotFoundError: No module named 'dotenv'
[2024-05-16 02:42:41,167] {processor.py:653} WARNING - No viable dags retrieved from /opt/airflow/dags/ETL_Games.py
[2024-05-16 02:42:41,192] {processor.py:161} INFO - Processing /opt/airflow/dags/ETL_Games.py took 0.586 seconds
[2024-05-16 02:42:51,286] {processor.py:153} INFO - Started process (PID=179) to work on /opt/airflow/dags/ETL_Games.py
[2024-05-16 02:42:51,287] {processor.py:641} INFO - Processing file /opt/airflow/dags/ETL_Games.py for tasks to queue
[2024-05-16 02:42:51,288] {logging_mixin.py:115} INFO - [2024-05-16 02:42:51,288] {dagbag.py:508} INFO - Filling up the DagBag from /opt/airflow/dags/ETL_Games.py
[2024-05-16 02:42:51,688] {logging_mixin.py:115} INFO - [2024-05-16 02:42:51,685] {dagbag.py:321} ERROR - Failed to import: /opt/airflow/dags/ETL_Games.py
Traceback (most recent call last):
  File "/home/airflow/.local/lib/python3.7/site-packages/airflow/models/dagbag.py", line 318, in parse
    loader.exec_module(new_module)
  File "<frozen importlib._bootstrap_external>", line 728, in exec_module
  File "<frozen importlib._bootstrap>", line 219, in _call_with_frames_removed
  File "/opt/airflow/dags/ETL_Games.py", line 7, in <module>
    from dotenv import load_dotenv
ModuleNotFoundError: No module named 'dotenv'
[2024-05-16 02:42:51,689] {processor.py:653} WARNING - No viable dags retrieved from /opt/airflow/dags/ETL_Games.py
[2024-05-16 02:42:51,707] {processor.py:161} INFO - Processing /opt/airflow/dags/ETL_Games.py took 0.424 seconds
[2024-05-16 02:43:01,762] {processor.py:153} INFO - Started process (PID=185) to work on /opt/airflow/dags/ETL_Games.py
[2024-05-16 02:43:01,763] {processor.py:641} INFO - Processing file /opt/airflow/dags/ETL_Games.py for tasks to queue
[2024-05-16 02:43:01,764] {logging_mixin.py:115} INFO - [2024-05-16 02:43:01,763] {dagbag.py:508} INFO - Filling up the DagBag from /opt/airflow/dags/ETL_Games.py
[2024-05-16 02:43:02,109] {logging_mixin.py:115} INFO - [2024-05-16 02:43:02,106] {dagbag.py:321} ERROR - Failed to import: /opt/airflow/dags/ETL_Games.py
Traceback (most recent call last):
  File "/home/airflow/.local/lib/python3.7/site-packages/airflow/models/dagbag.py", line 318, in parse
    loader.exec_module(new_module)
  File "<frozen importlib._bootstrap_external>", line 728, in exec_module
  File "<frozen importlib._bootstrap>", line 219, in _call_with_frames_removed
  File "/opt/airflow/dags/ETL_Games.py", line 7, in <module>
    from dotenv import load_dotenv
ModuleNotFoundError: No module named 'dotenv'
[2024-05-16 02:43:02,110] {processor.py:653} WARNING - No viable dags retrieved from /opt/airflow/dags/ETL_Games.py
[2024-05-16 02:43:02,125] {processor.py:161} INFO - Processing /opt/airflow/dags/ETL_Games.py took 0.366 seconds
[2024-05-16 02:43:12,191] {processor.py:153} INFO - Started process (PID=191) to work on /opt/airflow/dags/ETL_Games.py
[2024-05-16 02:43:12,192] {processor.py:641} INFO - Processing file /opt/airflow/dags/ETL_Games.py for tasks to queue
[2024-05-16 02:43:12,192] {logging_mixin.py:115} INFO - [2024-05-16 02:43:12,192] {dagbag.py:508} INFO - Filling up the DagBag from /opt/airflow/dags/ETL_Games.py
[2024-05-16 02:43:12,448] {logging_mixin.py:115} INFO - [2024-05-16 02:43:12,443] {dagbag.py:321} ERROR - Failed to import: /opt/airflow/dags/ETL_Games.py
Traceback (most recent call last):
  File "/home/airflow/.local/lib/python3.7/site-packages/airflow/models/dagbag.py", line 318, in parse
    loader.exec_module(new_module)
  File "<frozen importlib._bootstrap_external>", line 728, in exec_module
  File "<frozen importlib._bootstrap>", line 219, in _call_with_frames_removed
  File "/opt/airflow/dags/ETL_Games.py", line 7, in <module>
    from dotenv import load_dotenv
ModuleNotFoundError: No module named 'dotenv'
[2024-05-16 02:43:12,449] {processor.py:653} WARNING - No viable dags retrieved from /opt/airflow/dags/ETL_Games.py
[2024-05-16 02:43:12,469] {processor.py:161} INFO - Processing /opt/airflow/dags/ETL_Games.py took 0.280 seconds
[2024-05-16 02:43:22,535] {processor.py:153} INFO - Started process (PID=197) to work on /opt/airflow/dags/ETL_Games.py
[2024-05-16 02:43:22,536] {processor.py:641} INFO - Processing file /opt/airflow/dags/ETL_Games.py for tasks to queue
[2024-05-16 02:43:22,536] {logging_mixin.py:115} INFO - [2024-05-16 02:43:22,536] {dagbag.py:508} INFO - Filling up the DagBag from /opt/airflow/dags/ETL_Games.py
[2024-05-16 02:43:22,815] {logging_mixin.py:115} INFO - [2024-05-16 02:43:22,810] {dagbag.py:321} ERROR - Failed to import: /opt/airflow/dags/ETL_Games.py
Traceback (most recent call last):
  File "/home/airflow/.local/lib/python3.7/site-packages/airflow/models/dagbag.py", line 318, in parse
    loader.exec_module(new_module)
  File "<frozen importlib._bootstrap_external>", line 728, in exec_module
  File "<frozen importlib._bootstrap>", line 219, in _call_with_frames_removed
  File "/opt/airflow/dags/ETL_Games.py", line 7, in <module>
    from dotenv import load_dotenv
ModuleNotFoundError: No module named 'dotenv'
[2024-05-16 02:43:22,816] {processor.py:653} WARNING - No viable dags retrieved from /opt/airflow/dags/ETL_Games.py
[2024-05-16 02:43:22,828] {processor.py:161} INFO - Processing /opt/airflow/dags/ETL_Games.py took 0.295 seconds
[2024-05-16 02:43:32,889] {processor.py:153} INFO - Started process (PID=203) to work on /opt/airflow/dags/ETL_Games.py
[2024-05-16 02:43:32,890] {processor.py:641} INFO - Processing file /opt/airflow/dags/ETL_Games.py for tasks to queue
[2024-05-16 02:43:32,890] {logging_mixin.py:115} INFO - [2024-05-16 02:43:32,890] {dagbag.py:508} INFO - Filling up the DagBag from /opt/airflow/dags/ETL_Games.py
[2024-05-16 02:43:33,152] {logging_mixin.py:115} INFO - [2024-05-16 02:43:33,149] {dagbag.py:321} ERROR - Failed to import: /opt/airflow/dags/ETL_Games.py
Traceback (most recent call last):
  File "/home/airflow/.local/lib/python3.7/site-packages/airflow/models/dagbag.py", line 318, in parse
    loader.exec_module(new_module)
  File "<frozen importlib._bootstrap_external>", line 728, in exec_module
  File "<frozen importlib._bootstrap>", line 219, in _call_with_frames_removed
  File "/opt/airflow/dags/ETL_Games.py", line 7, in <module>
    from dotenv import load_dotenv
ModuleNotFoundError: No module named 'dotenv'
[2024-05-16 02:43:33,153] {processor.py:653} WARNING - No viable dags retrieved from /opt/airflow/dags/ETL_Games.py
[2024-05-16 02:43:33,166] {processor.py:161} INFO - Processing /opt/airflow/dags/ETL_Games.py took 0.279 seconds
[2024-05-16 02:43:43,227] {processor.py:153} INFO - Started process (PID=209) to work on /opt/airflow/dags/ETL_Games.py
[2024-05-16 02:43:43,228] {processor.py:641} INFO - Processing file /opt/airflow/dags/ETL_Games.py for tasks to queue
[2024-05-16 02:43:43,228] {logging_mixin.py:115} INFO - [2024-05-16 02:43:43,228] {dagbag.py:508} INFO - Filling up the DagBag from /opt/airflow/dags/ETL_Games.py
[2024-05-16 02:43:43,513] {logging_mixin.py:115} INFO - [2024-05-16 02:43:43,510] {dagbag.py:321} ERROR - Failed to import: /opt/airflow/dags/ETL_Games.py
Traceback (most recent call last):
  File "/home/airflow/.local/lib/python3.7/site-packages/airflow/models/dagbag.py", line 318, in parse
    loader.exec_module(new_module)
  File "<frozen importlib._bootstrap_external>", line 728, in exec_module
  File "<frozen importlib._bootstrap>", line 219, in _call_with_frames_removed
  File "/opt/airflow/dags/ETL_Games.py", line 7, in <module>
    from dotenv import load_dotenv
ModuleNotFoundError: No module named 'dotenv'
[2024-05-16 02:43:43,514] {processor.py:653} WARNING - No viable dags retrieved from /opt/airflow/dags/ETL_Games.py
[2024-05-16 02:43:43,529] {processor.py:161} INFO - Processing /opt/airflow/dags/ETL_Games.py took 0.304 seconds
[2024-05-16 02:52:52,484] {processor.py:153} INFO - Started process (PID=174) to work on /opt/airflow/dags/ETL_Games.py
[2024-05-16 02:52:52,486] {processor.py:641} INFO - Processing file /opt/airflow/dags/ETL_Games.py for tasks to queue
[2024-05-16 02:52:52,487] {logging_mixin.py:115} INFO - [2024-05-16 02:52:52,487] {dagbag.py:508} INFO - Filling up the DagBag from /opt/airflow/dags/ETL_Games.py
[2024-05-16 02:52:53,663] {logging_mixin.py:115} INFO - [2024-05-16 02:52:53,658] {dagbag.py:321} ERROR - Failed to import: /opt/airflow/dags/ETL_Games.py
Traceback (most recent call last):
  File "/home/airflow/.local/lib/python3.7/site-packages/airflow/models/dagbag.py", line 318, in parse
    loader.exec_module(new_module)
  File "<frozen importlib._bootstrap_external>", line 728, in exec_module
  File "<frozen importlib._bootstrap>", line 219, in _call_with_frames_removed
  File "/opt/airflow/dags/ETL_Games.py", line 7, in <module>
    from dotenv import load_dotenv
ModuleNotFoundError: No module named 'dotenv'
[2024-05-16 02:52:53,665] {processor.py:653} WARNING - No viable dags retrieved from /opt/airflow/dags/ETL_Games.py
[2024-05-16 02:52:53,687] {processor.py:161} INFO - Processing /opt/airflow/dags/ETL_Games.py took 1.209 seconds
[2024-05-16 02:53:03,760] {processor.py:153} INFO - Started process (PID=180) to work on /opt/airflow/dags/ETL_Games.py
[2024-05-16 02:53:03,761] {processor.py:641} INFO - Processing file /opt/airflow/dags/ETL_Games.py for tasks to queue
[2024-05-16 02:53:03,762] {logging_mixin.py:115} INFO - [2024-05-16 02:53:03,762] {dagbag.py:508} INFO - Filling up the DagBag from /opt/airflow/dags/ETL_Games.py
[2024-05-16 02:53:04,251] {logging_mixin.py:115} INFO - [2024-05-16 02:53:04,245] {dagbag.py:321} ERROR - Failed to import: /opt/airflow/dags/ETL_Games.py
Traceback (most recent call last):
  File "/home/airflow/.local/lib/python3.7/site-packages/airflow/models/dagbag.py", line 318, in parse
    loader.exec_module(new_module)
  File "<frozen importlib._bootstrap_external>", line 728, in exec_module
  File "<frozen importlib._bootstrap>", line 219, in _call_with_frames_removed
  File "/opt/airflow/dags/ETL_Games.py", line 7, in <module>
    from dotenv import load_dotenv
ModuleNotFoundError: No module named 'dotenv'
[2024-05-16 02:53:04,252] {processor.py:653} WARNING - No viable dags retrieved from /opt/airflow/dags/ETL_Games.py
[2024-05-16 02:53:04,272] {processor.py:161} INFO - Processing /opt/airflow/dags/ETL_Games.py took 0.516 seconds
[2024-05-16 02:53:14,334] {processor.py:153} INFO - Started process (PID=186) to work on /opt/airflow/dags/ETL_Games.py
[2024-05-16 02:53:14,335] {processor.py:641} INFO - Processing file /opt/airflow/dags/ETL_Games.py for tasks to queue
[2024-05-16 02:53:14,336] {logging_mixin.py:115} INFO - [2024-05-16 02:53:14,336] {dagbag.py:508} INFO - Filling up the DagBag from /opt/airflow/dags/ETL_Games.py
[2024-05-16 02:53:14,649] {logging_mixin.py:115} INFO - [2024-05-16 02:53:14,646] {dagbag.py:321} ERROR - Failed to import: /opt/airflow/dags/ETL_Games.py
Traceback (most recent call last):
  File "/home/airflow/.local/lib/python3.7/site-packages/airflow/models/dagbag.py", line 318, in parse
    loader.exec_module(new_module)
  File "<frozen importlib._bootstrap_external>", line 728, in exec_module
  File "<frozen importlib._bootstrap>", line 219, in _call_with_frames_removed
  File "/opt/airflow/dags/ETL_Games.py", line 7, in <module>
    from dotenv import load_dotenv
ModuleNotFoundError: No module named 'dotenv'
[2024-05-16 02:53:14,650] {processor.py:653} WARNING - No viable dags retrieved from /opt/airflow/dags/ETL_Games.py
[2024-05-16 02:53:14,664] {processor.py:161} INFO - Processing /opt/airflow/dags/ETL_Games.py took 0.332 seconds
[2024-05-16 02:53:24,723] {processor.py:153} INFO - Started process (PID=192) to work on /opt/airflow/dags/ETL_Games.py
[2024-05-16 02:53:24,724] {processor.py:641} INFO - Processing file /opt/airflow/dags/ETL_Games.py for tasks to queue
[2024-05-16 02:53:24,724] {logging_mixin.py:115} INFO - [2024-05-16 02:53:24,724] {dagbag.py:508} INFO - Filling up the DagBag from /opt/airflow/dags/ETL_Games.py
[2024-05-16 02:53:25,005] {logging_mixin.py:115} INFO - [2024-05-16 02:53:25,000] {dagbag.py:321} ERROR - Failed to import: /opt/airflow/dags/ETL_Games.py
Traceback (most recent call last):
  File "/home/airflow/.local/lib/python3.7/site-packages/airflow/models/dagbag.py", line 318, in parse
    loader.exec_module(new_module)
  File "<frozen importlib._bootstrap_external>", line 728, in exec_module
  File "<frozen importlib._bootstrap>", line 219, in _call_with_frames_removed
  File "/opt/airflow/dags/ETL_Games.py", line 7, in <module>
    from dotenv import load_dotenv
ModuleNotFoundError: No module named 'dotenv'
[2024-05-16 02:53:25,006] {processor.py:653} WARNING - No viable dags retrieved from /opt/airflow/dags/ETL_Games.py
[2024-05-16 02:53:25,019] {processor.py:161} INFO - Processing /opt/airflow/dags/ETL_Games.py took 0.297 seconds
[2024-05-16 02:53:35,079] {processor.py:153} INFO - Started process (PID=198) to work on /opt/airflow/dags/ETL_Games.py
[2024-05-16 02:53:35,079] {processor.py:641} INFO - Processing file /opt/airflow/dags/ETL_Games.py for tasks to queue
[2024-05-16 02:53:35,080] {logging_mixin.py:115} INFO - [2024-05-16 02:53:35,080] {dagbag.py:508} INFO - Filling up the DagBag from /opt/airflow/dags/ETL_Games.py
[2024-05-16 02:53:35,356] {logging_mixin.py:115} INFO - [2024-05-16 02:53:35,352] {dagbag.py:321} ERROR - Failed to import: /opt/airflow/dags/ETL_Games.py
Traceback (most recent call last):
  File "/home/airflow/.local/lib/python3.7/site-packages/airflow/models/dagbag.py", line 318, in parse
    loader.exec_module(new_module)
  File "<frozen importlib._bootstrap_external>", line 728, in exec_module
  File "<frozen importlib._bootstrap>", line 219, in _call_with_frames_removed
  File "/opt/airflow/dags/ETL_Games.py", line 7, in <module>
    from dotenv import load_dotenv
ModuleNotFoundError: No module named 'dotenv'
[2024-05-16 02:53:35,356] {processor.py:653} WARNING - No viable dags retrieved from /opt/airflow/dags/ETL_Games.py
[2024-05-16 02:53:35,370] {processor.py:161} INFO - Processing /opt/airflow/dags/ETL_Games.py took 0.294 seconds
[2024-05-16 02:53:45,440] {processor.py:153} INFO - Started process (PID=204) to work on /opt/airflow/dags/ETL_Games.py
[2024-05-16 02:53:45,441] {processor.py:641} INFO - Processing file /opt/airflow/dags/ETL_Games.py for tasks to queue
[2024-05-16 02:53:45,441] {logging_mixin.py:115} INFO - [2024-05-16 02:53:45,441] {dagbag.py:508} INFO - Filling up the DagBag from /opt/airflow/dags/ETL_Games.py
[2024-05-16 02:53:45,759] {logging_mixin.py:115} INFO - [2024-05-16 02:53:45,754] {dagbag.py:321} ERROR - Failed to import: /opt/airflow/dags/ETL_Games.py
Traceback (most recent call last):
  File "/home/airflow/.local/lib/python3.7/site-packages/airflow/models/dagbag.py", line 318, in parse
    loader.exec_module(new_module)
  File "<frozen importlib._bootstrap_external>", line 728, in exec_module
  File "<frozen importlib._bootstrap>", line 219, in _call_with_frames_removed
  File "/opt/airflow/dags/ETL_Games.py", line 7, in <module>
    from dotenv import load_dotenv
ModuleNotFoundError: No module named 'dotenv'
[2024-05-16 02:53:45,760] {processor.py:653} WARNING - No viable dags retrieved from /opt/airflow/dags/ETL_Games.py
[2024-05-16 02:53:45,772] {processor.py:161} INFO - Processing /opt/airflow/dags/ETL_Games.py took 0.336 seconds
[2024-05-16 02:53:55,837] {processor.py:153} INFO - Started process (PID=210) to work on /opt/airflow/dags/ETL_Games.py
[2024-05-16 02:53:55,838] {processor.py:641} INFO - Processing file /opt/airflow/dags/ETL_Games.py for tasks to queue
[2024-05-16 02:53:55,838] {logging_mixin.py:115} INFO - [2024-05-16 02:53:55,838] {dagbag.py:508} INFO - Filling up the DagBag from /opt/airflow/dags/ETL_Games.py
[2024-05-16 02:53:56,163] {logging_mixin.py:115} INFO - [2024-05-16 02:53:56,158] {dagbag.py:321} ERROR - Failed to import: /opt/airflow/dags/ETL_Games.py
Traceback (most recent call last):
  File "/home/airflow/.local/lib/python3.7/site-packages/airflow/models/dagbag.py", line 318, in parse
    loader.exec_module(new_module)
  File "<frozen importlib._bootstrap_external>", line 728, in exec_module
  File "<frozen importlib._bootstrap>", line 219, in _call_with_frames_removed
  File "/opt/airflow/dags/ETL_Games.py", line 7, in <module>
    from dotenv import load_dotenv
ModuleNotFoundError: No module named 'dotenv'
[2024-05-16 02:53:56,164] {processor.py:653} WARNING - No viable dags retrieved from /opt/airflow/dags/ETL_Games.py
[2024-05-16 02:53:56,181] {processor.py:161} INFO - Processing /opt/airflow/dags/ETL_Games.py took 0.346 seconds
[2024-05-16 02:54:06,240] {processor.py:153} INFO - Started process (PID=216) to work on /opt/airflow/dags/ETL_Games.py
[2024-05-16 02:54:06,240] {processor.py:641} INFO - Processing file /opt/airflow/dags/ETL_Games.py for tasks to queue
[2024-05-16 02:54:06,241] {logging_mixin.py:115} INFO - [2024-05-16 02:54:06,241] {dagbag.py:508} INFO - Filling up the DagBag from /opt/airflow/dags/ETL_Games.py
[2024-05-16 02:54:06,522] {logging_mixin.py:115} INFO - [2024-05-16 02:54:06,518] {dagbag.py:321} ERROR - Failed to import: /opt/airflow/dags/ETL_Games.py
Traceback (most recent call last):
  File "/home/airflow/.local/lib/python3.7/site-packages/airflow/models/dagbag.py", line 318, in parse
    loader.exec_module(new_module)
  File "<frozen importlib._bootstrap_external>", line 728, in exec_module
  File "<frozen importlib._bootstrap>", line 219, in _call_with_frames_removed
  File "/opt/airflow/dags/ETL_Games.py", line 7, in <module>
    from dotenv import load_dotenv
ModuleNotFoundError: No module named 'dotenv'
[2024-05-16 02:54:06,523] {processor.py:653} WARNING - No viable dags retrieved from /opt/airflow/dags/ETL_Games.py
[2024-05-16 02:54:06,536] {processor.py:161} INFO - Processing /opt/airflow/dags/ETL_Games.py took 0.298 seconds
[2024-05-16 02:57:26,983] {processor.py:153} INFO - Started process (PID=172) to work on /opt/airflow/dags/ETL_Games.py
[2024-05-16 02:57:26,985] {processor.py:641} INFO - Processing file /opt/airflow/dags/ETL_Games.py for tasks to queue
[2024-05-16 02:57:26,986] {logging_mixin.py:115} INFO - [2024-05-16 02:57:26,986] {dagbag.py:508} INFO - Filling up the DagBag from /opt/airflow/dags/ETL_Games.py
[2024-05-16 02:57:27,444] {logging_mixin.py:115} INFO - [2024-05-16 02:57:27,440] {dagbag.py:321} ERROR - Failed to import: /opt/airflow/dags/ETL_Games.py
Traceback (most recent call last):
  File "/home/airflow/.local/lib/python3.7/site-packages/airflow/models/dagbag.py", line 318, in parse
    loader.exec_module(new_module)
  File "<frozen importlib._bootstrap_external>", line 728, in exec_module
  File "<frozen importlib._bootstrap>", line 219, in _call_with_frames_removed
  File "/opt/airflow/dags/ETL_Games.py", line 7, in <module>
    from dotenv import load_dotenv
ModuleNotFoundError: No module named 'dotenv'
[2024-05-16 02:57:27,446] {processor.py:653} WARNING - No viable dags retrieved from /opt/airflow/dags/ETL_Games.py
[2024-05-16 02:57:27,467] {processor.py:161} INFO - Processing /opt/airflow/dags/ETL_Games.py took 0.487 seconds
[2024-05-16 02:57:37,534] {processor.py:153} INFO - Started process (PID=179) to work on /opt/airflow/dags/ETL_Games.py
[2024-05-16 02:57:37,535] {processor.py:641} INFO - Processing file /opt/airflow/dags/ETL_Games.py for tasks to queue
[2024-05-16 02:57:37,536] {logging_mixin.py:115} INFO - [2024-05-16 02:57:37,536] {dagbag.py:508} INFO - Filling up the DagBag from /opt/airflow/dags/ETL_Games.py
[2024-05-16 02:57:37,994] {logging_mixin.py:115} INFO - [2024-05-16 02:57:37,990] {dagbag.py:321} ERROR - Failed to import: /opt/airflow/dags/ETL_Games.py
Traceback (most recent call last):
  File "/home/airflow/.local/lib/python3.7/site-packages/airflow/models/dagbag.py", line 318, in parse
    loader.exec_module(new_module)
  File "<frozen importlib._bootstrap_external>", line 728, in exec_module
  File "<frozen importlib._bootstrap>", line 219, in _call_with_frames_removed
  File "/opt/airflow/dags/ETL_Games.py", line 7, in <module>
    from dotenv import load_dotenv
ModuleNotFoundError: No module named 'dotenv'
[2024-05-16 02:57:37,995] {processor.py:653} WARNING - No viable dags retrieved from /opt/airflow/dags/ETL_Games.py
[2024-05-16 02:57:38,015] {processor.py:161} INFO - Processing /opt/airflow/dags/ETL_Games.py took 0.484 seconds
[2024-05-16 02:57:48,086] {processor.py:153} INFO - Started process (PID=185) to work on /opt/airflow/dags/ETL_Games.py
[2024-05-16 02:57:48,088] {processor.py:641} INFO - Processing file /opt/airflow/dags/ETL_Games.py for tasks to queue
[2024-05-16 02:57:48,089] {logging_mixin.py:115} INFO - [2024-05-16 02:57:48,088] {dagbag.py:508} INFO - Filling up the DagBag from /opt/airflow/dags/ETL_Games.py
[2024-05-16 02:57:48,424] {logging_mixin.py:115} INFO - [2024-05-16 02:57:48,421] {dagbag.py:321} ERROR - Failed to import: /opt/airflow/dags/ETL_Games.py
Traceback (most recent call last):
  File "/home/airflow/.local/lib/python3.7/site-packages/airflow/models/dagbag.py", line 318, in parse
    loader.exec_module(new_module)
  File "<frozen importlib._bootstrap_external>", line 728, in exec_module
  File "<frozen importlib._bootstrap>", line 219, in _call_with_frames_removed
  File "/opt/airflow/dags/ETL_Games.py", line 7, in <module>
    from dotenv import load_dotenv
ModuleNotFoundError: No module named 'dotenv'
[2024-05-16 02:57:48,425] {processor.py:653} WARNING - No viable dags retrieved from /opt/airflow/dags/ETL_Games.py
[2024-05-16 02:57:48,440] {processor.py:161} INFO - Processing /opt/airflow/dags/ETL_Games.py took 0.357 seconds
[2024-05-16 02:57:58,493] {processor.py:153} INFO - Started process (PID=191) to work on /opt/airflow/dags/ETL_Games.py
[2024-05-16 02:57:58,494] {processor.py:641} INFO - Processing file /opt/airflow/dags/ETL_Games.py for tasks to queue
[2024-05-16 02:57:58,495] {logging_mixin.py:115} INFO - [2024-05-16 02:57:58,495] {dagbag.py:508} INFO - Filling up the DagBag from /opt/airflow/dags/ETL_Games.py
[2024-05-16 02:57:58,780] {logging_mixin.py:115} INFO - [2024-05-16 02:57:58,777] {dagbag.py:321} ERROR - Failed to import: /opt/airflow/dags/ETL_Games.py
Traceback (most recent call last):
  File "/home/airflow/.local/lib/python3.7/site-packages/airflow/models/dagbag.py", line 318, in parse
    loader.exec_module(new_module)
  File "<frozen importlib._bootstrap_external>", line 728, in exec_module
  File "<frozen importlib._bootstrap>", line 219, in _call_with_frames_removed
  File "/opt/airflow/dags/ETL_Games.py", line 7, in <module>
    from dotenv import load_dotenv
ModuleNotFoundError: No module named 'dotenv'
[2024-05-16 02:57:58,781] {processor.py:653} WARNING - No viable dags retrieved from /opt/airflow/dags/ETL_Games.py
[2024-05-16 02:57:58,792] {processor.py:161} INFO - Processing /opt/airflow/dags/ETL_Games.py took 0.301 seconds
[2024-05-16 02:58:08,857] {processor.py:153} INFO - Started process (PID=197) to work on /opt/airflow/dags/ETL_Games.py
[2024-05-16 02:58:08,857] {processor.py:641} INFO - Processing file /opt/airflow/dags/ETL_Games.py for tasks to queue
[2024-05-16 02:58:08,858] {logging_mixin.py:115} INFO - [2024-05-16 02:58:08,858] {dagbag.py:508} INFO - Filling up the DagBag from /opt/airflow/dags/ETL_Games.py
[2024-05-16 02:58:09,182] {logging_mixin.py:115} INFO - [2024-05-16 02:58:09,179] {dagbag.py:321} ERROR - Failed to import: /opt/airflow/dags/ETL_Games.py
Traceback (most recent call last):
  File "/home/airflow/.local/lib/python3.7/site-packages/airflow/models/dagbag.py", line 318, in parse
    loader.exec_module(new_module)
  File "<frozen importlib._bootstrap_external>", line 728, in exec_module
  File "<frozen importlib._bootstrap>", line 219, in _call_with_frames_removed
  File "/opt/airflow/dags/ETL_Games.py", line 7, in <module>
    from dotenv import load_dotenv
ModuleNotFoundError: No module named 'dotenv'
[2024-05-16 02:58:09,183] {processor.py:653} WARNING - No viable dags retrieved from /opt/airflow/dags/ETL_Games.py
[2024-05-16 02:58:09,200] {processor.py:161} INFO - Processing /opt/airflow/dags/ETL_Games.py took 0.345 seconds
[2024-05-16 13:16:36,359] {processor.py:153} INFO - Started process (PID=173) to work on /opt/airflow/dags/ETL_Games.py
[2024-05-16 13:16:36,365] {processor.py:641} INFO - Processing file /opt/airflow/dags/ETL_Games.py for tasks to queue
[2024-05-16 13:16:36,370] {logging_mixin.py:115} INFO - [2024-05-16 13:16:36,370] {dagbag.py:508} INFO - Filling up the DagBag from /opt/airflow/dags/ETL_Games.py
[2024-05-16 13:16:37,929] {logging_mixin.py:115} INFO - [2024-05-16 13:16:37,906] {dagbag.py:321} ERROR - Failed to import: /opt/airflow/dags/ETL_Games.py
Traceback (most recent call last):
  File "/home/airflow/.local/lib/python3.7/site-packages/airflow/models/dagbag.py", line 318, in parse
    loader.exec_module(new_module)
  File "<frozen importlib._bootstrap_external>", line 728, in exec_module
  File "<frozen importlib._bootstrap>", line 219, in _call_with_frames_removed
  File "/opt/airflow/dags/ETL_Games.py", line 7, in <module>
    from dotenv import load_dotenv
ModuleNotFoundError: No module named 'dotenv'
[2024-05-16 13:16:37,933] {processor.py:653} WARNING - No viable dags retrieved from /opt/airflow/dags/ETL_Games.py
[2024-05-16 13:16:37,997] {processor.py:161} INFO - Processing /opt/airflow/dags/ETL_Games.py took 1.669 seconds
[2024-05-16 13:16:48,098] {processor.py:153} INFO - Started process (PID=179) to work on /opt/airflow/dags/ETL_Games.py
[2024-05-16 13:16:48,099] {processor.py:641} INFO - Processing file /opt/airflow/dags/ETL_Games.py for tasks to queue
[2024-05-16 13:16:48,100] {logging_mixin.py:115} INFO - [2024-05-16 13:16:48,100] {dagbag.py:508} INFO - Filling up the DagBag from /opt/airflow/dags/ETL_Games.py
[2024-05-16 13:16:48,514] {logging_mixin.py:115} INFO - [2024-05-16 13:16:48,510] {dagbag.py:321} ERROR - Failed to import: /opt/airflow/dags/ETL_Games.py
Traceback (most recent call last):
  File "/home/airflow/.local/lib/python3.7/site-packages/airflow/models/dagbag.py", line 318, in parse
    loader.exec_module(new_module)
  File "<frozen importlib._bootstrap_external>", line 728, in exec_module
  File "<frozen importlib._bootstrap>", line 219, in _call_with_frames_removed
  File "/opt/airflow/dags/ETL_Games.py", line 7, in <module>
    from dotenv import load_dotenv
ModuleNotFoundError: No module named 'dotenv'
[2024-05-16 13:16:48,515] {processor.py:653} WARNING - No viable dags retrieved from /opt/airflow/dags/ETL_Games.py
[2024-05-16 13:16:48,530] {processor.py:161} INFO - Processing /opt/airflow/dags/ETL_Games.py took 0.436 seconds
[2024-05-16 13:16:58,600] {processor.py:153} INFO - Started process (PID=185) to work on /opt/airflow/dags/ETL_Games.py
[2024-05-16 13:16:58,601] {processor.py:641} INFO - Processing file /opt/airflow/dags/ETL_Games.py for tasks to queue
[2024-05-16 13:16:58,602] {logging_mixin.py:115} INFO - [2024-05-16 13:16:58,602] {dagbag.py:508} INFO - Filling up the DagBag from /opt/airflow/dags/ETL_Games.py
[2024-05-16 13:16:58,890] {logging_mixin.py:115} INFO - [2024-05-16 13:16:58,888] {dagbag.py:321} ERROR - Failed to import: /opt/airflow/dags/ETL_Games.py
Traceback (most recent call last):
  File "/home/airflow/.local/lib/python3.7/site-packages/airflow/models/dagbag.py", line 318, in parse
    loader.exec_module(new_module)
  File "<frozen importlib._bootstrap_external>", line 728, in exec_module
  File "<frozen importlib._bootstrap>", line 219, in _call_with_frames_removed
  File "/opt/airflow/dags/ETL_Games.py", line 7, in <module>
    from dotenv import load_dotenv
ModuleNotFoundError: No module named 'dotenv'
[2024-05-16 13:16:58,891] {processor.py:653} WARNING - No viable dags retrieved from /opt/airflow/dags/ETL_Games.py
[2024-05-16 13:16:58,905] {processor.py:161} INFO - Processing /opt/airflow/dags/ETL_Games.py took 0.307 seconds
[2024-05-16 13:17:08,955] {processor.py:153} INFO - Started process (PID=191) to work on /opt/airflow/dags/ETL_Games.py
[2024-05-16 13:17:08,956] {processor.py:641} INFO - Processing file /opt/airflow/dags/ETL_Games.py for tasks to queue
[2024-05-16 13:17:08,957] {logging_mixin.py:115} INFO - [2024-05-16 13:17:08,957] {dagbag.py:508} INFO - Filling up the DagBag from /opt/airflow/dags/ETL_Games.py
[2024-05-16 13:17:09,260] {logging_mixin.py:115} INFO - [2024-05-16 13:17:09,258] {dagbag.py:321} ERROR - Failed to import: /opt/airflow/dags/ETL_Games.py
Traceback (most recent call last):
  File "/home/airflow/.local/lib/python3.7/site-packages/airflow/models/dagbag.py", line 318, in parse
    loader.exec_module(new_module)
  File "<frozen importlib._bootstrap_external>", line 728, in exec_module
  File "<frozen importlib._bootstrap>", line 219, in _call_with_frames_removed
  File "/opt/airflow/dags/ETL_Games.py", line 7, in <module>
    from dotenv import load_dotenv
ModuleNotFoundError: No module named 'dotenv'
[2024-05-16 13:17:09,261] {processor.py:653} WARNING - No viable dags retrieved from /opt/airflow/dags/ETL_Games.py
[2024-05-16 13:17:09,276] {processor.py:161} INFO - Processing /opt/airflow/dags/ETL_Games.py took 0.323 seconds
[2024-05-16 13:17:19,336] {processor.py:153} INFO - Started process (PID=197) to work on /opt/airflow/dags/ETL_Games.py
[2024-05-16 13:17:19,337] {processor.py:641} INFO - Processing file /opt/airflow/dags/ETL_Games.py for tasks to queue
[2024-05-16 13:17:19,338] {logging_mixin.py:115} INFO - [2024-05-16 13:17:19,338] {dagbag.py:508} INFO - Filling up the DagBag from /opt/airflow/dags/ETL_Games.py
[2024-05-16 13:17:19,631] {logging_mixin.py:115} INFO - [2024-05-16 13:17:19,628] {dagbag.py:321} ERROR - Failed to import: /opt/airflow/dags/ETL_Games.py
Traceback (most recent call last):
  File "/home/airflow/.local/lib/python3.7/site-packages/airflow/models/dagbag.py", line 318, in parse
    loader.exec_module(new_module)
  File "<frozen importlib._bootstrap_external>", line 728, in exec_module
  File "<frozen importlib._bootstrap>", line 219, in _call_with_frames_removed
  File "/opt/airflow/dags/ETL_Games.py", line 7, in <module>
    from dotenv import load_dotenv
ModuleNotFoundError: No module named 'dotenv'
[2024-05-16 13:17:19,632] {processor.py:653} WARNING - No viable dags retrieved from /opt/airflow/dags/ETL_Games.py
[2024-05-16 13:17:19,644] {processor.py:161} INFO - Processing /opt/airflow/dags/ETL_Games.py took 0.310 seconds
[2024-05-16 13:17:29,703] {processor.py:153} INFO - Started process (PID=203) to work on /opt/airflow/dags/ETL_Games.py
[2024-05-16 13:17:29,704] {processor.py:641} INFO - Processing file /opt/airflow/dags/ETL_Games.py for tasks to queue
[2024-05-16 13:17:29,704] {logging_mixin.py:115} INFO - [2024-05-16 13:17:29,704] {dagbag.py:508} INFO - Filling up the DagBag from /opt/airflow/dags/ETL_Games.py
[2024-05-16 13:17:29,975] {logging_mixin.py:115} INFO - [2024-05-16 13:17:29,969] {dagbag.py:321} ERROR - Failed to import: /opt/airflow/dags/ETL_Games.py
Traceback (most recent call last):
  File "/home/airflow/.local/lib/python3.7/site-packages/airflow/models/dagbag.py", line 318, in parse
    loader.exec_module(new_module)
  File "<frozen importlib._bootstrap_external>", line 728, in exec_module
  File "<frozen importlib._bootstrap>", line 219, in _call_with_frames_removed
  File "/opt/airflow/dags/ETL_Games.py", line 7, in <module>
    from dotenv import load_dotenv
ModuleNotFoundError: No module named 'dotenv'
[2024-05-16 13:17:29,976] {processor.py:653} WARNING - No viable dags retrieved from /opt/airflow/dags/ETL_Games.py
[2024-05-16 13:17:29,992] {processor.py:161} INFO - Processing /opt/airflow/dags/ETL_Games.py took 0.291 seconds
[2024-05-16 13:17:40,060] {processor.py:153} INFO - Started process (PID=209) to work on /opt/airflow/dags/ETL_Games.py
[2024-05-16 13:17:40,061] {processor.py:641} INFO - Processing file /opt/airflow/dags/ETL_Games.py for tasks to queue
[2024-05-16 13:17:40,061] {logging_mixin.py:115} INFO - [2024-05-16 13:17:40,061] {dagbag.py:508} INFO - Filling up the DagBag from /opt/airflow/dags/ETL_Games.py
[2024-05-16 13:17:40,410] {logging_mixin.py:115} INFO - [2024-05-16 13:17:40,405] {dagbag.py:321} ERROR - Failed to import: /opt/airflow/dags/ETL_Games.py
Traceback (most recent call last):
  File "/home/airflow/.local/lib/python3.7/site-packages/airflow/models/dagbag.py", line 318, in parse
    loader.exec_module(new_module)
  File "<frozen importlib._bootstrap_external>", line 728, in exec_module
  File "<frozen importlib._bootstrap>", line 219, in _call_with_frames_removed
  File "/opt/airflow/dags/ETL_Games.py", line 7, in <module>
    from dotenv import load_dotenv
ModuleNotFoundError: No module named 'dotenv'
[2024-05-16 13:17:40,411] {processor.py:653} WARNING - No viable dags retrieved from /opt/airflow/dags/ETL_Games.py
[2024-05-16 13:17:40,429] {processor.py:161} INFO - Processing /opt/airflow/dags/ETL_Games.py took 0.372 seconds
[2024-05-16 13:17:50,492] {processor.py:153} INFO - Started process (PID=215) to work on /opt/airflow/dags/ETL_Games.py
[2024-05-16 13:17:50,493] {processor.py:641} INFO - Processing file /opt/airflow/dags/ETL_Games.py for tasks to queue
[2024-05-16 13:17:50,493] {logging_mixin.py:115} INFO - [2024-05-16 13:17:50,493] {dagbag.py:508} INFO - Filling up the DagBag from /opt/airflow/dags/ETL_Games.py
[2024-05-16 13:17:50,788] {logging_mixin.py:115} INFO - [2024-05-16 13:17:50,784] {dagbag.py:321} ERROR - Failed to import: /opt/airflow/dags/ETL_Games.py
Traceback (most recent call last):
  File "/home/airflow/.local/lib/python3.7/site-packages/airflow/models/dagbag.py", line 318, in parse
    loader.exec_module(new_module)
  File "<frozen importlib._bootstrap_external>", line 728, in exec_module
  File "<frozen importlib._bootstrap>", line 219, in _call_with_frames_removed
  File "/opt/airflow/dags/ETL_Games.py", line 7, in <module>
    from dotenv import load_dotenv
ModuleNotFoundError: No module named 'dotenv'
[2024-05-16 13:17:50,789] {processor.py:653} WARNING - No viable dags retrieved from /opt/airflow/dags/ETL_Games.py
[2024-05-16 13:17:50,808] {processor.py:161} INFO - Processing /opt/airflow/dags/ETL_Games.py took 0.319 seconds
[2024-05-16 13:18:00,873] {processor.py:153} INFO - Started process (PID=221) to work on /opt/airflow/dags/ETL_Games.py
[2024-05-16 13:18:00,874] {processor.py:641} INFO - Processing file /opt/airflow/dags/ETL_Games.py for tasks to queue
[2024-05-16 13:18:00,874] {logging_mixin.py:115} INFO - [2024-05-16 13:18:00,874] {dagbag.py:508} INFO - Filling up the DagBag from /opt/airflow/dags/ETL_Games.py
[2024-05-16 13:18:01,163] {logging_mixin.py:115} INFO - [2024-05-16 13:18:01,158] {dagbag.py:321} ERROR - Failed to import: /opt/airflow/dags/ETL_Games.py
Traceback (most recent call last):
  File "/home/airflow/.local/lib/python3.7/site-packages/airflow/models/dagbag.py", line 318, in parse
    loader.exec_module(new_module)
  File "<frozen importlib._bootstrap_external>", line 728, in exec_module
  File "<frozen importlib._bootstrap>", line 219, in _call_with_frames_removed
  File "/opt/airflow/dags/ETL_Games.py", line 7, in <module>
    from dotenv import load_dotenv
ModuleNotFoundError: No module named 'dotenv'
[2024-05-16 13:18:01,164] {processor.py:653} WARNING - No viable dags retrieved from /opt/airflow/dags/ETL_Games.py
[2024-05-16 13:18:01,177] {processor.py:161} INFO - Processing /opt/airflow/dags/ETL_Games.py took 0.306 seconds
[2024-05-16 13:18:11,240] {processor.py:153} INFO - Started process (PID=227) to work on /opt/airflow/dags/ETL_Games.py
[2024-05-16 13:18:11,241] {processor.py:641} INFO - Processing file /opt/airflow/dags/ETL_Games.py for tasks to queue
[2024-05-16 13:18:11,241] {logging_mixin.py:115} INFO - [2024-05-16 13:18:11,241] {dagbag.py:508} INFO - Filling up the DagBag from /opt/airflow/dags/ETL_Games.py
[2024-05-16 13:18:11,512] {logging_mixin.py:115} INFO - [2024-05-16 13:18:11,507] {dagbag.py:321} ERROR - Failed to import: /opt/airflow/dags/ETL_Games.py
Traceback (most recent call last):
  File "/home/airflow/.local/lib/python3.7/site-packages/airflow/models/dagbag.py", line 318, in parse
    loader.exec_module(new_module)
  File "<frozen importlib._bootstrap_external>", line 728, in exec_module
  File "<frozen importlib._bootstrap>", line 219, in _call_with_frames_removed
  File "/opt/airflow/dags/ETL_Games.py", line 7, in <module>
    from dotenv import load_dotenv
ModuleNotFoundError: No module named 'dotenv'
[2024-05-16 13:18:11,513] {processor.py:653} WARNING - No viable dags retrieved from /opt/airflow/dags/ETL_Games.py
[2024-05-16 13:18:11,527] {processor.py:161} INFO - Processing /opt/airflow/dags/ETL_Games.py took 0.289 seconds
[2024-05-16 13:18:21,582] {processor.py:153} INFO - Started process (PID=233) to work on /opt/airflow/dags/ETL_Games.py
[2024-05-16 13:18:21,583] {processor.py:641} INFO - Processing file /opt/airflow/dags/ETL_Games.py for tasks to queue
[2024-05-16 13:18:21,584] {logging_mixin.py:115} INFO - [2024-05-16 13:18:21,584] {dagbag.py:508} INFO - Filling up the DagBag from /opt/airflow/dags/ETL_Games.py
[2024-05-16 13:18:21,884] {logging_mixin.py:115} INFO - [2024-05-16 13:18:21,881] {dagbag.py:321} ERROR - Failed to import: /opt/airflow/dags/ETL_Games.py
Traceback (most recent call last):
  File "/home/airflow/.local/lib/python3.7/site-packages/airflow/models/dagbag.py", line 318, in parse
    loader.exec_module(new_module)
  File "<frozen importlib._bootstrap_external>", line 728, in exec_module
  File "<frozen importlib._bootstrap>", line 219, in _call_with_frames_removed
  File "/opt/airflow/dags/ETL_Games.py", line 7, in <module>
    from dotenv import load_dotenv
ModuleNotFoundError: No module named 'dotenv'
[2024-05-16 13:18:21,884] {processor.py:653} WARNING - No viable dags retrieved from /opt/airflow/dags/ETL_Games.py
[2024-05-16 13:18:21,898] {processor.py:161} INFO - Processing /opt/airflow/dags/ETL_Games.py took 0.317 seconds
[2024-05-16 13:18:31,954] {processor.py:153} INFO - Started process (PID=239) to work on /opt/airflow/dags/ETL_Games.py
[2024-05-16 13:18:31,955] {processor.py:641} INFO - Processing file /opt/airflow/dags/ETL_Games.py for tasks to queue
[2024-05-16 13:18:31,956] {logging_mixin.py:115} INFO - [2024-05-16 13:18:31,956] {dagbag.py:508} INFO - Filling up the DagBag from /opt/airflow/dags/ETL_Games.py
[2024-05-16 13:18:32,259] {logging_mixin.py:115} INFO - [2024-05-16 13:18:32,254] {dagbag.py:321} ERROR - Failed to import: /opt/airflow/dags/ETL_Games.py
Traceback (most recent call last):
  File "/home/airflow/.local/lib/python3.7/site-packages/airflow/models/dagbag.py", line 318, in parse
    loader.exec_module(new_module)
  File "<frozen importlib._bootstrap_external>", line 728, in exec_module
  File "<frozen importlib._bootstrap>", line 219, in _call_with_frames_removed
  File "/opt/airflow/dags/ETL_Games.py", line 7, in <module>
    from dotenv import load_dotenv
ModuleNotFoundError: No module named 'dotenv'
[2024-05-16 13:18:32,259] {processor.py:653} WARNING - No viable dags retrieved from /opt/airflow/dags/ETL_Games.py
[2024-05-16 13:18:32,273] {processor.py:161} INFO - Processing /opt/airflow/dags/ETL_Games.py took 0.322 seconds
[2024-05-16 13:18:42,336] {processor.py:153} INFO - Started process (PID=245) to work on /opt/airflow/dags/ETL_Games.py
[2024-05-16 13:18:42,336] {processor.py:641} INFO - Processing file /opt/airflow/dags/ETL_Games.py for tasks to queue
[2024-05-16 13:18:42,337] {logging_mixin.py:115} INFO - [2024-05-16 13:18:42,337] {dagbag.py:508} INFO - Filling up the DagBag from /opt/airflow/dags/ETL_Games.py
[2024-05-16 13:18:42,596] {logging_mixin.py:115} INFO - [2024-05-16 13:18:42,592] {dagbag.py:321} ERROR - Failed to import: /opt/airflow/dags/ETL_Games.py
Traceback (most recent call last):
  File "/home/airflow/.local/lib/python3.7/site-packages/airflow/models/dagbag.py", line 318, in parse
    loader.exec_module(new_module)
  File "<frozen importlib._bootstrap_external>", line 728, in exec_module
  File "<frozen importlib._bootstrap>", line 219, in _call_with_frames_removed
  File "/opt/airflow/dags/ETL_Games.py", line 7, in <module>
    from dotenv import load_dotenv
ModuleNotFoundError: No module named 'dotenv'
[2024-05-16 13:18:42,597] {processor.py:653} WARNING - No viable dags retrieved from /opt/airflow/dags/ETL_Games.py
[2024-05-16 13:18:42,609] {processor.py:161} INFO - Processing /opt/airflow/dags/ETL_Games.py took 0.276 seconds
[2024-05-16 13:18:52,665] {processor.py:153} INFO - Started process (PID=251) to work on /opt/airflow/dags/ETL_Games.py
[2024-05-16 13:18:52,666] {processor.py:641} INFO - Processing file /opt/airflow/dags/ETL_Games.py for tasks to queue
[2024-05-16 13:18:52,667] {logging_mixin.py:115} INFO - [2024-05-16 13:18:52,667] {dagbag.py:508} INFO - Filling up the DagBag from /opt/airflow/dags/ETL_Games.py
[2024-05-16 13:18:53,183] {logging_mixin.py:115} INFO - [2024-05-16 13:18:53,180] {dagbag.py:321} ERROR - Failed to import: /opt/airflow/dags/ETL_Games.py
Traceback (most recent call last):
  File "/home/airflow/.local/lib/python3.7/site-packages/airflow/models/dagbag.py", line 318, in parse
    loader.exec_module(new_module)
  File "<frozen importlib._bootstrap_external>", line 728, in exec_module
  File "<frozen importlib._bootstrap>", line 219, in _call_with_frames_removed
  File "/opt/airflow/dags/ETL_Games.py", line 7, in <module>
    from dotenv import load_dotenv
ModuleNotFoundError: No module named 'dotenv'
[2024-05-16 13:18:53,184] {processor.py:653} WARNING - No viable dags retrieved from /opt/airflow/dags/ETL_Games.py
[2024-05-16 13:18:53,205] {processor.py:161} INFO - Processing /opt/airflow/dags/ETL_Games.py took 0.543 seconds
[2024-05-16 13:19:03,275] {processor.py:153} INFO - Started process (PID=257) to work on /opt/airflow/dags/ETL_Games.py
[2024-05-16 13:19:03,276] {processor.py:641} INFO - Processing file /opt/airflow/dags/ETL_Games.py for tasks to queue
[2024-05-16 13:19:03,277] {logging_mixin.py:115} INFO - [2024-05-16 13:19:03,277] {dagbag.py:508} INFO - Filling up the DagBag from /opt/airflow/dags/ETL_Games.py
[2024-05-16 13:19:03,724] {logging_mixin.py:115} INFO - [2024-05-16 13:19:03,720] {dagbag.py:321} ERROR - Failed to import: /opt/airflow/dags/ETL_Games.py
Traceback (most recent call last):
  File "/home/airflow/.local/lib/python3.7/site-packages/airflow/models/dagbag.py", line 318, in parse
    loader.exec_module(new_module)
  File "<frozen importlib._bootstrap_external>", line 728, in exec_module
  File "<frozen importlib._bootstrap>", line 219, in _call_with_frames_removed
  File "/opt/airflow/dags/ETL_Games.py", line 7, in <module>
    from dotenv import load_dotenv
ModuleNotFoundError: No module named 'dotenv'
[2024-05-16 13:19:03,726] {processor.py:653} WARNING - No viable dags retrieved from /opt/airflow/dags/ETL_Games.py
[2024-05-16 13:19:03,750] {processor.py:161} INFO - Processing /opt/airflow/dags/ETL_Games.py took 0.478 seconds
[2024-05-16 13:19:13,811] {processor.py:153} INFO - Started process (PID=263) to work on /opt/airflow/dags/ETL_Games.py
[2024-05-16 13:19:13,812] {processor.py:641} INFO - Processing file /opt/airflow/dags/ETL_Games.py for tasks to queue
[2024-05-16 13:19:13,813] {logging_mixin.py:115} INFO - [2024-05-16 13:19:13,813] {dagbag.py:508} INFO - Filling up the DagBag from /opt/airflow/dags/ETL_Games.py
[2024-05-16 13:19:14,299] {logging_mixin.py:115} INFO - [2024-05-16 13:19:14,292] {dagbag.py:321} ERROR - Failed to import: /opt/airflow/dags/ETL_Games.py
Traceback (most recent call last):
  File "/home/airflow/.local/lib/python3.7/site-packages/airflow/models/dagbag.py", line 318, in parse
    loader.exec_module(new_module)
  File "<frozen importlib._bootstrap_external>", line 728, in exec_module
  File "<frozen importlib._bootstrap>", line 219, in _call_with_frames_removed
  File "/opt/airflow/dags/ETL_Games.py", line 7, in <module>
    from dotenv import load_dotenv
ModuleNotFoundError: No module named 'dotenv'
[2024-05-16 13:19:14,301] {processor.py:653} WARNING - No viable dags retrieved from /opt/airflow/dags/ETL_Games.py
[2024-05-16 13:19:14,323] {processor.py:161} INFO - Processing /opt/airflow/dags/ETL_Games.py took 0.516 seconds
[2024-05-16 13:19:24,392] {processor.py:153} INFO - Started process (PID=269) to work on /opt/airflow/dags/ETL_Games.py
[2024-05-16 13:19:24,393] {processor.py:641} INFO - Processing file /opt/airflow/dags/ETL_Games.py for tasks to queue
[2024-05-16 13:19:24,393] {logging_mixin.py:115} INFO - [2024-05-16 13:19:24,393] {dagbag.py:508} INFO - Filling up the DagBag from /opt/airflow/dags/ETL_Games.py
[2024-05-16 13:19:24,708] {logging_mixin.py:115} INFO - [2024-05-16 13:19:24,704] {dagbag.py:321} ERROR - Failed to import: /opt/airflow/dags/ETL_Games.py
Traceback (most recent call last):
  File "/home/airflow/.local/lib/python3.7/site-packages/airflow/models/dagbag.py", line 318, in parse
    loader.exec_module(new_module)
  File "<frozen importlib._bootstrap_external>", line 728, in exec_module
  File "<frozen importlib._bootstrap>", line 219, in _call_with_frames_removed
  File "/opt/airflow/dags/ETL_Games.py", line 7, in <module>
    from dotenv import load_dotenv
ModuleNotFoundError: No module named 'dotenv'
[2024-05-16 13:19:24,709] {processor.py:653} WARNING - No viable dags retrieved from /opt/airflow/dags/ETL_Games.py
[2024-05-16 13:19:24,723] {processor.py:161} INFO - Processing /opt/airflow/dags/ETL_Games.py took 0.334 seconds
[2024-05-16 13:19:34,781] {processor.py:153} INFO - Started process (PID=275) to work on /opt/airflow/dags/ETL_Games.py
[2024-05-16 13:19:34,781] {processor.py:641} INFO - Processing file /opt/airflow/dags/ETL_Games.py for tasks to queue
[2024-05-16 13:19:34,782] {logging_mixin.py:115} INFO - [2024-05-16 13:19:34,782] {dagbag.py:508} INFO - Filling up the DagBag from /opt/airflow/dags/ETL_Games.py
[2024-05-16 13:19:35,070] {logging_mixin.py:115} INFO - [2024-05-16 13:19:35,066] {dagbag.py:321} ERROR - Failed to import: /opt/airflow/dags/ETL_Games.py
Traceback (most recent call last):
  File "/home/airflow/.local/lib/python3.7/site-packages/airflow/models/dagbag.py", line 318, in parse
    loader.exec_module(new_module)
  File "<frozen importlib._bootstrap_external>", line 728, in exec_module
  File "<frozen importlib._bootstrap>", line 219, in _call_with_frames_removed
  File "/opt/airflow/dags/ETL_Games.py", line 7, in <module>
    from dotenv import load_dotenv
ModuleNotFoundError: No module named 'dotenv'
[2024-05-16 13:19:35,070] {processor.py:653} WARNING - No viable dags retrieved from /opt/airflow/dags/ETL_Games.py
[2024-05-16 13:19:35,083] {processor.py:161} INFO - Processing /opt/airflow/dags/ETL_Games.py took 0.304 seconds
[2024-05-16 13:19:42,806] {processor.py:153} INFO - Started process (PID=281) to work on /opt/airflow/dags/ETL_Games.py
[2024-05-16 13:19:42,807] {processor.py:641} INFO - Processing file /opt/airflow/dags/ETL_Games.py for tasks to queue
[2024-05-16 13:19:42,808] {logging_mixin.py:115} INFO - [2024-05-16 13:19:42,808] {dagbag.py:508} INFO - Filling up the DagBag from /opt/airflow/dags/ETL_Games.py
[2024-05-16 13:19:42,821] {logging_mixin.py:115} INFO - [2024-05-16 13:19:42,820] {dagbag.py:321} ERROR - Failed to import: /opt/airflow/dags/ETL_Games.py
Traceback (most recent call last):
  File "/home/airflow/.local/lib/python3.7/site-packages/airflow/models/dagbag.py", line 318, in parse
    loader.exec_module(new_module)
  File "<frozen importlib._bootstrap_external>", line 724, in exec_module
  File "<frozen importlib._bootstrap_external>", line 860, in get_code
  File "<frozen importlib._bootstrap_external>", line 791, in source_to_code
  File "<frozen importlib._bootstrap>", line 219, in _call_with_frames_removed
  File "/opt/airflow/dags/ETL_Games.py", line 9
    from airflow.operators. import PythonOperator
                                 ^
SyntaxError: invalid syntax
[2024-05-16 13:19:42,821] {processor.py:653} WARNING - No viable dags retrieved from /opt/airflow/dags/ETL_Games.py
[2024-05-16 13:19:42,841] {processor.py:161} INFO - Processing /opt/airflow/dags/ETL_Games.py took 0.038 seconds
[2024-05-16 13:19:49,911] {processor.py:153} INFO - Started process (PID=286) to work on /opt/airflow/dags/ETL_Games.py
[2024-05-16 13:19:49,911] {processor.py:641} INFO - Processing file /opt/airflow/dags/ETL_Games.py for tasks to queue
[2024-05-16 13:19:49,912] {logging_mixin.py:115} INFO - [2024-05-16 13:19:49,912] {dagbag.py:508} INFO - Filling up the DagBag from /opt/airflow/dags/ETL_Games.py
[2024-05-16 13:19:50,309] {logging_mixin.py:115} INFO - [2024-05-16 13:19:50,306] {dagbag.py:321} ERROR - Failed to import: /opt/airflow/dags/ETL_Games.py
Traceback (most recent call last):
  File "/home/airflow/.local/lib/python3.7/site-packages/airflow/models/dagbag.py", line 318, in parse
    loader.exec_module(new_module)
  File "<frozen importlib._bootstrap_external>", line 728, in exec_module
  File "<frozen importlib._bootstrap>", line 219, in _call_with_frames_removed
  File "/opt/airflow/dags/ETL_Games.py", line 7, in <module>
    from dotenv import load_dotenv
ModuleNotFoundError: No module named 'dotenv'
[2024-05-16 13:19:50,311] {processor.py:653} WARNING - No viable dags retrieved from /opt/airflow/dags/ETL_Games.py
[2024-05-16 13:19:50,332] {processor.py:161} INFO - Processing /opt/airflow/dags/ETL_Games.py took 0.425 seconds
[2024-05-16 13:20:00,392] {processor.py:153} INFO - Started process (PID=292) to work on /opt/airflow/dags/ETL_Games.py
[2024-05-16 13:20:00,394] {processor.py:641} INFO - Processing file /opt/airflow/dags/ETL_Games.py for tasks to queue
[2024-05-16 13:20:00,395] {logging_mixin.py:115} INFO - [2024-05-16 13:20:00,394] {dagbag.py:508} INFO - Filling up the DagBag from /opt/airflow/dags/ETL_Games.py
[2024-05-16 13:20:00,914] {logging_mixin.py:115} INFO - [2024-05-16 13:20:00,909] {dagbag.py:321} ERROR - Failed to import: /opt/airflow/dags/ETL_Games.py
Traceback (most recent call last):
  File "/home/airflow/.local/lib/python3.7/site-packages/airflow/models/dagbag.py", line 318, in parse
    loader.exec_module(new_module)
  File "<frozen importlib._bootstrap_external>", line 728, in exec_module
  File "<frozen importlib._bootstrap>", line 219, in _call_with_frames_removed
  File "/opt/airflow/dags/ETL_Games.py", line 7, in <module>
    from dotenv import load_dotenv
ModuleNotFoundError: No module named 'dotenv'
[2024-05-16 13:20:00,915] {processor.py:653} WARNING - No viable dags retrieved from /opt/airflow/dags/ETL_Games.py
[2024-05-16 13:20:00,932] {processor.py:161} INFO - Processing /opt/airflow/dags/ETL_Games.py took 0.543 seconds
[2024-05-16 13:20:10,971] {processor.py:153} INFO - Started process (PID=298) to work on /opt/airflow/dags/ETL_Games.py
[2024-05-16 13:20:10,971] {processor.py:641} INFO - Processing file /opt/airflow/dags/ETL_Games.py for tasks to queue
[2024-05-16 13:20:10,972] {logging_mixin.py:115} INFO - [2024-05-16 13:20:10,971] {dagbag.py:508} INFO - Filling up the DagBag from /opt/airflow/dags/ETL_Games.py
[2024-05-16 13:20:11,249] {logging_mixin.py:115} INFO - [2024-05-16 13:20:11,245] {dagbag.py:321} ERROR - Failed to import: /opt/airflow/dags/ETL_Games.py
Traceback (most recent call last):
  File "/home/airflow/.local/lib/python3.7/site-packages/airflow/models/dagbag.py", line 318, in parse
    loader.exec_module(new_module)
  File "<frozen importlib._bootstrap_external>", line 728, in exec_module
  File "<frozen importlib._bootstrap>", line 219, in _call_with_frames_removed
  File "/opt/airflow/dags/ETL_Games.py", line 7, in <module>
    from dotenv import load_dotenv
ModuleNotFoundError: No module named 'dotenv'
[2024-05-16 13:20:11,249] {processor.py:653} WARNING - No viable dags retrieved from /opt/airflow/dags/ETL_Games.py
[2024-05-16 13:20:11,262] {processor.py:161} INFO - Processing /opt/airflow/dags/ETL_Games.py took 0.294 seconds
[2024-05-16 13:20:21,314] {processor.py:153} INFO - Started process (PID=304) to work on /opt/airflow/dags/ETL_Games.py
[2024-05-16 13:20:21,315] {processor.py:641} INFO - Processing file /opt/airflow/dags/ETL_Games.py for tasks to queue
[2024-05-16 13:20:21,315] {logging_mixin.py:115} INFO - [2024-05-16 13:20:21,315] {dagbag.py:508} INFO - Filling up the DagBag from /opt/airflow/dags/ETL_Games.py
[2024-05-16 13:20:21,609] {logging_mixin.py:115} INFO - [2024-05-16 13:20:21,606] {dagbag.py:321} ERROR - Failed to import: /opt/airflow/dags/ETL_Games.py
Traceback (most recent call last):
  File "/home/airflow/.local/lib/python3.7/site-packages/airflow/models/dagbag.py", line 318, in parse
    loader.exec_module(new_module)
  File "<frozen importlib._bootstrap_external>", line 728, in exec_module
  File "<frozen importlib._bootstrap>", line 219, in _call_with_frames_removed
  File "/opt/airflow/dags/ETL_Games.py", line 7, in <module>
    from dotenv import load_dotenv
ModuleNotFoundError: No module named 'dotenv'
[2024-05-16 13:20:21,610] {processor.py:653} WARNING - No viable dags retrieved from /opt/airflow/dags/ETL_Games.py
[2024-05-16 13:20:21,622] {processor.py:161} INFO - Processing /opt/airflow/dags/ETL_Games.py took 0.310 seconds
[2024-05-16 13:20:31,680] {processor.py:153} INFO - Started process (PID=310) to work on /opt/airflow/dags/ETL_Games.py
[2024-05-16 13:20:31,681] {processor.py:641} INFO - Processing file /opt/airflow/dags/ETL_Games.py for tasks to queue
[2024-05-16 13:20:31,681] {logging_mixin.py:115} INFO - [2024-05-16 13:20:31,681] {dagbag.py:508} INFO - Filling up the DagBag from /opt/airflow/dags/ETL_Games.py
[2024-05-16 13:20:32,000] {logging_mixin.py:115} INFO - [2024-05-16 13:20:31,998] {dagbag.py:321} ERROR - Failed to import: /opt/airflow/dags/ETL_Games.py
Traceback (most recent call last):
  File "/home/airflow/.local/lib/python3.7/site-packages/airflow/models/dagbag.py", line 318, in parse
    loader.exec_module(new_module)
  File "<frozen importlib._bootstrap_external>", line 728, in exec_module
  File "<frozen importlib._bootstrap>", line 219, in _call_with_frames_removed
  File "/opt/airflow/dags/ETL_Games.py", line 7, in <module>
    from dotenv import load_dotenv
ModuleNotFoundError: No module named 'dotenv'
[2024-05-16 13:20:32,001] {processor.py:653} WARNING - No viable dags retrieved from /opt/airflow/dags/ETL_Games.py
[2024-05-16 13:20:32,022] {processor.py:161} INFO - Processing /opt/airflow/dags/ETL_Games.py took 0.345 seconds
[2024-05-16 13:20:42,098] {processor.py:153} INFO - Started process (PID=316) to work on /opt/airflow/dags/ETL_Games.py
[2024-05-16 13:20:42,099] {processor.py:641} INFO - Processing file /opt/airflow/dags/ETL_Games.py for tasks to queue
[2024-05-16 13:20:42,099] {logging_mixin.py:115} INFO - [2024-05-16 13:20:42,099] {dagbag.py:508} INFO - Filling up the DagBag from /opt/airflow/dags/ETL_Games.py
[2024-05-16 13:20:42,419] {logging_mixin.py:115} INFO - [2024-05-16 13:20:42,413] {dagbag.py:321} ERROR - Failed to import: /opt/airflow/dags/ETL_Games.py
Traceback (most recent call last):
  File "/home/airflow/.local/lib/python3.7/site-packages/airflow/models/dagbag.py", line 318, in parse
    loader.exec_module(new_module)
  File "<frozen importlib._bootstrap_external>", line 728, in exec_module
  File "<frozen importlib._bootstrap>", line 219, in _call_with_frames_removed
  File "/opt/airflow/dags/ETL_Games.py", line 7, in <module>
    from dotenv import load_dotenv
ModuleNotFoundError: No module named 'dotenv'
[2024-05-16 13:20:42,419] {processor.py:653} WARNING - No viable dags retrieved from /opt/airflow/dags/ETL_Games.py
[2024-05-16 13:20:42,439] {processor.py:161} INFO - Processing /opt/airflow/dags/ETL_Games.py took 0.343 seconds
[2024-05-16 13:20:52,494] {processor.py:153} INFO - Started process (PID=322) to work on /opt/airflow/dags/ETL_Games.py
[2024-05-16 13:20:52,495] {processor.py:641} INFO - Processing file /opt/airflow/dags/ETL_Games.py for tasks to queue
[2024-05-16 13:20:52,495] {logging_mixin.py:115} INFO - [2024-05-16 13:20:52,495] {dagbag.py:508} INFO - Filling up the DagBag from /opt/airflow/dags/ETL_Games.py
[2024-05-16 13:20:52,809] {logging_mixin.py:115} INFO - [2024-05-16 13:20:52,806] {dagbag.py:321} ERROR - Failed to import: /opt/airflow/dags/ETL_Games.py
Traceback (most recent call last):
  File "/home/airflow/.local/lib/python3.7/site-packages/airflow/models/dagbag.py", line 318, in parse
    loader.exec_module(new_module)
  File "<frozen importlib._bootstrap_external>", line 728, in exec_module
  File "<frozen importlib._bootstrap>", line 219, in _call_with_frames_removed
  File "/opt/airflow/dags/ETL_Games.py", line 7, in <module>
    from dotenv import load_dotenv
ModuleNotFoundError: No module named 'dotenv'
[2024-05-16 13:20:52,810] {processor.py:653} WARNING - No viable dags retrieved from /opt/airflow/dags/ETL_Games.py
[2024-05-16 13:20:52,826] {processor.py:161} INFO - Processing /opt/airflow/dags/ETL_Games.py took 0.334 seconds
